Workbook

Sheet הערות כלליות
A1: תיאור | B1: לשוניות | C1: שאלות | D1: שם חדש
A2: מפלגה/קואליציה מועדפת - יש נוסחים שונים | B2: עניין פוליטי, זיקה רגשית, העדפות, ציפיות
A3: התאמה לראשות ממשלה - יש נוסחים שונים | B3: תכונות
A4: ציפיות קואליציה - יש נוסחים שונים | B4: ציפיות
A5: מי יטפל טוב יותר בבעיות כלכליות - יש נוסחים שונים ומעבר בין שאלה המתייחסת למועמד ושאלה המתייחסת למפלגה | B5: כלכלה-חברה
A6: דירוג סיכון מלחמה בצפון - נוסחים שונים: 1992 - מלחמה עם הערבים, 2006 - מלחמה בצפון, 2009 - מלחמה עם חיזבאללה, 2015 - מלחמה עם סוריה | B6: חוץ ובטחון
A7: תחנות רדיו - יש נוסחים שונים לשאלה "לאיזו תחנת רדיו אתה מאזין" | B7: תקשורת

Sheet איחוד שאלות
A1: שם | B1: שם חדש | C1: מדרגה 1 | D1: מדרגה 2 | E1: מדרגה 3 | F1: מדרגה 4 | G1: מדרגה 5 | H1: לשונית | I1: מדרגה 1 | J1: מדרגה 2 | K1: מדרגה 3 | L1: מדרגה 4 | M1: מדרגה 5 | N1: שם
A2: ID | B2: ID | C2: {=_xlfn.TEXTSPLIT('איחוד שאלות'!$B2,"_")} -> ID | H2: דמוגרפיה | I2: ID | N2: ID
A3: תאריך | B3: questionnaire_date | C3: {=_xlfn.TEXTSPLIT('איחוד שאלות'!$B3,"_")} -> questionnaire | D3: date | H3: דמוגרפיה | I3: questionnaire | J3: date | N3: תאריך
A4: תאריך פוסט בחירות | B4: questionnaire_date_post | C4: {=_xlfn.TEXTSPLIT('איחוד שאלות'!$B4,"_")} -> questionnaire | D4: date | E4: post | H4: דמוגרפיה | I4: questionnaire | J4: date | K4: post | N4: תאריך פוסט בחירות
A5: מקום הראיון | B5: questionnaire_location | C5: {=_xlfn.TEXTSPLIT('איחוד שאלות'!$B5,"_")} -> questionnaire | D5: location | H5: דמוגרפיה | I5: questionnaire | J5: location | N5: מקום הראיון
A6: סקטור | B6: demography_identity_sector | C6: {=_xlfn.TEXTSPLIT('איחוד שאלות'!$B6,"_")} -> demography | D6: identity | E6: sector | H6: דמוגרפיה | I6: demography | J6: identity | K6: sector | N6: סקטור
A7: פאנל | B7: questionnaire_panel | C7: {=_xlfn.TEXTSPLIT('איחוד שאלות'!$B7,"_")} -> questionnaire | D7: panel | H7: דמוגרפיה | I7: questionnaire | J7: panel | N7: פאנל
A8: גרסה | B8: questionnaire_version | C8: {=_xlfn.TEXTSPLIT('איחוד שאלות'!$B8,"_")} -> questionnaire | D8: version | H8: דמוגרפיה | I8: questionnaire | J8: version | N8: גרסה
A9: שפה | B9: questionnaire_language | C9: {=_xlfn.TEXTSPLIT('איחוד שאלות'!$B9,"_")} -> questionnaire | D9: language | H9: דמוגרפיה | I9: questionnaire | J9: language | N9: שפה
A10: גיל | B10: demography_age | C10: {=_xlfn.TEXTSPLIT('איחוד שאלות'!$B10,"_")} -> demography | D10: age | H10: דמוגרפיה | I10: demography | J10: age | N10: גיל
A11: כיצד היית מגדיר את עצמך? (עדה) | B11: demography_identity_jewishetnicity | C11: {=_xlfn.TEXTSPLIT('איחוד שאלות'!$B11,"_")} -> demography | D11: identity | E11: jewishetnicity | H11: דמוגרפיה | I11: demography | J11: identity | K11: jewishetnicity | N11: כיצד היית מגדיר את עצמך? (עדה)
A12: עדה | B12: demography_identity_jewishetnicity | C12: {=_xlfn.TEXTSPLIT('איחוד שאלות'!$B12,"_")} -> demography | D12: identity | E12: jewishetnicity | H12: דמוגרפיה | I12: demography | J12: identity | K12: jewishetnicity | N12: עדה
A13: לאיזו קבוצת גיל אתה משתייך? | B13: demography_age_group | C13: {=_xlfn.TEXTSPLIT('איחוד שאלות'!$B13,"_")} -> demography | D13: age | E13: group | H13: דמוגרפיה | I13: demography | J13: age | K13: group | N13: לאיזו קבוצת גיל אתה משתייך?
A14: מגדר | B14: demography_identity_gender | C14: {=_xlfn.TEXTSPLIT('איחוד שאלות'!$B14,"_")} -> demography | D14: identity | E14: gender | H14: דמוגרפיה | I14: demography | J14: identity | K14: gender | N14: מגדר
A15: מהי השכלתך? | B15: demography_educ | C15: {=_xlfn.TEXTSPLIT('איחוד שאלות'!$B15,"_")} -> demography | D15: educ | H15: דמוגרפיה | I15: demography | J15: educ | N15: מהי השכלתך?
A16: כמה שנים למדת במסגרת מסודרת? | B16: demography_educ_years | C16: {=_xlfn.TEXTSPLIT('איחוד שאלות'!$B16,"_")} -> demography | D16: educ | E16: years | H16: דמוגרפיה | I16: demography | J16: educ | K16: years | N16: כמה שנים למדת במסגרת מסודרת?
A17: האם למדת את לימודייך התיכוניים או העל-תיכוניים במסגרת דתית כלשהי? | B17: demography_educ_religious | C17: {=_xlfn.TEXTSPLIT('איחוד שאלות'!$B17,"_")} -> demography | D17: educ | E17: religious | H17: דמוגרפיה | I17: demography | J17: educ | K17: religious | N17: האם למדת את לימודייך התיכוניים או העל-תיכוניים במסגרת דתית כלשהי?
A18: מהי ההשכלה של בן/בת זוגך? | B18: demography_educ_partner | C18: {=_xlfn.TEXTSPLIT('איחוד שאלות'!$B18,"_")} -> demography | D18: educ | E18: partner | H18: דמוגרפיה | I18: demography | J18: educ | K18: partner | N18: מהי ההשכלה של בן/בת זוגך?
A19: האם יש לך תואר אקדמי? | B19: demography_educ_academy | C19: {=_xlfn.TEXTSPLIT('איחוד שאלות'!$B19,"_")} -> demography | D19: educ | E19: academy | H19: דמוגרפיה | I19: demography | J19: educ | K19: academy | N19: האם יש לך תואר אקדמי?
A20: מהו מוסד הלימודים האחרון בו למדת? | B20: demography_educ_last | C20: {=_xlfn.TEXTSPLIT('איחוד שאלות'!$B20,"_")} -> demography | D20: educ | E20: last | H20: דמוגרפיה | I20: demography | J20: educ | K20: last | N20: מהו מוסד הלימודים האחרון בו למדת?
A21: האם אתה אזרח ישראלי? | B21: attribute_identity_citizen | C21: {=_xlfn.TEXTSPLIT('איחוד שאלות'!$B21,"_")} -> attribute | D21: identity | E21: citizen | H21: דמוגרפיה | I21: attribute | J21: identity | K21: citizen | N21: האם אתה אזרח ישראלי?
A22: באיזו ארץ נולדת? | B22: demography_birthcountry_self | C22: {=_xlfn.TEXTSPLIT('איחוד שאלות'!$B22,"_")} -> demography | D22: birthcountry | E22: self | H22: דמוגרפיה | I22: demography | J22: birthcountry | K22: self | N22: באיזו ארץ נולדת?
A23: ארץ לידה/מוצא אב | B23: demography_birthcountry_father | C23: {=_xlfn.TEXTSPLIT('איחוד שאלות'!$B23,"_")} -> demography | D23: birthcountry | E23: father | H23: דמוגרפיה | I23: demography | J23: birthcountry | K23: father | N23: ארץ לידה/מוצא אב
A24: היכן נולד אביך? | B24: demography_birthcountry_father | C24: {=_xlfn.TEXTSPLIT('איחוד שאלות'!$B24,"_")} -> demography | D24: birthcountry | E24: father | H24: דמוגרפיה | I24: demography | J24: birthcountry | K24: father | N24: היכן נולד אביך?
A25: היכן נולדה אמך? | B25: demography_birthcountry_mother | C25: {=_xlfn.TEXTSPLIT('איחוד שאלות'!$B25,"_")} -> demography | D25: birthcountry | E25: mother | H25: דמוגרפיה | I25: demography | J25: birthcountry | K25: mother | N25: היכן נולדה אמך?
A26: באיזו ארץ נולד/ה בן/בת זוגך? | B26: demography_birthcountry_partner | C26: {=_xlfn.TEXTSPLIT('איחוד שאלות'!$B26,"_")} -> demography | D26: birthcountry | E26: partner | H26: דמוגרפיה | I26: demography | J26: birthcountry | K26: partner | N26: באיזו ארץ נולד/ה בן/בת זוגך?
A27: אם לא נולד בארץ, באיזו שנה עלית ארצה? | B27: demography_imm_year | C27: {=_xlfn.TEXTSPLIT('איחוד שאלות'!$B27,"_")} -> demography | D27: imm | E27: year | H27: דמוגרפיה | I27: demography | J27: imm | K27: year | N27: אם לא נולד בארץ, באיזו שנה עלית ארצה?
A28: האם נולדת באחת מארצות ברה"מ ועלית ארצה אחרי 1988? | B28: demography_imm_USSR | C28: {=_xlfn.TEXTSPLIT('איחוד שאלות'!$B28,"_")} -> demography | D28: imm | E28: USSR | H28: דמוגרפיה | I28: demography | J28: imm | K28: USSR | N28: האם נולדת באחת מארצות ברה"מ ועלית ארצה אחרי 1988?
A29: באיזו עיר בברה"מ לשעבר גרת לפני שעלית ארצה? | B29: demography_imm_USSR_residence | C29: {=_xlfn.TEXTSPLIT('איחוד שאלות'!$B29,"_")} -> demography | D29: imm | E29: USSR | F29: residence | H29: דמוגרפיה | I29: demography | J29: imm | K29: USSR | L29: residence | N29: באיזו עיר בברה"מ לשעבר גרת לפני שעלית ארצה?
A30: מה היה הלאום שהיה רשום בפספורט הסובייטי הפנימי שלך? | B30: demography_imm_USSR_nationality | C30: {=_xlfn.TEXTSPLIT('איחוד שאלות'!$B30,"_")} -> demography | D30: imm | E30: USSR | F30: nationality | H30: דמוגרפיה | I30: demography | J30: imm | K30: USSR | L30: nationality | N30: מה היה הלאום שהיה רשום בפספורט הסובייטי הפנימי שלך?
A31: לגבי החברים שלך בארץ, היית אומר שהרוב: | B31: ???_friends_imm_USSR | C31: {=_xlfn.TEXTSPLIT('איחוד שאלות'!$B31,"_")} -> ??? | D31: friends | E31: imm | F31: USSR | H31: דמוגרפיה | I31: ??? | J31: friends | K31: imm | L31: USSR | N31: לגבי החברים שלך בארץ, היית אומר שהרוב:
A32: איזה מבין המונחים הבאים מגדיר בצורה הטובה ביותר את זהותך? | B32: demography_identity_hierarchy_1 | C32: {=_xlfn.TEXTSPLIT('איחוד שאלות'!$B32,"_")} -> demography | D32: identity | E32: hierarchy | F32: 1 | H32: דמוגרפיה | I32: demography | J32: identity | K32: hierarchy | L32: 1 | N32: איזה מבין המונחים הבאים מגדיר בצורה הטובה ביותר את זהותך?
A33: והשני? | B33: demography_identity_hierarchy_2 | C33: {=_xlfn.TEXTSPLIT('איחוד שאלות'!$B33,"_")} -> demography | D33: identity | E33: hierarchy | F33: 2 | H33: דמוגרפיה | I33: demography | J33: identity | K33: hierarchy | L33: 2 | N33: והשני?
A34: והשלישי? | B34: demography_identity_hierarchy_3 | C34: {=_xlfn.TEXTSPLIT('איחוד שאלות'!$B34,"_")} -> demography | D34: identity | E34: hierarchy | F34: 3 | H34: דמוגרפיה | I34: demography | J34: identity | K34: hierarchy | L34: 3 | N34: והשלישי?
A35: והרביעי? | B35: demography_identity_hierarchy_4 | C35: {=_xlfn.TEXTSPLIT('איחוד שאלות'!$B35,"_")} -> demography | D35: identity | E35: hierarchy | F35: 4 | H35: דמוגרפיה | I35: demography | J35: identity | K35: hierarchy | L35: 4 | N35: והרביעי?
A36: לאיזה מעמד חברתי אתה משייך את עצמך? | B36: demography_identity_class | C36: {=_xlfn.TEXTSPLIT('איחוד שאלות'!$B36,"_")} -> demography | D36: identity | E36: class | H36: דמוגרפיה | I36: demography | J36: identity | K36: class | N36: לאיזה מעמד חברתי אתה משייך את עצמך?
A37: ההוצאה החודשית הממוצעת של משפחה בישראל היא כ-16,500 ₪. בהתחשב בכל ההוצאות של משפחתכם, האם אתם מוציאים: | B37: demography_wealth_household_expense | C37: {=_xlfn.TEXTSPLIT('איחוד שאלות'!$B37,"_")} -> demography | D37: wealth | E37: household | F37: expense | H37: דמוגרפיה | I37: demography | J37: wealth | K37: household | L37: expense | N37: ההוצאה החודשית הממוצעת של משפחה בישראל היא כ-16,500 ₪. בהתחשב בכל ההוצאות של משפחתכם, האם אתם מוציאים:
A38: כמה כסף מוציאה המשפחה שלכם בממוצע בחודש? | B38: demography_wealth_household_expense | C38: {=_xlfn.TEXTSPLIT('איחוד שאלות'!$B38,"_")} -> demography | D38: wealth | E38: household | F38: expense | H38: דמוגרפיה | I38: demography | J38: wealth | K38: household | L38: expense | N38: כמה כסף מוציאה המשפחה שלכם בממוצע בחודש?
A39: חשוב על הכנסותיהם של כל בני הבית ועל כל ההכנסות במתקבלות במשק הבית בכללו. מהו מקור ההכנסה העיקרי של משק הבית שלך? | B39: demography_wealth_household_incomeprimery | C39: {=_xlfn.TEXTSPLIT('איחוד שאלות'!$B39,"_")} -> demography | D39: wealth | E39: household | F39: incomeprimery | H39: דמוגרפיה | I39: demography | J39: wealth | K39: household | L39: incomeprimery | N39: חשוב על הכנסותיהם של כל בני הבית ועל כל ההכנסות במתקבלות במשק הבית בכללו. מהו מקור ההכנסה העיקרי של משק הבית שלך?
A40: מהי ההכנסה של משק הבית שלך מכל המקורות, אחרי ניכוי מיסים וניכויי חובה אחרים? | B40: demography_wealth_household_incomehousehold | C40: {=_xlfn.TEXTSPLIT('איחוד שאלות'!$B40,"_")} -> demography | D40: wealth | E40: household | F40: incomehousehold | H40: דמוגרפיה | I40: demography | J40: wealth | K40: household | L40: incomehousehold | N40: מהי ההכנסה של משק הבית שלך מכל המקורות, אחרי ניכוי מיסים וניכויי חובה אחרים?
...

Sheet סופי סופי
A1: לשונית | B1: מדרגה1 | C1: מדרגה 2 | D1: מדרגה 3 | E1: מדרגה 4 | F1: מדרגה 5 | G1: מדרגה 6 | H1: שאלה
A2: ישראל כללי | B2: affect | C2: affinity | D2: country | E2: USA | F2: leaning | H2: לאן, בכל זאת נוטה דעתך לגבי ארה"ב, לכיוון דעה טובה או לכיוון דעה רעה?
A3: ישראל כללי | B3: affect | C3: affinity | D3: country | E3: USA | H3: מהי הרגשתך לגבי ארה"ב? האם יש לך דעה טובה או רעה עליה?
A4: שלום | B4: affect | C4: affinity | D4: groups | E4: arabs | F4: friend | H4: האם היית מוכן לקשור קשרי ידידות עם בן הלאום הערבי?
A5: שלום | B5: affect | C5: affinity | D5: groups | E5: arabs | F5: household | H5: האם היית מוכן לגור בבית שגרה בו משפחה ערבית?
A6: זיקה רגשית | B6: affect | C6: affinity | D6: groups | E6: arabs | H6: מה יחסך לערבים?
A7: זיקה רגשית | B7: affect | C7: affinity | D7: groups | E7: jewishetnicity | F7: ashkenazis | H7: מה יחסך לאשכנזים?
A8: כלכלה-חברה | B8: affect | C8: affinity | D8: groups | E8: jewishetnicity | F8: friends | H8: האם היית מוכן לקשור קשרי ידידות עם בן עדה שונה משלך?
A9: כלכלה-חברה | B9: affect | C9: affinity | D9: groups | E9: jewishetnicity | F9: household | H9: האם היית מוכן לגור בבית שבו גרים גם בני עדה שונה משלך?
A10: כלכלה-חברה | B10: affect | C10: affinity | D10: groups | E10: jewishetnicity | F10: marriage | H10: האם היית מוכן להינשא לבת עדה שונה משלך?
A11: זיקה רגשית | B11: affect | C11: affinity | D11: groups | E11: jewishetnicity | F11: sephardic | H11: מה יחסך לספרדים?
A12: זיקה רגשית | B12: affect | C12: affinity | D12: groups | E12: leftists | H12: על סולם שבו 0 משמעו דחייה ושנאה, 10 משמעו תמיכה ואהדה ו-5 משמעו אמצע, מה יחסך לשמאלנים?
A13: ימין-שמאל | B13: affect | C13: affinity | D13: groups | E13: leftright | F13: appreciated | H13: כשאנשים אומרים דברים טובים על (ימנים/שמאלנים/תומכים של המרכז) זה גורם לך הרגשה טובה
A14: ימין-שמאל | B14: affect | C14: affinity | D14: groups | E14: leftright | F14: close | H14: כשאתה פוגש תומך אחר של (הימין/שמאל/מרכז) אתה מרגיש קשור אליו
A15: ימין-שמאל | B15: affect | C15: affinity | D15: groups | E15: leftright | F15: insult | H15: באיזו מידה אתה מסכים או לא מסכים עם כל אחת מן הטענות הבאות: כשמישהו מעביר ביקורת על (ימנים/שמאלנים/תומכים של המרכז) זה מרגיש לך כמו עלבון אישי
A16: זיקה רגשית | B16: affect | C16: affinity | D16: groups | E16: party | F16: appreciated | H16: כשאנשים אומרים דברים טובים על תומכים של (המפלגה שציין) זה גורם לך להרגשה טובה
A17: זיקה רגשית | B17: affect | C17: affinity | D17: groups | E17: party | F17: close | H17: כשאתה פוגש מישהו שתומך ב(המפלגה שציין) אתה מרגיש קשור אליו
A18: זיקה רגשית | B18: affect | C18: affinity | D18: groups | E18: party | F18: insult | H18: באיזו מידה אתה מסכים או לא מסכים עם כל אחת מן הטענות הבאות: כשמישהו מעביר ביקורת על תומכים של (המפלגה שציין) זה מרגיש לך כמו עלבון אישי
A19: זיקה רגשית | B19: affect | C19: affinity | D19: groups | E19: religious | H19: מה יחסך לדתיים?
A20: זיקה רגשית | B20: affect | C20: affinity | D20: groups | E20: rightist | H20: על סולם שבו 0 משמעו דחייה ושנאה, 10 משמעו תמיכה ואהדה ו-5 משמעו אמצע, מה יחסך לימנים?
A21: זיקה רגשית | B21: affect | C21: affinity | D21: groups | E21: secular | H21: מה יחסך לחילונים?
A22: זיקה רגשית | B22: affect | C22: affinity | D22: groups | E22: ultraorthodox | H22: מה יחסך לחרדים?
A23: זיקה רגשית | B23: affect | C23: affinity | D23: organisations | E23: gushemunim | H23: מה יחסך לתנועת גוש אמונים?
A24: זיקה רגשית | B24: affect | C24: affinity | D24: organisations | E24: hatnuahaislamit | H24: מה יחסך לתנועה האסלאמית?
A25: זיקה רגשית | B25: affect | C25: affinity | D25: organisations | E25: moetzetyesha | H25: מה יחסך למועצת יש"ע?
A26: זיקה רגשית | B26: affect | C26: affinity | D26: organisations | E26: shalomachshav | H26: מה יחסך לתנועת שלום עכשיו?
A27: זיקה רגשית | B27: affect | C27: affinity | D27: parties | E27: 2 | H27: מהי המפלגה השנייה הכי קרובה אליך?
A28: זיקה רגשית | B28: affect | C28: affinity | D28: parties | E28: 3 | H28: מהי המפלגה השלישית הכי קרובה אליך?
A29: זיקה רגשית | B29: affect | C29: affinity | D29: parties | E29: 4 | H29: מהמפלגות הנותרות, איך היית מדרג את מידת הקרבה אלייך: מי הראשונה?
A30: זיקה רגשית | B30: affect | C30: affinity | D30: parties | E30: 5 | H30: מהמפלגות הנותרות, איך היית מדרג את מידת הקרבה אלייך: מי השנייה?
... A36: זיקה רגשית | B36: affect | C36: affinity | D36: parties | E36: binary | H36: באופן כללי, האם אתה רואה את עצמך קרוב למפלגה מסוימת?
A37: זיקה רגשית | B37: affect | C37: affinity | D37: parties | E37: closest | F37: XXXX | H37: לאיזו מפלגה אתה חש הכי קרוב?
A38: זיקה רגשית | B38: affect | C38: affinity | D38: parties | E38: closest | F38: XXXX | H38: מהי המפלגה המועדפת עליך?
A39: זיקה רגשית | B39: affect | C39: affinity | D39: parties | E39: closest | F39: XXXX | H39: באיזו מפלגה אתה תומך יותר מכל היתר?
A40: זיקה רגשית | B40: affect | C40: affinity | D40: parties | E40: closest | F40: XXXX | H40: ובמקום השני?
A41: זיקה רגשית | B41: affect | C41: affinity | D41: parties | E41: closest | F41: XXXX | H41: ובמקום השלישי?
A42: זיקה רגשית | B42: affect | C42: affinity | D42: parties | E42: closest | F42: XXXX | H42: מהי המפלגה הכי פחות מועדפת עליך?
A43: זיקה רגשית | B43: affect | C43: affinity | D43: parties | E43: closest | F43: XXXX | H43: ובמקום השני?
A44: זיקה רגשית | B44: affect | C44: affinity | D44: parties | E44: closest | F44: XXXX | H44: ובמקום השלישי?
A45: ייצוגיות | B45: affect | C45: affinity | D45: parties | E45: closest | H45: לאיזו מפלגה אתה מרגיש הכי קרוב?
...

Sheet דמוגרפיה
A1: שאלה | B1: 2025 | C1: 2022 | D1: 2021 | E1: 2020 | F1: 43709 | G1: 43556 | H1: 2015 | I1: 2013 | J1: 2009 | K1: 2006 | L1: 2003 | M1: 2001 | N1: 1999 | O1: 1996 | P1: 1992 | Q1: 1987* | R1: 1988* | S1: 1988 | T1: 1984 | U1: 1981 - 3 | V1: 1981 - 2 | W1: 1981 - 1 | X1: 1977 - 4 | Y1: 1977 - 3 | Z1: 1977 - 2 | AA1: 1977 - 1 | AB1: 1973 - 5 | AC1: 1973 - 4 | AD1: 1973 - 3 | AE1: 1973 - 2 | AF1: 1973 - 1 | AG1: 1969 - 3 | AH1: 1969 - 2 | AI1: 1969 - 1 | AK1: מספר חזרות | AM1: ספירה 84-19 | AO1: סה"כ מעל שתי חזרות
A2: ID | B2: resp_id | C2: ID | D2: resp_id | E2: id | F2: c_resp_id_~e | G2: resp_id | H2: ID | I2: id | K2: caseid | L2: id1 | M2: a1 | N2: v1 | P2: a1 | Q2: v1 | T2: v1 | U2: v1 | V2: v1 | W2: v1 | X2: v1 | Y2: v1 | Z2: v1 | AA2: v1 | AB2: v1 | AC2: v1 | AD2: v1 | AE2: v1 | AF2: v1 | AG2: b2 | AH2: a2 | AI2: a1 | AK2: =COUNTA(C2:AI2) -> 29 | AM2: =COUNTA(G2:P2,S2:T2) -> 9 | AO2: =COUNTIF(AM2:AM87,">=2") -> 43
A3: תאריך | B3: date | C3: date | D3: date | E3: date | F3: c_date_before | G3: date | H3: date | I3: date | M3: b51 | N3: c41 | O3: cccc26 | P3: i70 | R3: c66 | S3: g91 | V3: a161 | AA3: v3 | AB3: h66 | AC3: g68 | AG3: c60 | AH3: d32 | AK3: =COUNTA(C3:AI3) -> 19 | AM3: =COUNTA(G3:P3,S3:T3) -> 8
A4: תאריך פוסט בחירות | C4: date_after | D4: date_after | E4: date_after | F4: d_date_after | G4: date_after | H4: after_date | I4: a_date | AK4: =COUNTA(C4:AI4) -> 7 | AM4: =COUNTA(G4:P4,S4:T4) -> 3
A5: מקום הראיון | H5: v146 | I5: v151 | J5: v193 | K5: c90 | L5: b93 | M5: b48 | N5: c40 | O5: cccc28 | P5: i68 | R5: c64 | S5: g87 | T5: a65 | U5: b159 | V5: a160 | W5: v151 | AA5: v2 | AB5: h65 | AC5: g67 | AG5: c57 | AH5: d29 | AK5: =COUNTA(C5:AI5) -> 20 | AM5: =COUNTA(G5:P5,S5:T5) -> 11
A6: סקטור | C6: sector | D6: sector | E6: sector | F6: c149 | G6: v149 | H6: v148 | I6: v153 | J6: v195 | N6: cccc41 | AK6: =COUNTA(C6:AI6) -> 9 | AM6: =COUNTA(G6:P6,S6:T6) -> 5
A7: פאנל | J7: panel | R7: c67 | S7: g93 | AK7: =COUNTA(C7:AI7) -> 3 | AM7: =COUNTA(G7:P7,S7:T7) -> 2
A8: גרסה | C8: VERSION | F8: girsa_c | G8: version | H8: version | I8: version | J8: version | K8: c94 | L8: b99 | AK8: =COUNTA(C8:AI8) -> 8 | AM8: =COUNTA(G8:P8,S8:T8) -> 6
A9: שפה | C9: LANGUAGE | M9: b55 | AK9: =COUNTA(C9:AI9) -> 2 | AM9: =COUNTA(G9:P9,S9:T9) -> 1
A10: גיל | B10: age | C10: age | D10: age | E10: age | G10: age | H10: age | I10: age | J10: age_1 | K10: c54 | L10: b74 | M10: b24 | N10: c20 | O10: ccc57 | P10: i61 | Q10: a95 | R10: c57 | S10: g78 | T10: a54 | U10: b137 | V10: a151 | W10: v134 | X10: c24 | Y10: b17 | Z10: a17 | AA10: v116 | AB10: h60 | AC10: g62 | AD10: f54 | AE10: e17 | AF10: b25 | AG10: c30 | AH10: d11 | AI10: c79 | AK10: =COUNTA(C10:AI10) -> 32 | AM10: =COUNTA(G10:P10,S10:T10) -> 12
A11: עדה | O11: sephashk | AK11: =COUNTA(C11:AI11) -> 1 | AM11: =COUNTA(G11:P11,S11:T11) -> 1
A12: לאיזו קבוצת גיל אתה משתייך? | B12: agegroup | C12: age_group | D12: agegroup | E12: agegroup | G12: agegroup | H12: agegroup | I12: age_group | J12: agegroup_1 | AK12: =COUNTA(C12:AI12) -> 7 | AM12: =COUNTA(G12:P12,S12:T12) -> 4
A13: מגדר | B13: gender | C13: sex | D13: gender | E13: gender | G13: gender | H13: sex | I13: sex | J13: sex_1 | K13: c89 | L13: b92 | M13: b47 | N13: c39 | O13: ccc56 | P13: i67 | Q13: a119 | S13: g104 | T13: a58 | U13: b138 | V13: a146 | W13: v135 | X13: c19 | Y13: b12 | Z13: a12 | AA13: v111 | AB13: h57 | AC13: g59 | AD13: f52 | AE13: e16 | AF13: b23 | AG13: c29 | AH13: d4 | AI13: c71 | AK13: =COUNTA(C13:AI13) -> 31 | AM13: =COUNTA(G13:P13,S13:T13) -> 12
A14: מהי השכלתך? | B14: educ | C14: educ | D14: educ | E14: educ | G14: educ | H14: v128 | I14: v137 | AK14: =COUNTA(C14:AI14) -> 6 | AM14: =COUNTA(G14:P14,S14:T14) -> 3
A15: כמה שנים למדת במסגרת מסודרת? | H15: v127 | I15: v136 | J15: v181_1 | K15: c75 | L15: b82 | M15: b38 | N15: c28 | O15: ccc63 | P15: i62 | Q15: a99 | R15: c58 | S15: g80 | T15: a53 | U15: b139 | V15: a147 | W15: v136 | X15: c20 | Y15: b13 | Z15: a13 | AA15: v112 | AB15: h59 | AC15: g61 | AD15: f53 | AF15: b26 | AG15: c32 | AH15: d16 | AI15: c85 | AK15: =COUNTA(C15:AI15) -> 27 | AM15: =COUNTA(G15:P15,S15:T15) -> 11
A16: האם אתה אזרח ישראלי? | B16: Citizenship | C16: CITIZEN | E16: v5 | G16: v5 | H16: v5 | I16: v5 | J16: v5 | AK16: =COUNTA(C16:AI16) -> 6 | AM16: =COUNTA(G16:P16,S16:T16) -> 4
A17: באיזו ארץ נולדת? | H17: v115 | J17: v176 | K17: c57 | AG17: c43 | AH17: d5 | AI17: c73 | AK17: =COUNTA(C17:AI17) -> 6 | AM17: =COUNTA(G17:P17,S17:T17) -> 3
A18: ארץ לידה/מוצא אב | B18: v513 | C18: v513 | D18: v513 | E18: v513 | G18: v131 | H18: v117 | I18: v133 | L18: b77 | M18: b33 | N18: c26 | O18: ccc59 | P18: i52 | Q18: a97 | R18: c48 | S18: g68 | T18: a49 | U18: b140 | V18: a157 | W18: v137 | X18: a29 | Y18: b22 | Z18: a22 | AA18: v123 | AB18: h64 | AC18: g66 | AD18: f58 | AE18: e19 | AF18: b38 | AG18: c45 | AH18: d8 | AI18: c76 | AK18: =COUNTA(C18:AI18) -> 30 | AM18: =COUNTA(G18:P18,S18:T18) -> 10
A19: אם לא נולד בארץ, באיזו שנה עלית ארצה? | B19: v134 | C19: v134 | D19: v134 | E19: v134 | G19: v134 | H19: v118 | I19: v134 | J19: v177 | K19: c60 | L19: b79 | M19: b35 | N19: c27 | O19: ccc61 | P19: i53 | Q19: a98 | R19: c49 | S19: g70 | T19: a50 | U19: b141 | V19: a158 | W19: v138 | X19: c30 | Y19: b23 | Z19: a23 | AA19: v124 | AF19: b39 | AG19: c48 | AH19: d15 | AI19: c84 | AK19: =COUNTA(C19:AI19) -> 28 | AM19: =COUNTA(G19:P19,S19:T19) -> 12
A20: כיצד היית מגדיר את עצמך? (עדה) | B20: v131 | C20: v131 | E20: v135 | G20: v135 | H20: v120 | O20: ccc55 | P20: i51 | Q20: a96 | R20: c47 | S20: g67 | T20: a47 | AK20: =COUNTA(C20:AI20) -> 10 | AM20: =COUNTA(G20:P20,S20:T20) -> 6
A21: האם נולדת באחת מארצות ברה"מ ועלית ארצה אחרי 1988? | M21: b37 | AK21: =COUNTA(C21:AI21) -> 1 | AM21: =COUNTA(G21:P21,S21:T21) -> 1
A22: איזה מבין המונחים הבאים מגדיר בצורה הטובה ביותר את זהותך? | C22: v707a | J22: v164 | K22: c43 | M22: b29 | N22: c22 | O22: ccc47 | AK22: =COUNTA(C22:AI22) -> 6 | AM22: =COUNTA(G22:P22,S22:T22) -> 5
A23: והשני? | C23: v707b | J23: v165 | K23: c44 | M23: b30 | N23: c23 | O23: ccc48 | AK23: =COUNTA(C23:AI23) -> 6 | AM23: =COUNTA(G23:P23,S23:T23) -> 5
A24: והשלישי? | C24: v707c | J24: v166 | K24: c45 | M24: b31 | N24: c24 | O24: ccc49 | AK24: =COUNTA(C24:AI24) -> 6 | AM24: =COUNTA(G24:P24,S24:T24) -> 5
A25: והרביעי? | J25: v167 | K25: c46 | M25: b32 | N25: c25 | O25: ccc50 | AK25: =COUNTA(C25:AI25) -> 5 | AM25: =COUNTA(G25:P25,S25:T25) -> 5
A26: האם למדת את לימודייך התיכוניים או העל-תיכוניים במסגרת דתית כלשהי? | C26: v137 | D26: v137 | E26: v137 | G26: v137 | H26: v129 | I26: v138 | AK26: =COUNTA(C26:AI26) -> 6 | AM26: =COUNTA(G26:P26,S26:T26) -> 3
A27: ההוצאה החודשית הממוצעת של משפחה בישראל היא כ-16,500 ₪. בהתחשב בכל ההוצאות של משפחתכם, האם אתם מוציאים: | B27: v139 | C27: v139 | D27: v139 | E27: v139 | G27: v139 | H27: v134 | J27: v184 | K27: c80 | L27: b85 | M27: b41 | N27: c30 | O27: ccc74 | P27: i65 | Q27: a105 | R27: c62 | S27: g85 | T27: a55 | AK27: =COUNTA(C27:AI27) -> 16 | AM27: =COUNTA(G27:P27,S27:T27) -> 11
A28: כמה כסף מוציאה המשפחה שלכם בממוצע בחודש? | U28: b158 | W28: v150 | AK28: =COUNTA(C28:AI28) -> 2 | AM28: =COUNTA(G28:P28,S28:T28) -> 0
A29: מה מספר החדרים שיש לכם בבית? | C29: v140 | D29: v140 | E29: v140 | G29: v140 | H29: v135 | I29: v146 | J29: v186 | K29: c82 | L29: b87 | M29: b42 | N29: c34 | O29: ccc65 | P29: i63 | Q29: a106 | R29: c60 | S29: g83 | U29: b149 | V29: a148 | W29: v144 | X29: c21 | Y29: b14 | Z29: a14 | AA29: v113 | AF29: b40 | AK29: =COUNTA(C29:AI29) -> 24 | AM29: =COUNTA(G29:P29,S29:T29) -> 11
A30: מה מספר הנפשות המתגוררות בבית? (כולל חיילים) | C30: v141 | D30: v141 | E30: v141 | G30: v141 | H30: v136 | I30: v147 | J30: v187 | K30: c84 | L30: b88 | M30: b44 | N30: c35 | O30: ccc67 | P30: i64 | Q30: a107 | R30: c61 | S30: g84 | U30: b151 | V30: a149 | W30: v145 | X30: c22 | Y30: b15 | Z30: a15 | AA30: v114 | AF30: b41 | AG30: c52 | AK30: =COUNTA(C30:AI30) -> 25 | AM30: =COUNTA(G30:P30,S30:T30) -> 11
A31: צפיפות בבית | T31: a57 | AG31: c50 | AH31: d26 | AI31: c56 | AK31: =COUNTA(C31:AI31) -> 4 | AM31: =COUNTA(G31:P31,S31:T31) -> 1
A32: מהי דתך? | B32: v143 | C32: v143_code | D32: v143_code | E32: v143_code | G32: v143_code | H32: v138 | I32: v149 | J32: v189_1 | K32: c87 | L32: b90 | M32: b28 | O32: ccc75 | AK32: =COUNTA(C32:AI32) -> 11 | AM32: =COUNTA(G32:P32,S32:T32) -> 8
A33: כיצד היית מגדיר את עצמך מבחינה דתית? | B33: religiosity | C33: v144 | D33: v144 | E33: v144 | G33: v144 | H33: v139 | I33: v150 | J33: v190 | K33: c88 | L33: b91 | M33: b27 | N33: c38 | AK33: =COUNTA(C33:AI33) -> 11 | AM33: =COUNTA(G33:P33,S33:T33) -> 8
A34: מהו מצבך המשפחתי? | G34: v129 | H34: v111 | I34: v126 | P34: i54 | Q34: a69 | R34: c24 | S34: g34 | U34: b144 | V34: a154 | W34: v142 | AA34: v119 | AE34: e18 | AF34: b43 | AG34: c36 | AH34: d13 | AI34: c81 | AK34: =COUNTA(C34:AI34) -> 16 | AM34: =COUNTA(G34:P34,S34:T34) -> 5
A35: באיזו מידה אתה נוהג לשמור על המסורת הדתית? | B35: v132 | C35: v130 | G35: v130 | H35: v114 | I35: v132 | J35: v175 | K35: c56 | L35: b76 | M35: b26 | N35: c21 | O35: ccc70 | P35: i50 | Q35: a100 | R35: c46 | S35: g66 | T35: a48 | U35: b145 | V35: a155 | W35: v143 | X35: c26 | Y35: b19 | Z35: a19 | AA35: v120 | AB35: h62 | AC35: g64 | AD35: f56 | AF35: b37 | AG35: c20 | AH35: c30 | AI35: c49 | AK35: =COUNTA(C35:AI35) -> 29 | AM35: =COUNTA(G35:P35,S35:T35) -> 12
A36: האם אתה נוסע בשבת? | U36: b146 | AI36: c68 | AK36: =COUNTA(C36:AI36) -> 2 | AM36: =COUNTA(G36:P36,S36:T36) -> 0
A37: האם אתה אוכל רק אוכל כשר? | U37: b147 | AI37: c70 | AK37: =COUNTA(C37:AI37) -> 2 | AM37: =COUNTA(G37:P37,S37:T37) -> 0
A38: כמה פעמים בשנה אתה נוהג לבקר בבית כנסת? | U38: b148 | AH38: c29 | AK38: =COUNTA(C38:AI38) -> 2 | AM38: =COUNTA(G38:P38,S38:T38) -> 0
A39: היכן נולד אביך? | G39: v132 | H39: v116 | J39: v179 | K39: c69 | AG39: c44 | AH39: d7 | AI39: c74 | AK39: =COUNTA(C39:AI39) -> 7 | AM39: =COUNTA(G39:P39,S39:T39) -> 4
A40: היכן נולדה אמך? | G40: v133 | J40: v180 | K40: c72 | AG40: c47 | AH40: d10 | AI40: c77 | AK40: =COUNTA(C40:AI40) -> 6 | AM40: =COUNTA(G40:P40,S40:T40) -> 3
...

Sheet ישראל כללי
A1: שאלה | B1: 2025 | C1: 2022 | D1: 2021 | E1: 2020 | F1: 43709 | G1: 43556 | H1: 2015 | I1: 2013 | J1: 2009 | K1: 2006 | L1: 2003 | M1: 2001 | N1: 1999 | O1: 1996 | P1: 1992 | Q1: 1987* | R1: 1988* | S1: 1988 | T1: 1984 | U1: 1981 - 3 | V1: 1981 - 2 | W1: 1981 - 1 | X1: 1977 - 4 | Y1: 1977 - 3 | Z1: 1977 - 2 | AA1: 1977 - 1 | AB1: 1973 - 5 | AC1: 1973 - 4 | AD1: 1973 - 3 | AE1: 1973 - 2 | AF1: 1973 - 1 | AG1: 1969 - 3 | AH1: 1969 - 2 | AI1: 1969 - 1 | AK1: מספר חזרות | AM1: ספירה 84-19 | AO1: סה"כ מעל שתי חזרות
A2: מהו לדעתך מצבה של ישראל באופן כללי? | C2: v6 | D2: v6 | E2: v6 | G2: v6 | H2: v6 | I2: v6 | J2: v6 | K2: a6 | L2: a6 | M2: a6 | N2: v3 | O2: c6 | P2: a2 | R2: b2 | S2: f6 | T2: v2 | U2: b2 | V2: a2 | W2: v2 | AA2: v4 | AK2: =COUNTA(C2:AI2) -> 20 | AM2: =COUNTA(G2:P2,S2:T2) -> 12 | AO2: =COUNTIF(AM2:AM150,">=2") -> 14
A3: מה דעתך על הדרך שבה מטפלת הממשלה בבעיות שישנן כיום במדינה? | G3: v7 | H3: v7 | I3: v7 | J3: v7 | K3: a7 | L3: a7 | M3: a7 | N3: v4 | O3: c7 | P3: a3 | R3: b3 | S3: f7 | T3: v3 | U3: b3 | V3: a3 | W3: v3 | AA3: v5 | AI3: a83 | AK3: =COUNTA(C3:AI3) -> 18 | AM3: =COUNTA(G3:P3,S3:T3) -> 12
A4: מהי לדעתך הבעיה החשובה ביותר שעל הממשלה לטפל בה? | B4: v8 | C4: v8_code1 | D4: v8c | E4: v8_code | F4: c8_code | G4: v8_code | H4: v8 | I4: v8 | J4: v8 | K4: a8 | L4: a8 | M4: a8 | N4: v5 | O4: c8 | P4: a7 | Q4: a52 | R4: b8 | S4: f11 | T4: v4 | U4: b6 | V4: a4 | W4: v4 | Y4: b2 | Z4: a2 | AA4: v6 | AC4: g2 | AD4: f42 | AE4: c51 | AF4: v27 | AH4: b23 | AI4: b29 | AK4: =COUNTA(C4:AI4) -> 30 | AM4: =COUNTA(G4:P4,S4:T4) -> 12
A5: והבעיה השנייה הכי חשובה? | C5: v8_code2 | AC5: g3 | AD5: f43 | AE5: c52 | AF5: v28 | AH5: b24 | AI5: b30 | AK5: =COUNTA(C5:AI5) -> 7 | AM5: =COUNTA(G5:P5,S5:T5) -> 0
A6: והבעיה השלישית הכי חשובה? | C6: v8_code3 | AH6: b25 | AI6: b31 | AK6: =COUNTA(C6:AI6) -> 3 | AM6: =COUNTA(G6:P6,S6:T6) -> 0
A7: האם אתה מאמין שהממשלה תפתור בקרוב את שתי הבעיות שציינת? | AE7: c53 | AF7: v29 | AK7: =COUNTA(C7:AI7) -> 2 | AM7: =COUNTA(G7:P7,S7:T7) -> 0
A8: מי מהמועמדים לראשות הממשלה יוכל לטפל טוב יותר בבעיה? | N8: v6 | O8: c10 | U8: b5 | AK8: =COUNTA(C8:AI8) -> 3 | AM8: =COUNTA(G8:P8,S8:T8) -> 2
A9: איזו מפלגה תוכל לטפל טוב יותר בבעיה שציינת? | O9: c11 | P9: a8 | R9: b9 | S9: f13 | T9: v6 | W9: v6 | AA9: v9 | AK9: =COUNTA(C9:AI9) -> 7 | AM9: =COUNTA(G9:P9,S9:T9) -> 4
A10: מהי לדעתך הבעיה החשובה ביותר שעל הממשלה לטפל בה? (אחרי הבחירות) | N10: d2 | AK10: =COUNTA(C10:AI10) -> 1 | AM10: =COUNTA(G10:P10,S10:T10) -> 1
A11: בסך הכל, מי יטפל טוב יותר בכלל בעיות המדינה - הצוות של המערך או הצוות של הליכוד? | T11: v25 | AK11: =COUNTA(C11:AI11) -> 1 | AM11: =COUNTA(G11:P11,S11:T11) -> 1
A12: מבין הדברים הבאים, מה לדעתך הכי מאיים על המערכת הפוליטית כיום? | AK12: =COUNTA(C12:AI12) -> 0 | AM12: =COUNTA(G12:P12,S12:T12) -> 0
A13: באיזו מידה אתה מרוצה מהאופן בו המערכת הפוליטית בישראל מתפקדת כיום? | C13: v116 | D13: v116 | E13: v116 | G13: v116 | AK13: =COUNTA(C13:AI13) -> 4 | AM13: =COUNTA(G13:P13,S13:T13) -> 1
A14: כאשר אתה חושב על תולדות מדינת ישראל ועם ישראל, איזה אירוע מהעבר נראה לך החשוב ביותר? | I14: a_v17 | AK14: =COUNTA(C14:AI14) -> 1 | AM14: =COUNTA(G14:P14,S14:T14) -> 1
A15: כאשר אתה חושב על העתיד של מדינת ישראל ועם ישראל, איזה אירוע או התרחשות הייתה רוצה לראות? | I15: a_v18 | AK15: =COUNTA(C15:AI15) -> 1 | AM15: =COUNTA(G15:P15,S15:T15) -> 1
A16: מיהי, לדעתך, הדמות המשמעותית ביותר בתולדות מדינת ישראל ועם ישראל? | I16: a_v19 | AK16: =COUNTA(C16:AI16) -> 1 | AM16: =COUNTA(G16:P16,S16:T16) -> 1
A17: באיזו מידה אתה מסכים או לא מסכים עם המשפטים הבאים: לפעמים הפוליטיקה נראית כ"כ מסובכת שאדם כמוני לא יכול להבין באמת מה קורה | B17: v33 | C17: v33 | H17: v33 | I17: v32 | AK17: =COUNTA(C17:AI17) -> 3 | AM17: =COUNTA(G17:P17,S17:T17) -> 2
A18: באיזו מידה אתה מסכים או לא מסכים עם המשפטים הבאים: יש לגרש מהארץ את העובדים הזרים שאין להם רשיון עבודה וגם את ילדיהם | I18: v40 | AK18: =COUNTA(C18:AI18) -> 1 | AM18: =COUNTA(G18:P18,S18:T18) -> 1
A19: לפעמים, אנשים שואלים את עצמם מה צריכות להיות המטרות של המדינה לעשר השנים הבאות? מבין המטרות הבאות, מה לדעתך, המטרה החשובה ביותר של המדינה? | H19: v107 | I19: v115 | AK19: =COUNTA(C19:AI19) -> 2 | AM19: =COUNTA(G19:P19,S19:T19) -> 2
A20: ומה לדעתך, המטרה השנייה בחשיבותה? | H20: v108 | I20: v116 | AK20: =COUNTA(C20:AI20) -> 2 | AM20: =COUNTA(G20:P20,S20:T20) -> 2
A21: כיצד היית מדרג את מצבך האישי בימים אלו? | J21: v57 | K21: a55 | O21: cc61 | P21: i33 | Q21: a56 | U21: b61 | W21: v25 | AH21: a11 | AI21: a34 | AK21: =COUNTA(C21:AI21) -> 9 | AM21: =COUNTA(G21:P21,S21:T21) -> 4
A22: ולפני 5 שנים מה היה מצבך האישי? | J22: v58 | K22: a56 | O22: cc62 | P22: i34 | Q22: a57 | U22: b62 | W22: v26 | AH22: a12 | AI22: a35 | AK22: =COUNTA(C22:AI22) -> 9 | AM22: =COUNTA(G22:P22,S22:T22) -> 4
A23: ובעוד 5 שנים מה יהיה מצבך האישי? | J23: v59 | K23: a57 | O23: cc63 | P23: i35 | Q23: a58 | U23: b63 | W23: v27 | AH23: a13 | AI23: a36 | AK23: =COUNTA(C23:AI23) -> 9 | AM23: =COUNTA(G23:P23,S23:T23) -> 4
A24: האם החלפת המפלגה בשלטון תשנה את המצב האישי שלך? | AE24: d44 | AK24: =COUNTA(C24:AI24) -> 1 | AM24: =COUNTA(G24:P24,S24:T24) -> 0
A25: באיזו מידה אתה תומך או מתנגד לצירוף של שרים מטעם מפלגות ערביות לממשלה? | C25: v704 | M25: b13 | N25: c11 | O25: ccc20 | AK25: =COUNTA(C25:AI25) -> 4 | AM25: =COUNTA(G25:P25,S25:T25) -> 3
A26: מה צריך להיות יותר חשוב לאזרחי המדינה, האינטרסים האישיים שלהם או האינטרסים של המדינה כולה? | N26: i55 | O26: cc44 | P26: a75 | U26: b59 | AH26: b17 | AI26: b14 | AK26: =COUNTA(C26:AI26) -> 6 | AM26: =COUNTA(G26:P26,S26:T26) -> 3
A27: האם לפי הערכתך עלולה להתפתח מלחמת אזרחים בארץ בעקבות ההסדרים לגבי עתיד השטחים? | O27: c53 | AK27: =COUNTA(C27:AI27) -> 1 | AM27: =COUNTA(G27:P27,S27:T27) -> 1
A28: יש החושבים שישראל יכולה להשיג את כל היעדים החשובים לה: שלום, א"י השלמה, שמירה על רוב יהודי, שמירה על משטר דמוקרטי מבלי לוותר על אף דבר. אחרים חושבים שאי אפשר להשיג את כל היעדים הללו בו זמנית, וכדי להשיג יעדים מסויימים צריך להתפשר על יעדים אחרים. מה דעתך? | O28: cc73 | P28: i31 | AK28: =COUNTA(C28:AI28) -> 2 | AM28: =COUNTA(G28:P28,S28:T28) -> 2
A29: האם יש לך קשרים עם ערבים? | O29: ccc42 | AK29: =COUNTA(C29:AI29) -> 1 | AM29: =COUNTA(G29:P29,S29:T29) -> 1
A30: באיזו מידה כל אחד מהמצבים הבאים מהווה איום בעיניך: מספר שווה של יהודים וערבים במדינה | P30: i17 | AK30: =COUNTA(C30:AI30) -> 1 | AM30: =COUNTA(G30:P30,S30:T30) -> 1
A31: באיזו מידה כל אחד מהמצבים הבאים מהווה איום בעיניך: הפסקת הסיוע מארה"ב | P31: i20 | AK31: =COUNTA(C31:AI31) -> 1 | AM31: =COUNTA(G31:P31,S31:T31) -> 1
A32: מהם הסיכויים שיתקיים כל אחד מהמצבים הבאים בעתיד הנראה לעין: מספר שווה של יהודים וערבים במדינה | P32: i26 | AK32: =COUNTA(C32:AI32) -> 1 | AM32: =COUNTA(G32:P32,S32:T32) -> 1
A33: מהם הסיכויים שיתקיים כל אחד מהמצבים הבאים בעתיד הנראה לעין: הפסקת הסיוע של ארה"ב | P33: i29 | AK33: =COUNTA(C33:AI33) -> 1 | AM33: =COUNTA(G33:P33,S33:T33) -> 1
A34: לפניך רשימת דעות בנושאים שונים. ציין באיזו מידה אתה מסכים או מתנגד לכל אחת מהן: מבין כל ההשקפות הקיימות בעולם כנראה שיש רק אחת בלבד שהיא נכונה | Q34: v74 | AK34: =COUNTA(C34:AI34) -> 1 | AM34: =COUNTA(G34:P34,S34:T34) -> 0
A35: אין אף מצב בו נראה כי עדיף שאנשים יקחו בעצם את החוק לידיים | Q35: v75 | AK35: =COUNTA(C35:AI35) -> 1 | AM35: =COUNTA(G35:P35,S35:T35) -> 0
A36: במצבים בהם יש ניגוד אינטרסים בין טובת הכלל וטובת הפרט במדינה יש בדר"כ להעדיף את טובת הפרט | Q36: v76 | AK36: =COUNTA(C36:AI36) -> 1 | AM36: =COUNTA(G36:P36,S36:T36) -> 0
A37: לא להחזיר שטחים מא"י הוא בחזקת יהרג ובל יעבור | Q37: v77 | AK37: =COUNTA(C37:AI37) -> 1 | AM37: =COUNTA(G37:P37,S37:T37) -> 0
A38: אלוהים ישמור עלינו אם נהיה ראויים לכך אפילו אם לא נהיה מוכנים למלחמה הבאה | Q38: v78 | AK38: =COUNTA(C38:AI38) -> 1 | AM38: =COUNTA(G38:P38,S38:T38) -> 0
A39: באיזו מידה אתה מאמין או לא מאמין בעתיד קיומנו בארץ לטווח ארוך? | Q39: v79 | R39: b27 | S39: f31 | AK39: =COUNTA(C39:AI39) -> 3 | AM39: =COUNTA(G39:P39,S39:T39) -> 1
A40: האם נטל השירות הצבאי מתחלק באופן צודק או לא צודק? | Q40: v104 | AK40: =COUNTA(C40:AI40) -> 1 | AM40: =COUNTA(G40:P40,S40:T40) -> 0
...

Sheet עניין פוליטי
A1: שאלה | B1: 2025 | C1: 2022 | D1: 2021 | E1: 2020 | F1: 43709 | G1: 43556 | H1: 2015 | I1: 2013 | J1: 2009 | K1: 2006 | L1: 2003 | M1: 2001 | N1: 1999 | O1: 1996 | P1: 1992 | Q1: 1987* | R1: 1988* | S1: 1988 | T1: 1984 | U1: 1981 - 3 | V1: 1981 - 2 | W1: 1981 - 1 | X1: 1977 - 4 | Y1: 1977 - 3 | Z1: 1977 - 2 | AA1: 1977 - 1 | AB1: 1973 - 5 | AC1: 1973 - 4 | AD1: 1973 - 3 | AE1: 1973 - 2 | AF1: 1973 - 1 | AG1: 1969 - 3 | AH1: 1969 - 2 | AI1: 1969 - 1 | AK1: מספר חזרות | AM1: ספירה 84-19 | AO1: סה"כ מעל שתי חזרות
A2: באיזו מידה אתה וחבריך יכולים להשפיע על מדיניות הממשלה? | C2: v46 | D2: v46 | E2: v46 | G2: v46 | H2: v50 | I2: v44 | J2: v56 | K2: a54 | L2: a75 | M2: a74 | N2: i57 | O2: cc48 | P2: a61 | Q2: a16 | R2: b72 | S2: f75 | T2: v40 | U2: b30 | V2: a35 | W2: v70 | AA2: v32 | AC2: g33 | AE2: d6 | AF2: v66 | AH2: b14 | AI2: a73 | AK2: =COUNTA(C2:AI2) -> 26 | AM2: =COUNTA(G2:P2,S2:T2) -> 12 | AO2: =COUNTIF(AM2:AM47,">=2") -> 3
A3: באיזו מידה אתה נוהג לשוחח עם חבריך ובני משפחתך על עניינים פוליטיים? | B3: v45 | C3: v45 | D3: v45 | E3: v45 | G3: v45 | H3: v49 | I3: v43 | J3: v55 | K3: a53 | L3: a74 | M3: a73 | N3: i56 | O3: cc45 | P3: a60 | Q3: a75 | R3: b59 | S3: f62 | V3: a31 | W3: v19 | AA3: v28 | AE3: c25 | AF3: v11 | AK3: =COUNTA(C3:AI3) -> 21 | AM3: =COUNTA(G3:P3,S3:T3) -> 11
A4: כאשר אתה נפגש עם חבריך, האם אתם דנים על עניינים פוליטיים? | Q4: a113 | R4: b71 | S4: f74 | V4: a32 | AA4: v29 | AF4: v8 | AK4: =COUNTA(C4:AI4) -> 6 | AM4: =COUNTA(G4:P4,S4:T4) -> 1
A5: באיזו מידה אתה נוהג או לא נוהג להביע את דעתך בנושאי בטחון בדרכים שונות, כגון שיחות עם בני משפחה וחברים, כתיבת מכתבים למערכת העיתונים, חתומה על עצומות ועוד? | Q5: a15 | AK5: =COUNTA(C5:AI5) -> 1 | AM5: =COUNTA(G5:P5,S5:T5) -> 0
A6: באיזו מידה חשוב לך להביע את דעותיך בעניינים פוליטיים? | AE6: c46 | AK6: =COUNTA(C6:AI6) -> 1 | AM6: =COUNTA(G6:P6,S6:T6) -> 0
A7: באיזו מידה השתתפות בבחירות מאפשרת לך להביע את דעותיך בעניינים פוליטיים? | AE7: d23 | AK7: =COUNTA(C7:AI7) -> 1 | AM7: =COUNTA(G7:P7,S7:T7) -> 0
A8: באיזו מידה הדעות של בני משפחתך בנושאי השטחים ומדיניות הבטחון דומות לדעות שלך? | R8: b58 | S8: f61 | AK8: =COUNTA(C8:AI8) -> 2 | AM8: =COUNTA(G8:P8,S8:T8) -> 1
A9: עם מי מבני משפחתך הינך משוחח כיום על עניינים פוליטיים במידה הרבה ביותר? | Q9: a76 | R9: b60 | S9: f63 | AK9: =COUNTA(C9:AI9) -> 3 | AM9: =COUNTA(G9:P9,S9:T9) -> 1
A10: בתקופה בה התגוררת בבית הוריך, עם מי נהגת לשוחח על עניינים פוליטיים במידה הרבה ביותר? | Q10: a77 | AK10: =COUNTA(C10:AI10) -> 1 | AM10: =COUNTA(G10:P10,S10:T10) -> 0
A11: האם נהגת לשוחח עם אביך בענייני פוליטיקה? | AF11: v20 | AK11: =COUNTA(C11:AI11) -> 1 | AM11: =COUNTA(G11:P11,S11:T11) -> 0
A12: האם אתה חבר, אוהד או פעיל של מפלגה כלשהי? | H12: v89 | I12: v93 | J12: v151 | K12: b72 | L12: b72 | M12: b23 | N12: c18 | O12: ccc45 | P12: i55 | Q12: a59 | R12: c50 | S12: g71 | T12: a51 | U12: b156 | V12: a145 | AA12: v110 | AC12: g58 | AE12: d42 | AF12: b11 | AG12: b47 | AH12: b37 | AI12: b42 | AK12: =COUNTA(C12:AI12) -> 22 | AM12: =COUNTA(G12:P12,S12:T12) -> 11
A13: האם בתקופה שלפני הבחירות אתה נוהג להשתתף באסיפות המאורגנות ע"י המפלגות ואם כן באיזו תדירות? | W13: v17 | AF13: v6 | AH13: a4 | AI13: a3 | AK13: =COUNTA(C13:AI13) -> 4 | AM13: =COUNTA(G13:P13,S13:T13) -> 0
A14: האם אתה נוהג להשתתף בחוגי בית של המפלגות ואם כן באיזו תדירות? | W14: v18 | AE14: c23 | AI14: a5 | AK14: =COUNTA(C14:AI14) -> 3 | AM14: =COUNTA(G14:P14,S14:T14) -> 0
A15: האם בתקופה שלפני הבחירות מתקיימים חוגי בית בביתך? | AI15: a6 | AK15: =COUNTA(C15:AI15) -> 1 | AM15: =COUNTA(G15:P15,S15:T15) -> 0
A16: יש אנשים שמתעניינים במערכת הבחירות מכיוון שיש לה אופי של התמודדות ספורטיבית. באיזו מידה גם אתה מתעניין מסיבה זו? | AC16: g26 | AE16: d9 | AK16: =COUNTA(C16:AI16) -> 2 | AM16: =COUNTA(G16:P16,S16:T16) -> 0
A17: האם אתה פעיל במערכת הבחירות הנוכחית? (עובד למען אחת המפלגות בהתנדבות או בשכר) | AC17: g27 | AE17: d10 | AK17: =COUNTA(C17:AI17) -> 2 | AM17: =COUNTA(G17:P17,S17:T17) -> 0
A18: האם בתקופת הבחירות אתה מתעניין בפוליטיקה יותר מאשר בדר"כ? | AE18: c2 | AK18: =COUNTA(C18:AI18) -> 1 | AM18: =COUNTA(G18:P18,S18:T18) -> 0
A19: באיזו מידה אתה מתעניין במערכת הבחירות: להסתדרות | AE19: c3 | AK19: =COUNTA(C19:AI19) -> 1 | AM19: =COUNTA(G19:P19,S19:T19) -> 0
A20: באיזו מידה אתה מתעניין במערכת הבחירות: לעירייה | AE20: c4 | AK20: =COUNTA(C20:AI20) -> 1 | AM20: =COUNTA(G20:P20,S20:T20) -> 0
A21: באיזו מידה אתה מתעניין במערכת הבחירות: לכנסת | AE21: c5 | AK21: =COUNTA(C21:AI21) -> 1 | AM21: =COUNTA(G21:P21,S21:T21) -> 0
A22: איזה נושאים פוליטיים מעניינים אותך בעיקר? | AE22: c9 | AK22: =COUNTA(C22:AI22) -> 1 | AM22: =COUNTA(G22:P22,S22:T22) -> 0
A23: באיזו מידה אתה מתעניין בפוליטיקה בדר"כ? | AE23: c26 | AF23: v4 | AK23: =COUNTA(C23:AI23) -> 2 | AM23: =COUNTA(G23:P23,S23:T23) -> 0
A24: בדר"כ, האם אתה נוהג לבקר בהרצאות על נושאים פוליטיים? | AF24: v5 | AI24: a2 | AK24: =COUNTA(C24:AI24) -> 2 | AM24: =COUNTA(G24:P24,S24:T24) -> 0
A25: האם אתה פעיל בארגון ציבורי כלשהו? | AE25: d43 | AK25: =COUNTA(C25:AI25) -> 1 | AM25: =COUNTA(G25:P25,S25:T25) -> 0
A26: באיזו מידה מערכת הבחירות הנוכחית עוזרת לך להכיר יותר טוב את המנהיגים הפוליטיים? | AC26: g8 | AE26: d15 | AK26: =COUNTA(C26:AI26) -> 2 | AM26: =COUNTA(G26:P26,S26:T26) -> 0
A27: באיזו מידה חשוב לך להכיר יותר טוב את המנהיגים הפוליטיים? | AE27: c41 | AK27: =COUNTA(C27:AI27) -> 1 | AM27: =COUNTA(G27:P27,S27:T27) -> 0
A28: באיזו מידה מערכת הבחירות עוזרת לך להבין יותר את הבעיות הפוליטיות בארץ? | AC28: g6 | AE28: d13 | AK28: =COUNTA(C28:AI28) -> 2 | AM28: =COUNTA(G28:P28,S28:T28) -> 0
A29: באיזו מידה חשוב לך להבין יותר טוב את הבעיות הפוליטיות בארץ? | AE29: c39 | AK29: =COUNTA(C29:AI29) -> 1 | AM29: =COUNTA(G29:P29,S29:T29) -> 0
A30: האם אביך התעניין בפוליטיקה? | AF30: v19 | AK30: =COUNTA(C30:AI30) -> 1 | AM30: =COUNTA(G30:P30,S30:T30) -> 0
A31: לאחרונה יש הטוענים שקיים פער כלכלי וחברתי במדינה. האם אתה מתעניין בנושאים אלו? | AF31: v40 | AK31: =COUNTA(C31:AI31) -> 1 | AM31: =COUNTA(G31:P31,S31:T31) -> 0
A32: באיזו מידה אתה מתעניין בבעיות הכלכליות של מדינת ישראל? | AH32: b11 | AI32: a64 | AK32: =COUNTA(C32:AI32) -> 2 | AM32: =COUNTA(G32:P32,S32:T32) -> 0
A33: האם בדר"כ אתה מתעניין בבעיות חוץ וביטחון? | AF33: v48 | AI33: a61 | AK33: =COUNTA(C33:AI33) -> 2 | AM33: =COUNTA(G33:P33,S33:T33) -> 0
A34: באיזו מידה אתה מתעניין בתוצאות הבחירות לכנסת? | AG34: c13 | AK34: =COUNTA(C34:AI34) -> 1 | AM34: =COUNTA(G34:P34,S34:T34) -> 0
A35: באיזו מידה לדעתך צריך האזרח הרגיל במדינת ישראל להתעניין בבעיות הכלכליות של המדינה? | AH35: b12 | AI35: a65 | AK35: =COUNTA(C35:AI35) -> 2 | AM35: =COUNTA(G35:P35,S35:T35) -> 0
A36: באיזו מידה לדעתך צריך האזרח הרגיל במדינת ישראל להתעניין בבעיות החוץ והביטחון של המדינה? | AI36: a62 | AK36: =COUNTA(C36:AI36) -> 1 | AM36: =COUNTA(G36:P36,S36:T36) -> 0
A37: באיזו מידה אתה מתעניין בבעיות החברתיות של מדינת ישראל? | AI37: a67 | AK37: =COUNTA(C37:AI37) -> 1 | AM37: =COUNTA(G37:P37,S37:T37) -> 0
A38: באיזו מידה לדעתך צריך האזרח הרגיל במדינת ישראל להתעניין בבעיות החברתיות של המדינה? | AI38: a68 | AK38: =COUNTA(C38:AI38) -> 1 | AM38: =COUNTA(G38:P38,S38:T38) -> 0
A39: באיזו מידה אתה מתעניין בפוליטיקה מקומית של מדינת ישראל? | AI39: a70 | AK39: =COUNTA(C39:AI39) -> 1 | AM39: =COUNTA(G39:P39,S39:T39) -> 0
A40: באיזו מידה לדעתך צריך האזרח הרגיל במדינת ישראל להתעניין בפוליטיקה מקומית של המדינה? | AI40: a71 | AK40: =COUNTA(C40:AI40) -> 1 | AM40: =COUNTA(G40:P40,S40:T40) -> 0
...

Sheet ימין-שמאל
A1: שאלה | B1: 2025 | C1: 2022 | D1: 2021 | E1: 2020 | F1: 43709 | G1: 43556 | H1: 2015 | I1: 2013 | J1: 2009 | K1: 2006 | L1: 2003 | M1: 2001 | N1: 1999 | O1: 1996 | P1: 1992 | Q1: 1987* | R1: 1988* | S1: 1988 | T1: 1984 | U1: 1981 - 3 | V1: 1981 - 2 | W1: 1981 - 1 | X1: 1977 - 4 | Y1: 1977 - 3 | Z1: 1977 - 2 | AA1: 1977 - 1 | AB1: 1973 - 5 | AC1: 1973 - 4 | AD1: 1973 - 3 | AE1: 1973 - 2 | AF1: 1973 - 1 | AG1: 1969 - 3 | AH1: 1969 - 2 | AI1: 1969 - 1 | AK1: מספר חזרות | AM1: ספירה 84-19 | AO1: סה"כ מעל שתי חזרות
A2: בבחירות האלה דיברו הרבה על ימין ועל שמאל בפוליטיקה, מה זה להבנתך ימין? | E2: E8A_after | G2: V8A_after | H2: after_v13b_1 | AK2: =COUNTA(C2:AI2) -> 3 | AM2: =COUNTA(G2:P2,S2:T2) -> 2 | AO2: =COUNTIF(AM2:AM55,">=2") -> 21
A3: בבחירות האלה דיברו הרבה על ימין ועל שמאל בפוליטיקה, מה זה להבנתך שמאל? | E3: E8B_after | G3: V8B_after | H3: after_v13b_2 | AK3: =COUNTA(C3:AI3) -> 3 | AM3: =COUNTA(G3:P3,S3:T3) -> 2
A4: עם איזה זרם פוליטי אתה מזדהה? | C4: v53 | G4: v53 | H4: v71 | I4: v103 | J4: v134 | K4: b61 | L4: b73 | N4: c19 | O4: ccc46 | P4: i56 | R4: c51 | S4: g72 | T4: a52 | U4: b157 | V4: a133 | W4: v73 | AA4: v104 | AE4: d31 | AF4: v69 | AG4: c19 | AH4: c40 | AI4: c48 | AK4: =COUNTA(C4:AI4) -> 22 | AM4: =COUNTA(G4:P4,S4:T4) -> 11
A5: הרבה מדברים על שמאל וימין בפוליטיקה. היכן היית מדרג את עצמך על פני רצף שמאל-ימין, כאשר 1 הקצה הימני ו-7 הקצה השמאלי? | B5: v111 | C5: v111 | D5: v111 | E5: v111 | F5: c111 | G5: v111 | H5: v103 | I5: v88 | J5: v135 | K5: b62 | L5: a49 | M5: a66 | N5: i19 | O5: c69 | P5: a110 | Q5: a60 | R5: b126 | S5: f125 | T5: v43 | U5: b80 | W5: v116 | AK5: =COUNTA(C5:AI5) -> 20 | AM5: =COUNTA(G5:P5,S5:T5) -> 12
A6: האם אתה יכול לראות את עצמך בתנאים מסוימים עובר למחנה השמאל או למחנה הימין? | N6: i20 | AK6: =COUNTA(C6:AI6) -> 1 | AM6: =COUNTA(G6:P6,S6:T6) -> 1
A7: דירגת את עצמך יותר לכיוון מחנה השמאל/ימין. האם אתה יכול לראות את עצמך בתנאים מסוימים עובר למחנה האחר? | N7: i21 | AK7: =COUNTA(C7:AI7) -> 1 | AM7: =COUNTA(G7:P7,S7:T7) -> 1
A8: הרבה מדברים על "שמאל" ו-"ימין" בפוליטיקה. כיצד היית מדרג את עצמך על פני רצף "שמאל-ימין" כאשר 0 משמעו שמאל, 10 משמעו ימין ו-5 משמעו אמצע? | C8: v620 | D8: v621 | J8: v90 | K8: b7 | AK8: =COUNTA(C8:AI8) -> 4 | AM8: =COUNTA(G8:P8,S8:T8) -> 2
A9: הרבה מדברים על שמאל וימין בתחום המדיני-ביטחוני. כיצד היית מדרג את עצמך על רצף זה? | I9: v67 | Q9: v58 | R9: b44 | S9: f47 | T9: v44 | U9: b81 | W9: v117 | AK9: =COUNTA(C9:AI9) -> 7 | AM9: =COUNTA(G9:P9,S9:T9) -> 3
A10: הרבה מדברים על שמאל וימין בתחום הכלכלי. כיצד היית מדרג את עצמך על רצף זה? | T10: v45 | U10: b83 | W10: v118 | AK10: =COUNTA(C10:AI10) -> 3 | AM10: =COUNTA(G10:P10,S10:T10) -> 1
A11: הרבה מדברים על שמאל וימין בתחום מדיניות החוץ. כיצד היית מדרג את עצמך על רצף זה? | U11: b82 | AK11: =COUNTA(C11:AI11) -> 1 | AM11: =COUNTA(G11:P11,S11:T11) -> 0
A12: עד כמה חשובה לך הזהות שלך כ(ימני/שמאלני/תומך מרכז)? | G12: v54 | AK12: =COUNTA(C12:AI12) -> 1 | AM12: =COUNTA(G12:P12,S12:T12) -> 1
A13: באיזו מידה אתה מסכים או לא מסכים עם כל אחת מן הטענות הבאות: כשמישהו מעביר ביקורת על (ימנים/שמאלנים/תומכים של המרכז) זה מרגיש לך כמו עלבון אישי | G13: v55 | AK13: =COUNTA(C13:AI13) -> 1 | AM13: =COUNTA(G13:P13,S13:T13) -> 1
A14: כשאתה פוגש תומך אחר של (הימין/שמאל/מרכז) אתה מרגיש קשור אליו | G14: v56 | AK14: =COUNTA(C14:AI14) -> 1 | AM14: =COUNTA(G14:P14,S14:T14) -> 1
A15: כשאנשים אומרים דברים טובים על (ימנים/שמאלנים/תומכים של המרכז) זה גורם לך הרגשה טובה | G15: v57 | AK15: =COUNTA(C15:AI15) -> 1 | AM15: =COUNTA(G15:P15,S15:T15) -> 1
A16: בבחירות האלה דיברו הרבה על ימין ושמאל בפוליטיקה. מהם לדעתך הדברים העיקריים שמבחינים בין שמאל לימין? | H16: after_v13a | U16: b76 | AK16: =COUNTA(C16:AI16) -> 2 | AM16: =COUNTA(G16:P16,S16:T16) -> 1
A17: האם לדעתך קיימים הבדלים בעמדותיהן של המפלגות לגבי הבעיה שציינת? | T17: v5 | U17: b4 | W17: v5 | AA17: v7 | AE17: c54 | AF17: c30 | AK17: =COUNTA(C17:AI17) -> 6 | AM17: =COUNTA(G17:P17,S17:T17) -> 1
A18: האם ברור לך מה ההבדלים בעמדותיהן של המפלגות לגבי בעיה זו? | AA18: v8 | AK18: =COUNTA(C18:AI18) -> 1 | AM18: =COUNTA(G18:P18,S18:T18) -> 0
A19: האם לדעתך קיימים או לא קיימים הבדלים בעמדותיהן של המפלגות העיקריות בארץ בנושאים הבאים: מדיניות כלכלית-חברתית | C19: v58 | G19: v58 | H19: v59 | AF19: v43 | AK19: =COUNTA(C19:AI19) -> 4 | AM19: =COUNTA(G19:P19,S19:T19) -> 2
A20: האם לדעתך קיימים או לא קיימים הבדלים בעמדותיהן של המפלגות העיקריות בארץ בנושאים הבאים: כלכלה | I20: v51 | J20: v76 | K20: a85 | L20: a51 | M20: a68 | N20: i33 | O20: c74 | P20: a53 | R20: b63 | S20: f66 | T20: v19 | U20: b16 | W20: v15 | AA20: v21 | AK20: =COUNTA(C20:AI20) -> 14 | AM20: =COUNTA(G20:P20,S20:T20) -> 10
A21: האם לדעתך קיימים או לא קיימים הבדלים בעמדותיהן של המפלגות העיקריות בארץ בנושאים הבאים: מדיניות חברתית | I21: v52 | J21: v77 | K21: a86 | L21: a52 | M21: a69 | N21: i34 | AK21: =COUNTA(C21:AI21) -> 6 | AM21: =COUNTA(G21:P21,S21:T21) -> 6
A22: האם לדעתך קיימים או לא קיימים הבדלים בעמדותיהן של המפלגות העיקריות בארץ בנושאים הבאים: דת ומדינה | C22: v59 | G22: v59 | H22: v60 | I22: v53 | J22: v78 | K22: a87 | L22: a53 | M22: a70 | N22: i35 | AK22: =COUNTA(C22:AI22) -> 9 | AM22: =COUNTA(G22:P22,S22:T22) -> 8
A23: האם לדעתך קיימים או לא קיימים הבדלים בעמדותיהן של המפלגות העיקריות בארץ בנושאים הבאים: שלום ושטחים | C23: v60 | G23: v60 | H23: v61 | I23: v54 | J23: v79 | K23: a88 | L23: a54 | M23: a71 | N23: i37 | O23: c75 | P23: a51 | T23: v12 | W23: v9 | AA23: v12 | AF23: v51 | AK23: =COUNTA(C23:AI23) -> 15 | AM23: =COUNTA(G23:P23,S23:T23) -> 11
A24: האם לדעתך קיימים או לא קיימים הבדלים בעמדותיהן של המפלגות העיקריות בארץ בנושאים הבאים: בטחון וטרור | C24: v61 | G24: v61 | H24: v62 | I24: v55 | J24: v80 | K24: a89 | L24: a55 | M24: a72 | N24: i38 | O24: c76 | Q24: v16 | R24: b57 | S24: f60 | U24: b7 | AC24: g53 | AD24: f48 | AK24: =COUNTA(C24:AI24) -> 16 | AM24: =COUNTA(G24:P24,S24:T24) -> 10
A25: האם לדעתך קיימים או לא קיימים הבדלים בעמדותיהן של המפלגות העיקריות בארץ בנושאים הבאים: ביחס שלהן לדמוקרטיה | C25: v62 | G25: v62 | H25: v63 | I25: v57 | AK25: =COUNTA(C25:AI25) -> 4 | AM25: =COUNTA(G25:P25,S25:T25) -> 3
A26: האם לדעתך קיימים או לא קיימים הבדלים בעמדותיהן של המפלגות העיקריות בארץ בנושאים הבאים: האיום האיראני | I26: v56 | AK26: =COUNTA(C26:AI26) -> 1 | AM26: =COUNTA(G26:P26,S26:T26) -> 1
A27: האם לדעתך קיימים או לא קיימים הבדלים בעמדותיהן של המפלגות העיקריות בארץ בנושאים הבאים: ירושלים | J27: v75 | K27: a84 | L27: a50 | M27: a67 | N27: i32 | O27: c73 | AK27: =COUNTA(C27:AI27) -> 6 | AM27: =COUNTA(G27:P27,S27:T27) -> 6
A28: האם לדעתך קיימים או לא קיימים הבדלים בעמדותיהן של המפלגות העיקריות בארץ בנושאים הבאים: לבנון | N28: i36 | AK28: =COUNTA(C28:AI28) -> 1 | AM28: =COUNTA(G28:P28,S28:T28) -> 1
A29: האם לדעתך קיימים או לא קיימים הבדלים בעמדותיהן של המפלגות העיקריות בארץ בנושאים הבאים: שחיתות | AE29: d3 | AK29: =COUNTA(C29:AI29) -> 1 | AM29: =COUNTA(G29:P29,S29:T29) -> 0
A30: היכן היית מדרג את המפלגות הבאות על פני רצף "שמאל-ימין" כאשר 0 משמעו שמאל, 10 משמעו ימין ו-5 משמעו אמצע: ליכוד | C30: v620a | D30: v620A | J30: v91 | K30: b11 | AK30: =COUNTA(C30:AI30) -> 4 | AM30: =COUNTA(G30:P30,S30:T30) -> 2
A31: היכן היית מדרג את המפלגות הבאות על פני רצף "שמאל-ימין" כאשר 0 משמעו שמאל, 10 משמעו ימין ו-5 משמעו אמצע: עבודה | C31: v620c | D31: v620C | J31: v92 | K31: b13 | AK31: =COUNTA(C31:AI31) -> 4 | AM31: =COUNTA(G31:P31,S31:T31) -> 2
A32: היכן היית מדרג את המפלגות הבאות על פני רצף "שמאל-ימין" כאשר 0 משמעו שמאל, 10 משמעו ימין ו-5 משמעו אמצע: קדימה | J32: v93 | K32: b15 | AK32: =COUNTA(C32:AI32) -> 2 | AM32: =COUNTA(G32:P32,S32:T32) -> 2
A33: היכן היית מדרג את המפלגות הבאות על פני רצף "שמאל-ימין" כאשר 0 משמעו שמאל, 10 משמעו ימין ו-5 משמעו אמצע: ש"ס | C33: v620i | D33: v620I | J33: v94 | K33: b17 | AK33: =COUNTA(C33:AI33) -> 4 | AM33: =COUNTA(G33:P33,S33:T33) -> 2
A34: היכן היית מדרג את המפלגות הבאות על פני רצף "שמאל-ימין" כאשר 0 משמעו שמאל, 10 משמעו ימין ו-5 משמעו אמצע: הבית היהודי | C34: v620s | D34: v620S | J34: v95 | K34: b19 | AK34: =COUNTA(C34:AI34) -> 4 | AM34: =COUNTA(G34:P34,S34:T34) -> 2
A35: היכן היית מדרג את המפלגות הבאות על פני רצף "שמאל-ימין" כאשר 0 משמעו שמאל, 10 משמעו ימין ו-5 משמעו אמצע: ישראל ביתנו | C35: v620h | D35: v620H | J35: v96 | K35: b21 | AK35: =COUNTA(C35:AI35) -> 4 | AM35: =COUNTA(G35:P35,S35:T35) -> 2
A36: היכן היית מדרג את המפלגות הבאות על פני רצף "שמאל-ימין" כאשר 0 משמעו שמאל, 10 משמעו ימין ו-5 משמעו אמצע: מרצ | C36: v620f | D36: v620F | J36: v97 | K36: b23 | AK36: =COUNTA(C36:AI36) -> 4 | AM36: =COUNTA(G36:P36,S36:T36) -> 2
A37: היכן היית מדרג את המפלגות הבאות על פני רצף "שמאל-ימין" כאשר 0 משמעו שמאל, 10 משמעו ימין ו-5 משמעו אמצע: כחול-לבן | C37: v620b | D37: v620B | AK37: =COUNTA(C37:AI37) -> 2 | AM37: =COUNTA(G37:P37,S37:T37) -> 0
A38: היכן היית מדרג את המפלגות הבאות על פני רצף "שמאל-ימין" כאשר 0 משמעו שמאל, 10 משמעו ימין ו-5 משמעו אמצע: יש עתיד | C38: v620z | D38: v620Z | AK38: =COUNTA(C38:AI38) -> 2 | AM38: =COUNTA(G38:P38,S38:T38) -> 0
A39: היכן היית מדרג את המפלגות הבאות על פני רצף "שמאל-ימין" כאשר 0 משמעו שמאל, 10 משמעו ימין ו-5 משמעו אמצע: תקווה חדשה | D39: v620X | AK39: =COUNTA(C39:AI39) -> 1 | AM39: =COUNTA(G39:P39,S39:T39) -> 0
A40: היכן היית מדרג את המפלגות הבאות על פני רצף "שמאל-ימין" כאשר 0 משמעו שמאל, 10 משמעו ימין ו-5 משמעו אמצע: ימינה | D40: v620D | AK40: =COUNTA(C40:AI40) -> 1 | AM40: =COUNTA(G40:P40,S40:T40) -> 0
...

Sheet זיקה רגשית
A1: שאלה | B1: 2025 | C1: 2022 | D1: 2021 | E1: 2020 | F1: 43709 | G1: 43556 | H1: 2015 | I1: 2013 | J1: 2009 | K1: 2006 | L1: 2003 | M1: 2001 | N1: 1999 | O1: 1996 | P1: 1992 | Q1: 1987* | R1: 1988* | S1: 1988 | T1: 1984 | U1: 1981 - 3 | V1: 1981 - 2 | W1: 1981 - 1 | X1: 1977 - 4 | Y1: 1977 - 3 | Z1: 1977 - 2 | AA1: 1977 - 1 | AB1: 1973 - 5 | AC1: 1973 - 4 | AD1: 1973 - 3 | AE1: 1973 - 2 | AF1: 1973 - 1 | AG1: 1969 - 3 | AH1: 1969 - 2 | AI1: 1969 - 1 | AK1: מספר חזרות | AM1: ספירה 84-19 | AO1: סה"כ מעל שתי חזרות
A2: מה יחסך לכל אחת מן המפלגות הבאות? הליכוד | C2: v49a | D2: v49A | E2: v49A | F2: c49_a | G2: v49A | H2: v51A | I2: v45A | J2: v63 | K2: a61 | L2: a27 | M2: a47 | N2: v43 | O2: c59 | P2: a102 | R2: b111 | S2: f110 | T2: a27 | AK2: =COUNTA(C2:AI2) -> 17 | AM2: =COUNTA(G2:P2,S2:T2) -> 12 | AO2: =COUNTIF(AM2:AM179,">=2") -> 46
A3: מה יחסך לכל אחת מן המפלגות הבאות? כחול-לבן | C3: v49b | D3: v49B | E3: v49B | F3: c49_b | G3: v49B | AK3: =COUNTA(C3:AI3) -> 5 | AM3: =COUNTA(G3:P3,S3:T3) -> 1
A4: מה יחסך לכל אחת מן המפלגות הבאות? יש עתיד | C4: v49z | D4: v49Z | H4: v51F | I4: v45F | AK4: =COUNTA(C4:AI4) -> 4 | AM4: =COUNTA(G4:P4,S4:T4) -> 2
A5: מה יחסך לכל אחת מן המפלגות הבאות? שינוי | L5: a31 | AK5: =COUNTA(C5:AI5) -> 1 | AM5: =COUNTA(G5:P5,S5:T5) -> 1
A6: מה יחסך לכל אחת מן המפלגות הבאות? מפלגת המרכז | N6: v40 | AK6: =COUNTA(C6:AI6) -> 1 | AM6: =COUNTA(G6:P6,S6:T6) -> 1
A7: מה יחסך לכל אחת מן המפלגות הבאות? העבודה/המערך | C7: v49c | D7: v49C | E7: v49C | F7: v49_c | G7: v49C | H7: v51B | I7: v45B | J7: v62 | K7: a60 | L7: a28 | M7: a45 | N7: v41 | O7: c58 | P7: a101 | R7: b110 | S7: f109 | T7: a26 | AK7: =COUNTA(C7:AI7) -> 17 | AM7: =COUNTA(G7:P7,S7:T7) -> 12
A8: מה יחסך לכל אחת מן המפלגות הבאות? ישראל אחת | N8: v53 | AK8: =COUNTA(C8:AI8) -> 1 | AM8: =COUNTA(G8:P8,S8:T8) -> 1
A9: מה יחסך לכל אחת מן המפלגות הבאות? קדימה | J9: v61 | K9: a59 | AK9: =COUNTA(C9:AI9) -> 2 | AM9: =COUNTA(G9:P9,S9:T9) -> 2
A10: מה יחסך לכל אחת מן המפלגות הבאות? התנועה | I10: v51C | AK10: =COUNTA(C10:AI10) -> 1 | AM10: =COUNTA(G10:P10,S10:T10) -> 1
A11: מה יחסך לכל אחת מן המפלגות הבאות? מרצ | C11: v49f | D11: v49F | F11: c49_f | G11: v49F | H11: v51G | I11: v45G | J11: v64 | K11: a62 | L11: a29 | N11: v44 | O11: c61 | AK11: =COUNTA(C11:AI11) -> 11 | AM11: =COUNTA(G11:P11,S11:T11) -> 8
A12: מה יחסך לכל אחת מן המפלגות הבאות? ימינה | D12: v49D | E12: v49D | F12: c49_d | G12: v49D | AK12: =COUNTA(C12:AI12) -> 4 | AM12: =COUNTA(G12:P12,S12:T12) -> 1
A13: מה יחסך לכל אחת מן המפלגות הבאות? תקווה חדשה | D13: v49X | AK13: =COUNTA(C13:AI13) -> 1 | AM13: =COUNTA(G13:P13,S13:T13) -> 0
A14: מה יחסך לכל אחת מהמפלגות הבאות? הבית היהודי/מפד"ל | C14: v49s | D14: v49S | G14: v49E | H14: v51C | I14: v45D | J14: v65 | K14: a63 | L14: a30 | AK14: =COUNTA(C14:AI14) -> 8 | AM14: =COUNTA(G14:P14,S14:T14) -> 6
A15: מה יחסך לכל אחת מן המפלגות הבאות? ישראל ביתנו | C15: v49h | D15: v49H | E15: v49H | F15: c49_h | G15: v49H | H15: v51H | J15: v66 | K15: a64 | L15: a32 | AK15: =COUNTA(C15:AI15) -> 9 | AM15: =COUNTA(G15:P15,S15:T15) -> 5
A16: מה יחסך לכל אחת מן המפלגות הבאות? ש"ס | C16: v49i | D16: v49I | E16: v49I | G16: v49I | H16: v51E | I16: v45E | J16: v67 | K16: a65 | L16: a33 | AK16: =COUNTA(C16:AI16) -> 9 | AM16: =COUNTA(G16:P16,S16:T16) -> 6
A17: מה יחסך לכל אחת מן המפלגות הבאות? ישראל בעליה | L17: a34 | AK17: =COUNTA(C17:AI17) -> 1 | AM17: =COUNTA(G17:P17,S17:T17) -> 1
A18: מה יחסך לכל אחת מן המפלגות הבאות? עוצמה יהודית | E18: v49S | G18: v49S | H18: v51I | AK18: =COUNTA(C18:AI18) -> 3 | AM18: =COUNTA(G18:P18,S18:T18) -> 2
A19: מה יחסך לכל אחת מן המפלגות הבאות? יהדות התורה | C19: v49k | D19: v49K | E19: v49K | AK19: =COUNTA(C19:AI19) -> 3 | AM19: =COUNTA(G19:P19,S19:T19) -> 0
A20: מה יחסך לכל אחת מן המפלגות הבאות? כולנו | G20: v49G | H20: v51D | AK20: =COUNTA(C20:AI20) -> 2 | AM20: =COUNTA(G20:P20,S20:T20) -> 2
A21: מה יחסך לכל אחת מן המפלגות הבאות? הרשימה המשותפת | C21: v49j | D21: v49J | E21: v49J | F21: c49_j | G21: v49J | H21: v51J | AK21: =COUNTA(C21:AI21) -> 6 | AM21: =COUNTA(G21:P21,S21:T21) -> 2
A22: מה יחסך לכל אחת מן המפלגות הבאות? רע"מ-בל"ד | G22: v49R | AK22: =COUNTA(C22:AI22) -> 1 | AM22: =COUNTA(G22:P22,S22:T22) -> 1
A23: מה יחסך לכל אחת מן המפלגות הבאות? רע"מ-תע"ל | I23: v45I | AK23: =COUNTA(C23:AI23) -> 1 | AM23: =COUNTA(G23:P23,S23:T23) -> 1
A24: מה יחסך לכל אחת מן המפלגות הבאות? חד"ש | H24: v51K | I24: v45H | AK24: =COUNTA(C24:AI24) -> 2 | AM24: =COUNTA(G24:P24,S24:T24) -> 2
A25: מה יחסך לכל אחת מן המפלגות הבאות? תע"ל | H25: v51L | AK25: =COUNTA(C25:AI25) -> 1 | AM25: =COUNTA(G25:P25,S25:T25) -> 1
A26: מה יחסך לכל אחת מן המפלגות הבאות? רע"מ | C26: v49y | D26: v49Y | H26: v51M | AK26: =COUNTA(C26:AI26) -> 3 | AM26: =COUNTA(G26:P26,S26:T26) -> 1
A27: מה יחסך לכל אחת מן המפלגות הבאות? בל"ד | C27: v49t | H27: v51N | I27: v45J | AK27: =COUNTA(C27:AI27) -> 3 | AM27: =COUNTA(G27:P27,S27:T27) -> 2
A28: לאחר הבחירות, מה יחסך לכל אחת מן מפלגות הבאות: הציונות הדתית | D28: F49S_1 | AK28: =COUNTA(C28:AI28) -> 1 | AM28: =COUNTA(G28:P28,S28:T28) -> 0
A29: לאחר הבחירות, מה יחסך לכל אחת מן מפלגות הבאות: ימינה | D29: F49D_1 | AK29: =COUNTA(C29:AI29) -> 1 | AM29: =COUNTA(G29:P29,S29:T29) -> 0
A30: לאחר הבחירות, מה יחסך לכל אחת מן מפלגות הבאות: הרשימה המשותפת | D30: F49J_1 | AK30: =COUNTA(C30:AI30) -> 1 | AM30: =COUNTA(G30:P30,S30:T30) -> 0
A31: לאחר הבחירות, מה יחסך לכל אחת מן מפלגות הבאות: רע"מ | D31: F49Y_1 | AK31: =COUNTA(C31:AI31) -> 1 | AM31: =COUNTA(G31:P31,S31:T31) -> 0
A32: לאחר הבחירות, מה יחסך לכל אחת מן מפלגות הבאות: יהדות התורה | D32: F49K_1 | AK32: =COUNTA(C32:AI32) -> 1 | AM32: =COUNTA(G32:P32,S32:T32) -> 0
A33: על סולם שבו 0 משמעו דחייה ושנאה, 10 משמעו תמיכה ואהדה ו-5 משמעו אמצע, מה יחסך לימנים? | B33: v50 | C33: v50 | D33: v50 | E33: v50 | G33: v50 | AK33: =COUNTA(C33:AI33) -> 4 | AM33: =COUNTA(G33:P33,S33:T33) -> 1
A34: על סולם שבו 0 משמעו דחייה ושנאה, 10 משמעו תמיכה ואהדה ו-5 משמעו אמצע, מה יחסך לשמאלנים? | B34: v51 | C34: v51 | D34: v51 | E34: v51 | G34: v51 | AK34: =COUNTA(C34:AI34) -> 4 | AM34: =COUNTA(G34:P34,S34:T34) -> 1
A35: מה יחסך לערבים? | B35: v623 | C35: v623 | D35: v623 | L35: a37 | M35: a54 | N35: v55 | O35: c63 | P35: a106 | R35: b114 | S35: f113 | T35: a30 | AK35: =COUNTA(C35:AI35) -> 10 | AM35: =COUNTA(G35:P35,S35:T35) -> 7
A36: מה יחסך לדתיים? | M36: a48 | N36: v45 | O36: c62 | P36: a107 | R36: b116 | S36: f115 | T36: a32 | AK36: =COUNTA(C36:AI36) -> 7 | AM36: =COUNTA(G36:P36,S36:T36) -> 6
A37: מה יחסך לחרדים? | B37: v622A | C37: v622a | D37: v622 | N37: v54 | AK37: =COUNTA(C37:AI37) -> 3 | AM37: =COUNTA(G37:P37,S37:T37) -> 1
A38: מה יחסך לחילונים? | B38: v622B | C38: v622b | AK38: =COUNTA(C38:AI38) -> 1
A39: מה יחסך לדתיים-לאומיים? | B39: v622C
A40: מה יחסך לאשכנזים? | R40: b117 | S40: f116 | T40: a33 | AK40: =COUNTA(C40:AI40) -> 3 | AM40: =COUNTA(G40:P40,S40:T40) -> 2
...

Sheet תכונות
A1: שאלה | B1: 2022 | C1: 2021 | D1: 2020 | E1: 43709 | F1: 43556 | G1: 2015 | H1: 2013 | I1: 2009 | J1: 2006 | K1: 2003 | L1: 2001 | M1: 1999 | N1: 1996 | O1: 1992 | P1: 1987* | Q1: 1988* | R1: 1988 | S1: 1984 | T1: 1981 - 3 | U1: 1981 - 2 | V1: 1981 - 1 | W1: 1977 - 4 | X1: 1977 - 3 | Y1: 1977 - 2 | Z1: 1977 - 1 | AA1: 1973 - 5 | AB1: 1973 - 4 | AC1: 1973 - 3 | AD1: 1973 - 2 | AE1: 1973 - 1 | AF1: 1969 - 3 | AG1: 1969 - 2 | AH1: 1969 - 1 | AJ1: מספר חזרות | AL1: ספירה 84-19 | AN1: סה"כ מעל שתי חזרות
A2: לפניך רשימה של תכונות שונות של מפלגות. לגבי כל אחת מהן, ציין לאיזו מפלגה היא מתאימה ביותר: מפלגה שתדע לעמוד בתוקף במו"מ על שטחים ושלום | I2: v109 | J2: b36 | K2: a78 | L2: a81 | M2: i60 | N2: cc51 | O2: a92 | Q2: b101 | R2: f101 | S2: a11 | AJ2: =COUNTA(B2:AH2) -> 10 | AL2: =COUNTA(F2:O2,R2:S2) -> 9 | AN2: =COUNTIF(AL2:AL235,">=2") -> 40
A3: ולמי הכי פחות? | I3: v110 | J3: b37 | AJ3: =COUNTA(B3:AH3) -> 2 | AL3: =COUNTA(F3:O3,R3:S3) -> 2
A4: לפניך רשימה של תכונות שונות של מפלגות. לגבי כל אחת מהן, ציין לאיזו מפלגה היא מתאימה ביותר: מפלגה שתשמור על המשטר הדמוקרטי במדינה | I4: v111 | J4: b38 | K4: a79 | M4: i61 | N4: cc52 | O4: a93 | Q4: b102 | R4: f102 | S4: a15 | AJ4: =COUNTA(B4:AH4) -> 9 | AL4: =COUNTA(F4:O4,R4:S4) -> 8
A5: ולמי הכי פחות? | I5: v112 | J5: b39 | AJ5: =COUNTA(B5:AH5) -> 2 | AL5: =COUNTA(F5:O5,R5:S5) -> 2
A6: לפניך רשימה של תכונות שונות של מפלגות. לגבי כל אחת מהן, ציין לאיזו מפלגה היא מתאימה ביותר: מפלגה שתוכל להוביל לשלום אמת עם הערבים | I6: v113 | J6: b40 | K6: a80 | L6: a83 | M6: i62 | N6: cc53 | O6: a94 | Q6: b105 | R6: f105 | AJ6: =COUNTA(B6:AH6) -> 9 | AL6: =COUNTA(F6:O6,R6:S6) -> 8
A7: ולמי הכי פחות? | I7: v114 | J7: b41 | AJ7: =COUNTA(B7:AH7) -> 2 | AL7: =COUNTA(F7:O7,R7:S7) -> 2
A8: לפניך רשימה של תכונות שונות של מפלגות. לגבי כל אחת מהן, ציין לאיזו מפלגה היא מתאימה ביותר: מפלגה שתדע לטפל בטרור | I8: v115 | J8: b42 | K8: a81 | L8: a82 | M8: i63 | N8: cc54 | O8: a95 | Q8: b106 | R8: f106 | AJ8: =COUNTA(B8:AH8) -> 9 | AL8: =COUNTA(F8:O8,R8:S8) -> 8
A9: ולמי הכי פחות? | I9: v116 | J9: b43 | AJ9: =COUNTA(B9:AH9) -> 2 | AL9: =COUNTA(F9:O9,R9:S9) -> 2
