Workbook

Sheet codebooks_data
A1: survey_name | B1: category | C1: record | D1: columns | E1: question_id | F1: question_title | G1: question_description | H1: question_data_type | I1: answers
A2: 2006 | E2: Election | F2: Study 2006
A3: 2006 | B3: Case Identification | C3: 1 | D3: 1-4 | E3: CASEID | F3: Case ID | H3: numeric
A4: 2006 | B4: Case Identification | C4: 1 | D4: 5-8 | E4: id_svv_2 | F4: Respondent's ID in all consecutive surveys | H4: numeric
A5: 2006 | B5: Pre-Election Survey | C5: 1 | D5: 9 | E5: a6 | F5: Israeli condition in general | G5: 6. In your opinion, what is Israel's general situation? | H5: numeric | I5: 1: Very good; 2: Good; 3: So so; 4: Not good; 5: Bad
A6: 2006 | B6: Pre-Election Survey | C6: 1 | D6: 10 | E6: a7 | F6: The way government handles problems | G6: 7. What do you think about the way the government is handling the problems that exist in Israel today? | H6: numeric | I6: 1: Very good way; 2: Good way; 3: Bad way; 4: Very badly
A7: 2006 | B7: Pre-Election Survey | C7: 1 | D7: 11-12 | E7: a8 | F7: Most important problem for government | G7: 8. What do you think is the most important problem the government must take care of? | H7: numeric
A8: 2006 | B8: Pre-Election Survey | C8: 1 | D8: 13 | E8: a10 | F8: Economic situation in past 3 years | G8: 10. Do you think that the economic situation in the past 3 years has improved, didn't change, or got worse? | H8: numeric | I8: 1: Improved a lot; 2: Improved a bit; 3: Didn't change; 4: Got a bit worse; 5: Got much worse
A9: 2006 | B9: Pre-Election Survey | C9: 1 | D9: 14 | E9: a11 | F9: Personal economic situation in past year | G9: 11. And what about your own personal economic status? Would you say that for the past year your personal status: | H9: numeric | I9: 1: Improved a lot; 2: Improved a bit; 3: Didn't change; 4: Got a bit worse; 5: Got much worse
A10: 2006 | B10: Pre-Election Survey | C10: 1 | D10: 15 | E10: a12 | F10: National security today | G10: Here is a 9 step ladder that depicts where the country might be in terms of national security. The top of the ladder is 9 and that is the best possible situation that you can think of and 1 is the worst. One which rank do you think the country is? | H10: numeric | I10: 1: Worst situation; 9: Best situation
A11: 2006 | B11: Pre-Election Survey | C11: 1 | D11: 16 | E11: a13 | F11: National security in last 5 years | G11: Here is a 9 step ladder that depicts where the country might be in terms of national security. The top of the ladder is 9 and that is the best possible situation that you can think of and 1 is the worst. One which rank do you think the country is? | H11: numeric | I11: 1: Worst situation; 9: Best situation
A12: 2006 | B12: Pre-Election Survey | C12: 1 | D12: 17 | E12: a14 | F12: National security in next 5 years | G12: Here is a 9 step ladder that depicts where the country might be in terms of national security. The top of the ladder is 9 and that is the best possible situation that you can think of and 1 is the worst. One which rank do you think the country is? | H12: numeric | I12: 1: Worst situation; 9: Best situation
A13: 2006 | B13: Pre-Election Survey | C13: 1 | D13: 18 | E13: a15 | F13: Territories should be exchanged for peace | G13: 15. In a peace agreement with the Palestinians, should Israel agree or disagree to a territorial compromise and to the evacuation of settlements in Judea and Samaria? | H13: numeric | I13: 1: Should definitely agree; 2: Should agree; 3: Should disagree; 4: Should definitely disagree
A14: 2006 | B14: Pre-Election Survey | C14: 1 | D14: 19 | E14: a16 | F14: Israel should decide on borders and unilaterally withdraw | G14: 16. And if it would not be possible to achieve a peace agreement with the Palestinians in the next few years, should Israel undertake another unilateral separation? | H14: numeric | I14: 1: Yes definitely; 2: Yes; 3: No; 4: Definitely no
A15: 2006 | B15: Pre-Election Survey | C15: 1 | D15: 20-21 | E15: a17 | F15: Chances of Olmert's disengagement | G15: 17. If Ehud Olmert will be elected prime minister, what are the chances odds that he would undertake unilateral separation in Judea and Samaria? | H15: numeric | I15: 1: Great odds; 2: Medium odds; 3: Low odds; 4: No chance
A16: 2006 | B16: Pre-Election Survey | C16: 1 | D16: 22 | E16: a18 | F16: Chances of peace between Israel and Arabs in next 3 years | G16: 18. What are the odds that the peace between Israel and the Arab states will grow stronger in the next 3 years? | H16: numeric | I16: 1: Great odds; 2: Medium odds; 3: Low odds; 4: Very low odds
A17: 2006 | B17: Pre-Election Survey | C17: 1 | D17: 23-24 | E17: a19 | F17: Chances of war in next 3 years | G17: 19. And what are the odds for a war to break out between Israel and an Arab state in the next 3 years? | H17: numeric | I17: 1: Great odds; 2: Medium odds; 3: Low odds; 4: Very low odds
A18: 2006 | B18: Pre-Election Survey | C18: 1 | D18: 25 | E18: a20 | F18: Chances of peace agreement | G18: 20. Do you think it is possible to achieve a peace agreement with the Palestinians? | H18: numeric | I18: 1: Yes definitely; 2: I think so; 3: I dont think so; 4: Definitely no
A19: 2006 | B19: Pre-Election Survey | C19: 1 | D19: 26 | E19: a21 | F19: Evaluation of Arab aspirations | G19: 21. What do you think are the aspirations of the in the long run? | H19: numeric | I19: 1: Return part of territories occupied in the six days war; 2: Return all the territories occupied in the six days war; 3: To conquer the state of Israel; 4: Conquer the state of Israel and to destroy a significant part of the Jewish population in Israel
... A63: 2006 | B63: Support/Rejection of a Group or a Person | C63: 1 | D63: 77-78 | E63: a66 | F63: Your favorite party | G63: 66. In sum, among these parties, which one do you support most? | H63: numeric | I63: 59: Kadima; 60: Avoda; 61: Likud; 62: Meretz; 63: Ihud Leumi Mafdal; 64: Israel Beitenu; 65: Shas; 66: Another Party; 67: No Favorite Party
A64: 2006 | B64: Support/Rejection of a Group or a Person | C64: 1 | D64: 79-80 | E64: a68 | F64: Support: Olmert | H64: numeric | I64: 1: Hate/rejection; 10: Love/support
A65: 2006 | B65: Support/Rejection of a Group or a Person | C65: 1 | D65: 81-82 | E65: a69 | F65: Support: Peretz | H65: numeric | I65: 1: Hate/rejection; 10: Love/support
A66: 2006 | B66: Support/Rejection of a Group or a Person | C66: 1 | D66: 83-84 | E66: a70 | F66: Support: Netanyahu | H66: numeric | I66: 1: Hate/rejection; 10: Love/support
A67: 2006 | B67: Support/Rejection of a Group or a Person | C67: 1 | D67: 85-86 | E67: a71 | F67: Support: Peres | H67: numeric | I67: 1: Hate/rejection; 10: Love/support
A68: 2006 | B68: Support/Rejection of a Group or a Person | C68: 1 | D68: 87-88 | E68: a72 | F68: Support: Yishai | H68: numeric | I68: 1: Hate/rejection; 10: Love/support
A69: 2006 | B69: Support/Rejection of a Group or a Person | C69: 1 | D69: 89-90 | E69: a73 | F69: Support: Sharon | H69: numeric | I69: 1: Hate/rejection; 10: Love/support
A70: 2006 | B70: Support/Rejection of a Group or a Person | C70: 1 | D70: 91-92 | E70: a74 | F70: Support: Liberman | H70: numeric | I70: 1: Hate/rejection; 10: Love/support
A71: 2006 | B71: Support/Rejection of a Group or a Person | C71: 1 | D71: 93-94 | E71: a75 | F71: Support: Beilin | H71: numeric | I71: 1: Hate/rejection; 10: Love/support
A72: 2006 | B72: Support/Rejection of a Group or a Person | C72: 1 | D72: 95-96 | E72: a76 | F72: Support: Eylon | H72: numeric | I72: 1: Hate/rejection; 10: Love/support
A73: 2006 | B73: Support/Rejection of a Group or a Person | C73: 1 | D73: 97-98 | E73: a77 | F73: Support: Sharanskiy | H73: numeric | I73: 1: Hate/rejection; 10: Love/support
A74: 2006 | B74: Support/Rejection of a Group or a Person | C74: 1 | D74: 99 | E74: a78 | F74: Party leaders to deal best with economy | G74: 78  79. Who do you think will deal best with the economic problems of Israel: Kadima leaders, the Likud leaders, to Labor's leaders? Who is in second place? | H74: numeric | I74: 1: Kadima leaders; 2: Likud leaders; 3: Avoda leaders; 4: All of them to the same deggree; 5: None of them; 6: Another party
A75: 2006 | B75: Support/Rejection of a Group or a Person | C75: 1 | D75: 100 | E75: a79 | F75: In second place | G75: 79  79. Who do you think will deal best with the economic problems of Israel: Kadima leaders, the Likud leaders, to Labor's leaders? Who is in second place? | H75: numeric | I75: 1: Kadima leaders; 2: Likud leaders; 3: Avoda leaders; 4: All of them to the same deggree; 5: None of them; 6: Another party
A76: 2006 | B76: Support/Rejection of a Group or a Person | C76: 1 | D76: 101 | E76: a80 | F76: Party leaders to deal best with the social problems | G76: 80  81. And regarding the social problems in Israel? | H76: numeric | I76: 1: Kadima leaders; 2: Likud leaders; 3: Avoda leaders; 4: All of them to the same deggree; 5: None of them; 6: Another party
A77: 2006 | B77: Support/Rejection of a Group or a Person | C77: 1 | D77: 102 | E77: a81 | F77: In second place | G77: 81  81. And regarding the social problems in Israel? | H77: numeric | I77: 1: Kadima leaders; 2: Likud leaders; 3: Avoda leaders; 4: All of them to the same deggree; 5: None of them; 6: Another party
A78: 2006 | B78: Support/Rejection of a Group or a Person | C78: 1 | D78: 103 | E78: a82 | F78: Party leaders to deal best with foreign and security issues in Israel | G78: 82  83. And regarding the foreign and security issues in Israel? | H78: numeric | I78: 1: Kadima leaders; 2: Likud leaders; 3: Avoda leaders; 4: All of them to the same deggree; 5: None of them; 6: Another party
A79: 2006 | B79: Support/Rejection of a Group or a Person | C79: 1 | D79: 104 | E79: a83 | F79: In second place | G79: 83  83. And regarding the foreign and security issues in Israel? | H79: numeric | I79: 1: Kadima leaders; 2: Likud leaders; 3: Avoda leaders; 4: All of them to the same deggree; 5: None of them; 6: Another party
A80: 2006 | B80: Party Differences | C80: 1 | D80: 105 | E80: a84 | F80: Party differences on the following issue:Jerusalem | G80: Do you think there are or are not differences among the parties on the following issues? | H80: numeric | I80: 1: Great differences; 5: Almost no differences
A81: 2006 | B81: Party Differences | C81: 1 | D81: 106 | E81: a85 | F81: Party differences on the following issue:Economy | G81: Do you think there are or are not differences among the parties on the following issues? | H81: numeric | I81: 1: Great differences; 5: Almost no differences
A82: 2006 | B82: Party Differences | C82: 1 | D82: 107 | E82: a86 | F82: Party differences on the following issue:Social policy | G82: Do you think there are or are not differences among the parties on the following issues? | H82: numeric | I82: 1: Great differences; 5: Almost no differences
A83: 2006 | B83: Party Differences | C83: 1 | D83: 108 | E83: a87 | F83: Party differences on the following issue:State and Religion | G83: Do you think there are or are not differences among the parties on the following issues? | H83: numeric | I83: 1: Great differences; 5: Almost no differences
...

Sheet codebooks_data_reordered
A1: Question Id | B1: Election | C1: category2 | D1: record | E1: columns | F1: question_title | G1: question_description | H1: question_data_type | I1: answers
A2: CASEID | B2: 2006 | F2: Study 2006
A3: id_svv_2 | B3: 2006 | C3: Case Identification | D3: 1 | E3: 1-4 | F3: Case ID | H3: numeric
A4: a6 | B4: 2006 | C4: Case Identification | D4: 1 | E4: 5-8 | F4: Respondent's ID in all consecutive surveys | H4: numeric
A5: a7 | B5: 2006 | C5: Pre-Election Survey | D5: 1 | E5: 9 | F5: Israeli condition in general | G5: 6. In your opinion, what is Israel's general situation? | H5: numeric | I5: 1: Very good; 2: Good; 3: So so; 4: Not good; 5: Bad
A6: a8 | B6: 2006 | C6: Pre-Election Survey | D6: 1 | E6: 10 | F6: The way government handles problems | G6: 7. What do you think about the way the government is handling the problems that exist in Israel today? | H6: numeric | I6: 1: Very good way; 2: Good way; 3: Bad way; 4: Very badly
A7: a10 | B7: 2006 | C7: Pre-Election Survey | D7: 1 | E7: 11-12 | F7: Most important problem for government | G7: 8. What do you think is the most important problem the government must take care of? | H7: numeric
A8: a11 | B8: 2006 | C8: Pre-Election Survey | D8: 1 | E8: 13 | F8: Economic situation in past 3 years | G8: 10. Do you think that the economic situation in the past 3 years has improved, didn't change, or got worse? | H8: numeric | I8: 1: Improved a lot; 2: Improved a bit; 3: Didn't change; 4: Got a bit worse; 5: Got much worse
A9: a12 | B9: 2006 | C9: Pre-Election Survey | D9: 1 | E9: 14 | F9: Personal economic situation in past year | G9: 11. And what about your own personal economic status? Would you say that for the past year your personal status: | H9: numeric | I9: 1: Improved a lot; 2: Improved a bit; 3: Didn't change; 4: Got a bit worse; 5: Got much worse
A10: a13 | B10: 2006 | C10: Pre-Election Survey | D10: 1 | E10: 15 | F10: National security today | G10: Here is a 9 step ladder that depicts where the country might be in terms of national security. The top of the ladder is 9 and that is the best possible situation that you can think of and 1 is the worst. One which rank do you think the country is? | H10: numeric | I10: 1: Worst situation; 9: Best situation
A11: a14 | B11: 2006 | C11: Pre-Election Survey | D11: 1 | E11: 16 | F11: National security in last 5 years | G11: Here is a 9 step ladder that depicts where the country might be in terms of national security. The top of the ladder is 9 and that is the best possible situation that you can think of and 1 is the worst. One which rank do you think the country is? | H11: numeric | I11: 1: Worst situation; 9: Best situation
A12: a15 | B12: 2006 | C12: Pre-Election Survey | D12: 1 | E12: 17 | F12: National security in next 5 years | G12: Here is a 9 step ladder that depicts where the country might be in terms of national security. The top of the ladder is 9 and that is the best possible situation that you can think of and 1 is the worst. One which rank do you think the country is? | H12: numeric | I12: 1: Worst situation; 9: Best situation
A13: a16 | B13: 2006 | C13: Pre-Election Survey | D13: 1 | E13: 18 | F13: Territories should be exchanged for peace | G13: 15. In a peace agreement with the Palestinians, should Israel agree or disagree to a territorial compromise and to the evacuation of settlements in Judea and Samaria? | H13: numeric | I13: 1: Should definitely agree; 2: Should agree; 3: Should disagree; 4: Should definitely disagree
A14: a17 | B14: 2006 | C14: Pre-Election Survey | D14: 1 | E14: 19 | F14: Israel should decide on borders and unilaterally withdraw | G14: 16. And if it would not be possible to achieve a peace agreement with the Palestinians in the next few years, should Israel undertake another unilateral separation? | H14: numeric | I14: 1: Yes definitely; 2: Yes; 3: No; 4: Definitely no
A15: a18 | B15: 2006 | C15: Pre-Election Survey | D15: 1 | E15: 20-21 | F15: Chances of Olmert's disengagement | G15: 17. If Ehud Olmert will be elected prime minister, what are the chances odds that he would undertake unilateral separation in Judea and Samaria? | H15: numeric | I15: 1: Great odds; 2: Medium odds; 3: Low odds; 4: No chance
A16: a19 | B16: 2006 | C16: Pre-Election Survey | D16: 1 | E16: 22 | F16: Chances of peace between Israel and Arabs in next 3 years | G16: 18. What are the odds that the peace between Israel and the Arab states will grow stronger in the next 3 years? | H16: numeric | I16: 1: Great odds; 2: Medium odds; 3: Low odds; 4: Very low odds
A17: a20 | B17: 2006 | C17: Pre-Election Survey | D17: 1 | E17: 23-24 | F17: Chances of war in next 3 years | G17: 19. And what are the odds for a war to break out between Israel and an Arab state in the next 3 years? | H17: numeric | I17: 1: Great odds; 2: Medium odds; 3: Low odds; 4: Very low odds
A18: a21 | B18: 2006 | C18: Pre-Election Survey | D18: 1 | E18: 25 | F18: Chances of peace agreement | G18: 20. Do you think it is possible to achieve a peace agreement with the Palestinians? | H18: numeric | I18: 1: Yes definitely; 2: I think so; 3: I dont think so; 4: Definitely no
A19: a22 | B19: 2006 | C19: Pre-Election Survey | D19: 1 | E19: 26 | F19: Evaluation of Arab aspirations | G19: 21. What do you think are the aspirations of the in the long run? | H19: numeric | I19: 1: Return part of territories occupied in the six days war; 2: Return all the territories occupied in the six days war; 3: To conquer the state of Israel; 4: Conquer the state of Israel and to destroy a significant part of the Jewish population in Israel
... A63: a68 | B63: 2006 | C63: Support/Rejection of a Group or a Person | D63: 1 | E63: 77-78 | F63: Your favorite party | G63: 66. In sum, among these parties, which one do you support most? | H63: numeric | I63: 59: Kadima; 60: Avoda; 61: Likud; 62: Meretz; 63: Ihud Leumi Mafdal; 64: Israel Beitenu; 65: Shas; 66: Another Party; 67: No Favorite Party
A64: a69 | B64: 2006 | C64: Support/Rejection of a Group or a Person | D64: 1 | E64: 79-80 | F64: Support: Olmert | H64: numeric | I64: 1: Hate/rejection; 10: Love/support
A65: a70 | B65: 2006 | C65: Support/Rejection of a Group or a Person | D65: 1 | E65: 81-82 | F65: Support: Peretz | H65: numeric | I65: 1: Hate/rejection; 10: Love/support
A66: a71 | B66: 2006 | C66: Support/Rejection of a Group or a Person | D66: 1 | E66: 83-84 | F66: Support: Netanyahu | H66: numeric | I66: 1: Hate/rejection; 10: Love/support
A67: a72 | B67: 2006 | C67: Support/Rejection of a Group or a Person | D67: 1 | E67: 85-86 | F67: Support: Peres | H67: numeric | I67: 1: Hate/rejection; 10: Love/support
A68: a73 | B68: 2006 | C68: Support/Rejection of a Group or a Person | D68: 1 | E68: 87-88 | F68: Support: Yishai | H68: numeric | I68: 1: Hate/rejection; 10: Love/support
A69: a74 | B69: 2006 | C69: Support/Rejection of a Group or a Person | D69: 1 | E69: 89-90 | F69: Support: Sharon | H69: numeric | I69: 1: Hate/rejection; 10: Love/support
A70: a75 | B70: 2006 | C70: Support/Rejection of a Group or a Person | D70: 1 | E70: 91-92 | F70: Support: Liberman | H70: numeric | I70: 1: Hate/rejection; 10: Love/support
A71: a76 | B71: 2006 | C71: Support/Rejection of a Group or a Person | D71: 1 | E71: 93-94 | F71: Support: Beilin | H71: numeric | I71: 1: Hate/rejection; 10: Love/support
A72: a77 | B72: 2006 | C72: Support/Rejection of a Group or a Person | D72: 1 | E72: 95-96 | F72: Support: Eylon | H72: numeric | I72: 1: Hate/rejection; 10: Love/support
A73: a78 | B73: 2006 | C73: Support/Rejection of a Group or a Person | D73: 1 | E73: 97-98 | F73: Support: Sharanskiy | H73: numeric | I73: 1: Hate/rejection; 10: Love/support
A74: a79 | B74: 2006 | C74: Support/Rejection of a Group or a Person | D74: 1 | E74: 99 | F74: Party leaders to deal best with economy | G74: 78  79. Who do you think will deal best with the economic problems of Israel: Kadima leaders, the Likud leaders, to Labor's leaders? Who is in second place? | H74: numeric | I74: 1: Kadima leaders; 2: Likud leaders; 3: Avoda leaders; 4: All of them to the same deggree; 5: None of them; 6: Another party
A75: a80 | B75: 2006 | C75: Support/Rejection of a Group or a Person | D75: 1 | E75: 100 | F75: In second place | G75: 79  79. Who do you think will deal best with the economic problems of Israel: Kadima leaders, the Likud leaders, to Labor's leaders? Who is in second place? | H75: numeric | I75: 1: Kadima leaders; 2: Likud leaders; 3: Avoda leaders; 4: All of them to the same deggree; 5: None of them; 6: Another party
A76: a81 | B76: 2006 | C76: Support/Rejection of a Group or a Person | D76: 1 | E76: 101 | F76: Party leaders to deal best with the social problems | G76: 80  81. And regarding the social problems in Israel? | H76: numeric | I76: 1: Kadima leaders; 2: Likud leaders; 3: Avoda leaders; 4: All of them to the same deggree; 5: None of them; 6: Another party
A77: a82 | B77: 2006 | C77: Support/Rejection of a Group or a Person | D77: 1 | E77: 102 | F77: In second place | G77: 81  81. And regarding the social problems in Israel? | H77: numeric | I77: 1: Kadima leaders; 2: Likud leaders; 3: Avoda leaders; 4: All of them to the same deggree; 5: None of them; 6: Another party
A78: a83 | B78: 2006 | C78: Support/Rejection of a Group or a Person | D78: 1 | E78: 103 | F78: Party leaders to deal best with foreign and security issues in Israel | G78: 82  83. And regarding the foreign and security issues in Israel? | H78: numeric | I78: 1: Kadima leaders; 2: Likud leaders; 3: Avoda leaders; 4: All of them to the same deggree; 5: None of them; 6: Another party
A79: a84 | B79: 2006 | C79: Support/Rejection of a Group or a Person | D79: 1 | E79: 104 | F79: In second place | G79: 83  83. And regarding the foreign and security issues in Israel? | H79: numeric | I79: 1: Kadima leaders; 2: Likud leaders; 3: Avoda leaders; 4: All of them to the same deggree; 5: None of them; 6: Another party
A80: a85 | B80: 2006 | C80: Party Differences | D80: 1 | E80: 105 | F80: Party differences on the following issue:Jerusalem | G80: Do you think there are or are not differences among the parties on the following issues? | H80: numeric | I80: 1: Great differences; 5: Almost no differences
A81: a86 | B81: 2006 | C81: Party Differences | D81: 1 | E81: 106 | F81: Party differences on the following issue:Economy | G81: Do you think there are or are not differences among the parties on the following issues? | H81: numeric | I81: 1: Great differences; 5: Almost no differences
A82: a87 | B82: 2006 | C82: Party Differences | D82: 1 | E82: 107 | F82: Party differences on the following issue:Social policy | G82: Do you think there are or are not differences among the parties on the following issues? | H82: numeric | I82: 1: Great differences; 5: Almost no differences
A83: a88 | B83: 2006 | C83: Party Differences | D83: 1 | E83: 108 | F83: Party differences on the following issue:State and Religion | G83: Do you think there are or are not differences among the parties on the following issues? | H83: numeric | I83: 1: Great differences; 5: Almost no differences
...

Sheet comments_data
A1: Sheet Name | B1: Cell Address | C1: Comment | D1: finalType | E1: Content Only | F1: Question Id | G1: Survey | H1: category | I1: record | J1: columns | K1: question_title | L1: question_description | M1: answers | N1: Affected Surveys | O1: Answers but better
A2: דמוגרפיה | B2: $L$3 | C2: יניב שפירא: 1 = ינואר 2 = פברואר | D2: scale | E2: 1 = ינואר 2 = פברואר | F2: b51 | G2: =VLOOKUP($F2, codebooks_data_reordered!$A:$I, 2, FALSE) -> 2006 | H2: =VLOOKUP($F2, codebooks_data_reordered!$A:$I, 3, FALSE) -> Most/Less Suitable Characteristic of the Party | I2: =VLOOKUP($F2, codebooks_data_reordered!$A:$I, 4, FALSE) -> 1 | J2: =VLOOKUP($F2, codebooks_data_reordered!$A:$I, 5, FALSE) -> 161 | K2: =VLOOKUP($F2, codebooks_data_reordered!$A:$I, 6, FALSE) -> Most suitable characteristic of the party: Leadership abilites | L2: =VLOOKUP($F2, codebooks_data_reordered!$A:$I, 7, FALSE) -> Below is a list of characteristics of leaders. Please tell which politician suits the characteristic best: Ehud Ulmert, Binyamin Netanyahu or Amir Peretz? Do not read 4 and 5. To those who said 1, 2 or 3, ask to whom this characteristic suits the least. Leadership abilities | M2: =VLOOKUP($F2, codebooks_data_reordered!$A:$I, 9, FALSE) -> 1: Olmert; 2: Netanyahu; 3: Peretz; 4: All; 5: None | O2: =SUBSTITUTE(M2, ";", CHAR(10)) -> 1: Olmert 2: Netanyahu 3: Peretz 4: All 5: None
A3: דמוגרפיה | B3: $A$5 | C3: יניב שפירא: שאלה 145 אין קידוד בstata גם ב2020 וגם ב2019 גם ב2021 | D3: scale | E3: שאלה 145 אין קידוד בstata גם ב2020 וגם ב2019 גם ב2021 | F3: מקום הראיון | G3: =VLOOKUP($F3, codebooks_data_reordered!$A:$I, 2, FALSE) -> #N/A | H3: =VLOOKUP($F3, codebooks_data_reordered!$A:$I, 3, FALSE) -> #N/A | I3: =VLOOKUP($F3, codebooks_data_reordered!$A:$I, 4, FALSE) -> #N/A | J3: =VLOOKUP($F3, codebooks_data_reordered!$A:$I, 5, FALSE) -> #N/A | K3: =VLOOKUP($F3, codebooks_data_reordered!$A:$I, 6, FALSE) -> #N/A | L3: =VLOOKUP($F3, codebooks_data_reordered!$A:$I, 7, FALSE) -> #N/A | M3: =VLOOKUP($F3, codebooks_data_reordered!$A:$I, 9, FALSE) -> #N/A | N3: 2020, 2019, 2021 | O3: =SUBSTITUTE(M3, ";", CHAR(10)) -> #N/A
A4: דמוגרפיה | B4: $D$6 | C4: יניב שפירא: 1 = יהודי 2 = ערבי | D4: scale | E4: 1 = יהודי 2 = ערבי | F4: sector | G4: =VLOOKUP($F4, codebooks_data_reordered!$A:$I, 2, FALSE) -> #N/A | H4: =VLOOKUP($F4, codebooks_data_reordered!$A:$I, 3, FALSE) -> #N/A | I4: =VLOOKUP($F4, codebooks_data_reordered!$A:$I, 4, FALSE) -> #N/A | J4: =VLOOKUP($F4, codebooks_data_reordered!$A:$I, 5, FALSE) -> #N/A | K4: =VLOOKUP($F4, codebooks_data_reordered!$A:$I, 6, FALSE) -> #N/A | L4: =VLOOKUP($F4, codebooks_data_reordered!$A:$I, 7, FALSE) -> #N/A | M4: =VLOOKUP($F4, codebooks_data_reordered!$A:$I, 9, FALSE) -> #N/A | O4: =SUBSTITUTE(M4, ";", CHAR(10)) -> #N/A
A5: דמוגרפיה | B5: $F$8 | C5: יניב שפירא: 1 = גרסה A 2 = גרסה B | D5: scale | E5: 1 = גרסה A 2 = גרסה B | F5: version | G5: =VLOOKUP($F5, codebooks_data_reordered!$A:$I, 2, FALSE) -> #N/A | H5: =VLOOKUP($F5, codebooks_data_reordered!$A:$I, 3, FALSE) -> #N/A | I5: =VLOOKUP($F5, codebooks_data_reordered!$A:$I, 4, FALSE) -> #N/A | J5: =VLOOKUP($F5, codebooks_data_reordered!$A:$I, 5, FALSE) -> #N/A | K5: =VLOOKUP($F5, codebooks_data_reordered!$A:$I, 6, FALSE) -> #N/A | L5: =VLOOKUP($F5, codebooks_data_reordered!$A:$I, 7, FALSE) -> #N/A | M5: =VLOOKUP($F5, codebooks_data_reordered!$A:$I, 9, FALSE) -> #N/A | O5: =SUBSTITUTE(M5, ";", CHAR(10)) -> #N/A
A6: דמוגרפיה | B6: $I$8 | C6: יניב שפירא: a , b, c | D6: scale | E6: a , b, c | F6: version | G6: =VLOOKUP($F6, codebooks_data_reordered!$A:$I, 2, FALSE) -> #N/A | H6: =VLOOKUP($F6, codebooks_data_reordered!$A:$I, 3, FALSE) -> #N/A | I6: =VLOOKUP($F6, codebooks_data_reordered!$A:$I, 4, FALSE) -> #N/A | J6: =VLOOKUP($F6, codebooks_data_reordered!$A:$I, 5, FALSE) -> #N/A | K6: =VLOOKUP($F6, codebooks_data_reordered!$A:$I, 6, FALSE) -> #N/A | L6: =VLOOKUP($F6, codebooks_data_reordered!$A:$I, 7, FALSE) -> #N/A | M6: =VLOOKUP($F6, codebooks_data_reordered!$A:$I, 9, FALSE) -> #N/A | O6: =SUBSTITUTE(M6, ";", CHAR(10)) -> #N/A
A7: דמוגרפיה | B7: $L$9 | C7: יניב שפירא: 1 = עברית 2 = ערבית 3 = רוסית | D7: scale | E7: 1 = עברית 2 = ערבית 3 = רוסית | F7: b55 | G7: =VLOOKUP($F7, codebooks_data_reordered!$A:$I, 2, FALSE) -> 2006 | H7: =VLOOKUP($F7, codebooks_data_reordered!$A:$I, 3, FALSE) -> Most/Less Suitable Characteristic of the Party | I7: =VLOOKUP($F7, codebooks_data_reordered!$A:$I, 4, FALSE) -> 1 | J7: =VLOOKUP($F7, codebooks_data_reordered!$A:$I, 5, FALSE) -> 165 | K7: =VLOOKUP($F7, codebooks_data_reordered!$A:$I, 6, FALSE) -> Most suitable characteristic of the party: Prefers the country | L7: =VLOOKUP($F7, codebooks_data_reordered!$A:$I, 7, FALSE) -> Below is a list of characteristics of leaders. Please tell which politician suits the characteristic best: Ehud Ulmert, Binyamin Netanyahu or Amir Peretz? Do not read 4 and 5. To those who said 1, 2 or 3, ask to whom this characteristic suits the least. Prefers the country's good to other interests | M7: =VLOOKUP($F7, codebooks_data_reordered!$A:$I, 9, FALSE) -> 1: Olmert; 2: Netanyahu; 3: Peretz; 4: All; 5: None | O7: =SUBSTITUTE(M7, ";", CHAR(10)) -> 1: Olmert 2: Netanyahu 3: Peretz 4: All 5: None
A8: דמוגרפיה | B8: $W$10 | C8: יניב שפירא: 1 = 20-25 2 = 25-29 3 = 30-34 4 = 35-39 5 = 40-44 6 = 45-49 7 = 50-54 8 = 55-64 9 = 65+ | D8: scale | E8: 1 = 20-25 2 = 25-29 3 = 30-34 4 = 35-39 5 = 40-44 6 = 45-49 7 = 50-54 8 = 55-64 9 = 65+ | F8: c24 | G8: =VLOOKUP($F8, codebooks_data_reordered!$A:$I, 2, FALSE) -> 2006 | H8: =VLOOKUP($F8, codebooks_data_reordered!$A:$I, 3, FALSE) -> Different Coalitions after the Elections | I8: =VLOOKUP($F8, codebooks_data_reordered!$A:$I, 4, FALSE) -> 1 | J8: =VLOOKUP($F8, codebooks_data_reordered!$A:$I, 5, FALSE) -> 225-227 | K8: =VLOOKUP($F8, codebooks_data_reordered!$A:$I, 6, FALSE) -> Chances for Kadima-Labor-Meretz coalition | L8: =VLOOKUP($F8, codebooks_data_reordered!$A:$I, 7, FALSE) -> And now we want to ask you about the chances of different coalitions after the elections. On a scale of 0 to 100, 0 means you give no chance for a certain coalition, 50 means that the coalition's chances are half and half, and 100 means that you are sure this coalition will exist. Naturally you can give any number between 0 to 100. On such a scale, what are the chances that after the elections, there will be a coalition between: | M8: =VLOOKUP($F8, codebooks_data_reordered!$A:$I, 9, FALSE) -> 0 | O8: =SUBSTITUTE(M8, ";", CHAR(10)) -> 0
A9: דמוגרפיה | B9: $AB$10 | C9: יניב שפירא: 1 = 20-24 2 = 25-29 3 = 30-34 4 = 35-39 5 = 40-44 6 = 45-49 7 = 50-54 8 = 55-64 9 = 65+ | D9: scale | E9: 1 = 20-24 2 = 25-29 3 = 30-34 4 = 35-39 5 = 40-44 6 = 45-49 7 = 50-54 8 = 55-64 9 = 65+ | F9: g62 | G9: =VLOOKUP($F9, codebooks_data_reordered!$A:$I, 2, FALSE) -> 1988_N=873 | H9: =VLOOKUP($F9, codebooks_data_reordered!$A:$I, 3, FALSE) -> FOR WHICH PARTIES WOULD YOU VOTE FOR IF NO LIMITATION IS POSED | I9: =VLOOKUP($F9, codebooks_data_reordered!$A:$I, 4, FALSE) -> 1 | J9: =VLOOKUP($F9, codebooks_data_reordered!$A:$I, 5, FALSE) -> 175-176 | K9: =VLOOKUP($F9, codebooks_data_reordered!$A:$I, 6, FALSE) -> Basis for above estimate | L9: =VLOOKUP($F9, codebooks_data_reordered!$A:$I, 7, FALSE) -> 0 | M9: =VLOOKUP($F9, codebooks_data_reordered!$A:$I, 9, FALSE) -> 0 | O9: =SUBSTITUTE(M9, ";", CHAR(10)) -> 0
A10: דמוגרפיה | B10: $AH$10 | C10: יניב שפירא: 1 = 18-24 2 = 25-29 3 = 30-34 4 = 35-39 5 = 40-44 6 = 45-49 7 = 50-54 8 = 55-64 9 = 65+ | D10: scale | E10: 1 = 18-24 2 = 25-29 3 = 30-34 4 = 35-39 5 = 40-44 6 = 45-49 7 = 50-54 8 = 55-64 9 = 65+ | F10: c79 | G10: =VLOOKUP($F10, codebooks_data_reordered!$A:$I, 2, FALSE) -> 1969_1 | H10: =VLOOKUP($F10, codebooks_data_reordered!$A:$I, 3, FALSE) -> SUPPORT OR OPPOSITION FOR GOVERNMENT OWNERSHIP OF THE FOLLOWING: | I10: =VLOOKUP($F10, codebooks_data_reordered!$A:$I, 4, FALSE) -> 3 | J10: =VLOOKUP($F10, codebooks_data_reordered!$A:$I, 5, FALSE) -> 58 | K10: =VLOOKUP($F10, codebooks_data_reordered!$A:$I, 6, FALSE) -> Mother's country of birth | L10: =VLOOKUP($F10, codebooks_data_reordered!$A:$I, 7, FALSE) -> 0 | M10: =VLOOKUP($F10, codebooks_data_reordered!$A:$I, 9, FALSE) -> 0: No answer; 1: Israel; 2: Central and Eastern Europe; 3: Southern Europe; 4: Western Europe; 5: English-speaking countries; 6: North African countries; 7: Near and Middle Eastern countries; 8: Far Eastern countries; 9: South and Gentral America | O10: =SUBSTITUTE(M10, ";", CHAR(10)) -> 0: No answer 1: Israel 2: Central and Eastern Europe 3: Southern Europe 4: Western Europe 5: English-speaking countries 6: North African countries 7: Near and Middle Eastern countries 8: Far Eastern countries 9: South and Gentral America
A11: דמוגרפיה | B11: $D$12 | C11: יניב שפירא: 1 = 18-22 2 = 23-29 3 = 30-39 4 = 40-49 5 = 50-59 6 = 60-69 7 = 70-79 8 = 80 ומעלה | D11: scale | E11: 1 = 18-22 2 = 23-29 3 = 30-39 4 = 40-49 5 = 50-59 6 = 60-69 7 = 70-79 8 = 80 ומעלה | F11: agegroup | G11: =VLOOKUP($F11, codebooks_data_reordered!$A:$I, 2, FALSE) -> #N/A | H11: =VLOOKUP($F11, codebooks_data_reordered!$A:$I, 3, FALSE) -> #N/A | I11: =VLOOKUP($F11, codebooks_data_reordered!$A:$I, 4, FALSE) -> #N/A | J11: =VLOOKUP($F11, codebooks_data_reordered!$A:$I, 5, FALSE) -> #N/A | K11: =VLOOKUP($F11, codebooks_data_reordered!$A:$I, 6, FALSE) -> #N/A | L11: =VLOOKUP($F11, codebooks_data_reordered!$A:$I, 7, FALSE) -> #N/A | M11: =VLOOKUP($F11, codebooks_data_reordered!$A:$I, 9, FALSE) -> #N/A | O11: =SUBSTITUTE(M11, ";", CHAR(10)) -> #N/A
A12: דמוגרפיה | B12: $D$13 | C12: יניב שפירא: 1 = male 2 = female | D12: scale | E12: 1 = male 2 = female | F12: gender | G12: =VLOOKUP($F12, codebooks_data_reordered!$A:$I, 2, FALSE) -> #N/A | H12: =VLOOKUP($F12, codebooks_data_reordered!$A:$I, 3, FALSE) -> #N/A | I12: =VLOOKUP($F12, codebooks_data_reordered!$A:$I, 4, FALSE) -> #N/A | J12: =VLOOKUP($F12, codebooks_data_reordered!$A:$I, 5, FALSE) -> #N/A | K12: =VLOOKUP($F12, codebooks_data_reordered!$A:$I, 6, FALSE) -> #N/A | L12: =VLOOKUP($F12, codebooks_data_reordered!$A:$I, 7, FALSE) -> #N/A | M12: =VLOOKUP($F12, codebooks_data_reordered!$A:$I, 9, FALSE) -> #N/A | O12: =SUBSTITUTE(M12, ";", CHAR(10)) -> #N/A
A13: דמוגרפיה | B13: $M$13 | C13: יניב שפירא: 1 = אישה 2 = גבר | D13: scale | E13: 1 = אישה 2 = גבר | F13: c39 | G13: =VLOOKUP($F13, codebooks_data_reordered!$A:$I, 2, FALSE) -> 1999_1 | H13: =VLOOKUP($F13, codebooks_data_reordered!$A:$I, 3, FALSE) -> RESPONDENT'S DEMOGRAPHIC DETAILS | I13: =VLOOKUP($F13, codebooks_data_reordered!$A:$I, 4, FALSE) -> 3 | J13: =VLOOKUP($F13, codebooks_data_reordered!$A:$I, 5, FALSE) -> 48 | K13: =VLOOKUP($F13, codebooks_data_reordered!$A:$I, 6, FALSE) -> Self-definition of religious identity | L13: =VLOOKUP($F13, codebooks_data_reordered!$A:$I, 7, FALSE) -> 0 | M13: =VLOOKUP($F13, codebooks_data_reordered!$A:$I, 9, FALSE) -> 1: Secular; 2: Traditional; 3: Orthodox; 4: Ultra orthodox | O13: =SUBSTITUTE(M13, ";", CHAR(10)) -> 1: Secular 2: Traditional 3: Orthodox 4: Ultra orthodox
A14: דמוגרפיה | B14: $N$13 | C14: יניב שפירא: 1 = זכר 2 = נקבה | D14: scale | E14: 1 = זכר 2 = נקבה | F14: ccc56 | G14: =VLOOKUP($F14, codebooks_data_reordered!$A:$I, 2, FALSE) -> 1996_Jews | H14: =VLOOKUP($F14, codebooks_data_reordered!$A:$I, 3, FALSE) -> PERSONAL DATA | I14: =VLOOKUP($F14, codebooks_data_reordered!$A:$I, 4, FALSE) -> 1 | J14: =VLOOKUP($F14, codebooks_data_reordered!$A:$I, 5, FALSE) -> 204 | K14: =VLOOKUP($F14, codebooks_data_reordered!$A:$I, 6, FALSE) -> Ethnic self definition | L14: =VLOOKUP($F14, codebooks_data_reordered!$A:$I, 7, FALSE) -> 0 | M14: =VLOOKUP($F14, codebooks_data_reordered!$A:$I, 9, FALSE) -> 1: Ashkenazi; 2: Sephardi; 3: Neither | O14: =SUBSTITUTE(M14, ";", CHAR(10)) -> 1: Ashkenazi 2: Sephardi 3: Neither
A15: דמוגרפיה | B15: $O$13 | C15: יניב שפירא: 1 = אישה 2 = גבר | D15: scale | E15: 1 = אישה 2 = גבר | F15: i67 | G15: =VLOOKUP($F15, codebooks_data_reordered!$A:$I, 2, FALSE) -> 1999_1 | H15: =VLOOKUP($F15, codebooks_data_reordered!$A:$I, 3, FALSE) -> EVALUATE PARTIES AND CANDIDATES | I15: =VLOOKUP($F15, codebooks_data_reordered!$A:$I, 4, FALSE) -> 2 | J15: =VLOOKUP($F15, codebooks_data_reordered!$A:$I, 5, FALSE) -> 69 | K15: =VLOOKUP($F15, codebooks_data_reordered!$A:$I, 6, FALSE) -> Corrupt party | L15: =VLOOKUP($F15, codebooks_data_reordered!$A:$I, 7, FALSE) -> 0 | M15: =VLOOKUP($F15, codebooks_data_reordered!$A:$I, 9, FALSE) -> 1: Labor; 2: Likud; 3: Equally; 4: None of them | O15: =SUBSTITUTE(M15, ";", CHAR(10)) -> 1: Labor 2: Likud 3: Equally 4: None of them
... A46: דמוגרפיה | B46: $D$26 | C46: יניב שפירא: 1 = לא למד 2 = למד במסגרת דתית | D46: scale | E46: 1 = לא למד 2 = למד במסגרת דתית | F46: v137 | G46: =VLOOKUP($F46, codebooks_data_reordered!$A:$I, 2, FALSE) -> 1981_1 | H46: =VLOOKUP($F46, codebooks_data_reordered!$A:$I, 3, FALSE) -> CHARACTERIZATION OF MOSHE DAYAN, GRADED SCALE 1-6 | I46: =VLOOKUP($F46, codebooks_data_reordered!$A:$I, 4, FALSE) -> 1 | J46: =VLOOKUP($F46, codebooks_data_reordered!$A:$I, 5, FALSE) -> 138 | K46: =VLOOKUP($F46, codebooks_data_reordered!$A:$I, 6, FALSE) -> Years of schooling | L46: =VLOOKUP($F46, codebooks_data_reordered!$A:$I, 7, FALSE) -> 0 | M46: =VLOOKUP($F46, codebooks_data_reordered!$A:$I, 9, FALSE) -> 1: Did not study; 2: Up to 4 years; 3: 5-8; 4: 9-10; 5: 11; 6: 12; 7: 13+, without academic degree; 8: University degree | O46: =SUBSTITUTE(M46, ";", CHAR(10)) -> 1: Did not study 2: Up to 4 years 3: 5-8 4: 9-10 5: 11 6: 12 7: 13+, without academic degree 8: University degree
A47: דמוגרפיה | B47: $A$27 | C47: יניב שפירא: ב2022 הוצאה עמדה על 16,000 ₪ ב2019 הוצאה עמדה על 15,000 ₪ ב2015 ההוצאה עמדה על 14,000 ₪ | D47: scale | E47: ב2022 הוצאה עמדה על 16,000 ₪ ב2019 הוצאה עמדה על 15,000 ₪ ב2015 ההוצאה עמדה על 14,000 ₪ | F47: ההוצאה החודשית הממוצעת של משפחה בישראל היא כ-16,500 ₪. בהתחשב בכל ההוצאות של משפחתכם, האם אתם מוציאים: | G47: =VLOOKUP($F47, codebooks_data_reordered!$A:$I, 2, FALSE) -> #N/A | H47: =VLOOKUP($F47, codebooks_data_reordered!$A:$I, 3, FALSE) -> #N/A | I47: =VLOOKUP($F47, codebooks_data_reordered!$A:$I, 4, FALSE) -> #N/A | J47: =VLOOKUP($F47, codebooks_data_reordered!$A:$I, 5, FALSE) -> #N/A | K47: =VLOOKUP($F47, codebooks_data_reordered!$A:$I, 6, FALSE) -> #N/A | L47: =VLOOKUP($F47, codebooks_data_reordered!$A:$I, 7, FALSE) -> #N/A | M47: =VLOOKUP($F47, codebooks_data_reordered!$A:$I, 9, FALSE) -> #N/A | N47: 2022, 2019, 2015 | O47: =SUBSTITUTE(M47, ";", CHAR(10)) -> #N/A
A48: דמוגרפיה | B48: $D$27 | C48: יניב שפירא: 1 = הרבה מתחת לממוצע 2 = מעט מתחת לממוצע 3 = כמו הממוצע 4 = מעט מעל הממוצע 5 = הרבה מעל הממוצע | D48: scale | E48: 1 = הרבה מתחת לממוצע 2 = מעט מתחת לממוצע 3 = כמו הממוצע 4 = מעט מעל הממוצע 5 = הרבה מעל הממוצע | F48: v139 | G48: =VLOOKUP($F48, codebooks_data_reordered!$A:$I, 2, FALSE) -> 1981_1 | H48: =VLOOKUP($F48, codebooks_data_reordered!$A:$I, 3, FALSE) -> CHARACTERIZATION OF MOSHE DAYAN, GRADED SCALE 1-6 | I48: =VLOOKUP($F48, codebooks_data_reordered!$A:$I, 4, FALSE) -> 1 | J48: =VLOOKUP($F48, codebooks_data_reordered!$A:$I, 5, FALSE) -> 140 | K48: =VLOOKUP($F48, codebooks_data_reordered!$A:$I, 6, FALSE) -> Year of Aliyah (immigration) | L48: =VLOOKUP($F48, codebooks_data_reordered!$A:$I, 7, FALSE) -> 0 | M48: =VLOOKUP($F48, codebooks_data_reordered!$A:$I, 9, FALSE) -> 0: 1980+; 1: Born in Israel; 2: Before 1948; 3: 1948-1954; 4: 1955-1960; 5: 1961-1966; 6: 1967-1972; 7: 1973-1977; 8: 1978-1978 | O48: =SUBSTITUTE(M48, ";", CHAR(10)) -> 0: 1980+ 1: Born in Israel 2: Before 1948 3: 1948-1954 4: 1955-1960 5: 1961-1966 6: 1967-1972 7: 1973-1977 8: 1978-1978
A49: דמוגרפיה | B49: $I$27 | C49: יניב שפירא: 1 = הרבה מעל הממוצע 2 = מעט מעל הממוצע 3 = כמו הממוצע 4 = מעט מתחת לממוצע 5 = הרבה מתחת לממוצע | D49: scale | E49: 1 = הרבה מעל הממוצע 2 = מעט מעל הממוצע 3 = כמו הממוצע 4 = מעט מתחת לממוצע 5 = הרבה מתחת לממוצע | F49: v184 | G49: =VLOOKUP($F49, codebooks_data_reordered!$A:$I, 2, FALSE) -> #N/A | H49: =VLOOKUP($F49, codebooks_data_reordered!$A:$I, 3, FALSE) -> #N/A | I49: =VLOOKUP($F49, codebooks_data_reordered!$A:$I, 4, FALSE) -> #N/A | J49: =VLOOKUP($F49, codebooks_data_reordered!$A:$I, 5, FALSE) -> #N/A | K49: =VLOOKUP($F49, codebooks_data_reordered!$A:$I, 6, FALSE) -> #N/A | L49: =VLOOKUP($F49, codebooks_data_reordered!$A:$I, 7, FALSE) -> #N/A | M49: =VLOOKUP($F49, codebooks_data_reordered!$A:$I, 9, FALSE) -> #N/A | O49: =SUBSTITUTE(M49, ";", CHAR(10)) -> #N/A
A50: דמוגרפיה | B50: $S$27 | C50: יניב שפירא: 1 = הרבה מתחת לממוצע 2 = מעט מתחת לממוצע 3 = כמו הממוצע 4 = מעט מעל הממוצע 5 = הרבה מעל הממוצע | D50: scale | E50: 1 = הרבה מתחת לממוצע 2 = מעט מתחת לממוצע 3 = כמו הממוצע 4 = מעט מעל הממוצע 5 = הרבה מעל הממוצע | F50: a55 | G50: =VLOOKUP($F50, codebooks_data_reordered!$A:$I, 2, FALSE) -> 2006 | H50: =VLOOKUP($F50, codebooks_data_reordered!$A:$I, 3, FALSE) -> Agree/Disagree with the Different Statements | I50: =VLOOKUP($F50, codebooks_data_reordered!$A:$I, 4, FALSE) -> 1 | J50: =VLOOKUP($F50, codebooks_data_reordered!$A:$I, 5, FALSE) -> 58 | K50: =VLOOKUP($F50, codebooks_data_reordered!$A:$I, 6, FALSE) -> Affect government policy | L50: =VLOOKUP($F50, codebooks_data_reordered!$A:$I, 7, FALSE) -> 54. To what extent can you and your friends effect government policy? | M50: =VLOOKUP($F50, codebooks_data_reordered!$A:$I, 9, FALSE) -> 1: A great amount; 2: A certain amount; 3: A small amount; 4: Not at all | O50: =SUBSTITUTE(M50, ";", CHAR(10)) -> 1: A great amount 2: A certain amount 3: A small amount 4: Not at all
A51: דמוגרפיה | B51: $T$28 | C51: יניב שפירא: 1 = עד 1,000 2 = 1,001-1,500 3 = 1,501-2,000 4 = 2,001-2,500 5 = 2,501-3,000 6 = 3,001-4,000 7 = 4,001-5,000 8 = 5,001-6,000 9 = 6,001-7,000 10 = 7,001 + | D51: scale | E51: 1 = עד 1,000 2 = 1,001-1,500 3 = 1,501-2,000 4 = 2,001-2,500 5 = 2,501-3,000 6 = 3,001-4,000 7 = 4,001-5,000 8 = 5,001-6,000 9 = 6,001-7,000 10 = 7,001 + | F51: b158 | G51: =VLOOKUP($F51, codebooks_data_reordered!$A:$I, 2, FALSE) -> 1981_3 | H51: =VLOOKUP($F51, codebooks_data_reordered!$A:$I, 3, FALSE) -> INTERVIEWEE EVALUATION OF THE STATE OF ISRAEL | I51: =VLOOKUP($F51, codebooks_data_reordered!$A:$I, 4, FALSE) -> 1 | J51: =VLOOKUP($F51, codebooks_data_reordered!$A:$I, 5, FALSE) -> 168 | K51: =VLOOKUP($F51, codebooks_data_reordered!$A:$I, 6, FALSE) -> Political tendency interviewee identifies with | L51: =VLOOKUP($F51, codebooks_data_reordered!$A:$I, 7, FALSE) -> 0 | M51: =VLOOKUP($F51, codebooks_data_reordered!$A:$I, 9, FALSE) -> 1: Left; 2: Moderate left; 3: Center; 4: Moderate right; 5: Right; 6: Religious; 7: Does not identify with any tendency | O51: =SUBSTITUTE(M51, ";", CHAR(10)) -> 1: Left 2: Moderate left 3: Center 4: Moderate right 5: Right 6: Religious 7: Does not identify with any tendency
A52: דמוגרפיה | B52: $T$29 | C52: יניב שפירא: 1 = חדר אחד 2 = שני חדרים 3 = שלושה חדרים 4 = ארבעה חדרים 5 = חמישה חדרים 6 = שישה חדרים 7 = שבעה חדרים 8 = שמונה חדרים 9 = תשעה חדשים ויותר | D52: scale | E52: 1 = חדר אחד 2 = שני חדרים 3 = שלושה חדרים 4 = ארבעה חדרים 5 = חמישה חדרים 6 = שישה חדרים 7 = שבעה חדרים 8 = שמונה חדרים 9 = תשעה חדשים ויותר | F52: b149 | G52: =VLOOKUP($F52, codebooks_data_reordered!$A:$I, 2, FALSE) -> 1981_3 | H52: =VLOOKUP($F52, codebooks_data_reordered!$A:$I, 3, FALSE) -> INTERVIEWEE EVALUATION OF THE STATE OF ISRAEL | I52: =VLOOKUP($F52, codebooks_data_reordered!$A:$I, 4, FALSE) -> 1 | J52: =VLOOKUP($F52, codebooks_data_reordered!$A:$I, 5, FALSE) -> 155 | K52: =VLOOKUP($F52, codebooks_data_reordered!$A:$I, 6, FALSE) -> Number of times interviewee goes to synagogue during the year | L52: =VLOOKUP($F52, codebooks_data_reordered!$A:$I, 7, FALSE) -> 0 | M52: =VLOOKUP($F52, codebooks_data_reordered!$A:$I, 9, FALSE) -> 1: Every day; 2: Almost every Sabbath and holiday; 3: A few times; 4: Only on Yom Kippur; 5: Never | O52: =SUBSTITUTE(M52, ";", CHAR(10)) -> 1: Every day 2: Almost every Sabbath and holiday 3: A few times 4: Only on Yom Kippur 5: Never
A53: דמוגרפיה | B53: $T$30 | C53: יניב שפירא: 1 = 1 2 = 2 3 = 3 4 = 4 5 = 5 6 = 6 7 = 7 8 = 8 9 = 9+ | D53: scale | E53: 1 = 1 2 = 2 3 = 3 4 = 4 5 = 5 6 = 6 7 = 7 8 = 8 9 = 9+ | F53: b151 | G53: =VLOOKUP($F53, codebooks_data_reordered!$A:$I, 2, FALSE) -> 1981_3 | H53: =VLOOKUP($F53, codebooks_data_reordered!$A:$I, 3, FALSE) -> INTERVIEWEE EVALUATION OF THE STATE OF ISRAEL | I53: =VLOOKUP($F53, codebooks_data_reordered!$A:$I, 4, FALSE) -> 1 | J53: =VLOOKUP($F53, codebooks_data_reordered!$A:$I, 5, FALSE) -> 156 | K53: =VLOOKUP($F53, codebooks_data_reordered!$A:$I, 6, FALSE) -> Number of rooms in dwelling | L53: =VLOOKUP($F53, codebooks_data_reordered!$A:$I, 7, FALSE) -> 0 | M53: =VLOOKUP($F53, codebooks_data_reordered!$A:$I, 9, FALSE) -> 1: One room; 2: 2; 3: 3; 4: 4; 5: 5; 6: 6; 7: 7; 8: 8; 9: 9+ | O53: =SUBSTITUTE(M53, ";", CHAR(10)) -> 1: One room 2: 2 3: 3 4: 4 5: 5 6: 6 7: 7 8: 8 9: 9+
A54: דמוגרפיה | B54: $AF$30 | C54: יניב שפירא: מס' הילדים שגרים בבית | D54: rephrase | E54: מס' הילדים שגרים בבית | F54: c52 | G54: =VLOOKUP($F54, codebooks_data_reordered!$A:$I, 2, FALSE) -> 2006 | H54: =VLOOKUP($F54, codebooks_data_reordered!$A:$I, 3, FALSE) -> Self-identity | I54: =VLOOKUP($F54, codebooks_data_reordered!$A:$I, 4, FALSE) -> 1 | J54: =VLOOKUP($F54, codebooks_data_reordered!$A:$I, 5, FALSE) -> 266 | K54: =VLOOKUP($F54, codebooks_data_reordered!$A:$I, 6, FALSE) -> Minimum threshold for representation in the Knesset | L54: =VLOOKUP($F54, codebooks_data_reordered!$A:$I, 7, FALSE) -> 51. To the best of your knowledge, what is the minimum threshold for representation in the Knesset? | M54: =VLOOKUP($F54, codebooks_data_reordered!$A:$I, 9, FALSE) -> 1: 2%; 2: Wrong answer; 8: Don't know | O54: =SUBSTITUTE(M54, ";", CHAR(10)) -> 1: 2% 2: Wrong answer 8: Don't know
A55: דמוגרפיה | B55: $S$31 | C55: יניב שפירא: צפיפות מדד אחד לחדרים\נפשות | D55: scale | E55: צפיפות מדד אחד לחדרים\נפשות | F55: a57 | G55: =VLOOKUP($F55, codebooks_data_reordered!$A:$I, 2, FALSE) -> 2006 | H55: =VLOOKUP($F55, codebooks_data_reordered!$A:$I, 3, FALSE) -> Personal Status | I55: =VLOOKUP($F55, codebooks_data_reordered!$A:$I, 4, FALSE) -> 1 | J55: =VLOOKUP($F55, codebooks_data_reordered!$A:$I, 5, FALSE) -> 60 | K55: =VLOOKUP($F55, codebooks_data_reordered!$A:$I, 6, FALSE) -> Your personal status 5 years ago | L55: =VLOOKUP($F55, codebooks_data_reordered!$A:$I, 7, FALSE) -> Here you have a 9 stages scale describing different situations a person can be on. The top of the ladder is 9 and that is the best possible situation that you can think of and 1 is the worst. On which rank would you place yourself? | M55: =VLOOKUP($F55, codebooks_data_reordered!$A:$I, 9, FALSE) -> 1: Worst; 9: Best | O55: =SUBSTITUTE(M55, ";", CHAR(10)) -> 1: Worst 9: Best
A56: דמוגרפיה | B56: $AF$31 | C56: יניב שפירא: 1 = עד ולא כולל 1 2 = 1-1.99 2 = 2-2.99 3 = 3-3.99 4 = 4+ | D56: scale | E56: 1 = עד ולא כולל 1 2 = 1-1.99 2 = 2-2.99 3 = 3-3.99 4 = 4+ | F56: c50 | G56: =VLOOKUP($F56, codebooks_data_reordered!$A:$I, 2, FALSE) -> 2006 | H56: =VLOOKUP($F56, codebooks_data_reordered!$A:$I, 3, FALSE) -> Self-identity | I56: =VLOOKUP($F56, codebooks_data_reordered!$A:$I, 4, FALSE) -> 1 | J56: =VLOOKUP($F56, codebooks_data_reordered!$A:$I, 5, FALSE) -> 264 | K56: =VLOOKUP($F56, codebooks_data_reordered!$A:$I, 6, FALSE) -> Self-identity for Arabs (third) | L56: =VLOOKUP($F56, codebooks_data_reordered!$A:$I, 7, FALSE) -> (for Arabs): Which of the following concepts best defines your identity? (read) and the second? And the third? And the fourth? | M56: =VLOOKUP($F56, codebooks_data_reordered!$A:$I, 9, FALSE) -> 1: Israeli; 2: Palestinian; 3: Arab; 4: Muslim/Christian/Druze | O56: =SUBSTITUTE(M56, ";", CHAR(10)) -> 1: Israeli 2: Palestinian 3: Arab 4: Muslim/Christian/Druze
A57: דמוגרפיה | B57: $D$32 | C57: יניב שפירא: 1 = יהודי 2 = מוסלמי 3 = נוצרי 4 = דרוזי 5 = אחר | D57: scale | E57: 1 = יהודי 2 = מוסלמי 3 = נוצרי 4 = דרוזי 5 = אחר | F57: v143_code | G57: =VLOOKUP($F57, codebooks_data_reordered!$A:$I, 2, FALSE) -> #N/A | H57: =VLOOKUP($F57, codebooks_data_reordered!$A:$I, 3, FALSE) -> #N/A | I57: =VLOOKUP($F57, codebooks_data_reordered!$A:$I, 4, FALSE) -> #N/A | J57: =VLOOKUP($F57, codebooks_data_reordered!$A:$I, 5, FALSE) -> #N/A | K57: =VLOOKUP($F57, codebooks_data_reordered!$A:$I, 6, FALSE) -> #N/A | L57: =VLOOKUP($F57, codebooks_data_reordered!$A:$I, 7, FALSE) -> #N/A | M57: =VLOOKUP($F57, codebooks_data_reordered!$A:$I, 9, FALSE) -> #N/A | O57: =SUBSTITUTE(M57, ";", CHAR(10)) -> #N/A
A58: דמוגרפיה | B58: $K$32 | C58: יניב שפירא: לא ליהודים 1 = מוסלמי 2 = נוצרי 3 = דרוזי | D58: scale | E58: לא ליהודים 1 = מוסלמי 2 = נוצרי 3 = דרוזי | F58: b90 | G58: =VLOOKUP($F58, codebooks_data_reordered!$A:$I, 2, FALSE) -> 2003 | H58: =VLOOKUP($F58, codebooks_data_reordered!$A:$I, 3, FALSE) -> Respondent's demographic details | I58: =VLOOKUP($F58, codebooks_data_reordered!$A:$I, 4, FALSE) -> 1 | J58: =VLOOKUP($F58, codebooks_data_reordered!$A:$I, 5, FALSE) -> 198 | K58: =VLOOKUP($F58, codebooks_data_reordered!$A:$I, 6, FALSE) -> Social class (self identified) | L58: =VLOOKUP($F58, codebooks_data_reordered!$A:$I, 7, FALSE) -> To which social class do you belong? | M58: =VLOOKUP($F58, codebooks_data_reordered!$A:$I, 9, FALSE) -> 1: Upper class; 2: Middle upper; 3: Middle; 4: Lower | O58: =SUBSTITUTE(M58, ";", CHAR(10)) -> 1: Upper class 2: Middle upper 3: Middle 4: Lower
A59: דמוגרפיה | B59: $L$32 | C59: יניב שפירא: 5 = מוסלמי 6 = נוצרי 7 = דרוזי | D59: scale | E59: 5 = מוסלמי 6 = נוצרי 7 = דרוזי | F59: b28 | G59: =VLOOKUP($F59, codebooks_data_reordered!$A:$I, 2, FALSE) -> 2006 | H59: =VLOOKUP($F59, codebooks_data_reordered!$A:$I, 3, FALSE) -> State expenditures on Different Issues | I59: =VLOOKUP($F59, codebooks_data_reordered!$A:$I, 4, FALSE) -> 1 | J59: =VLOOKUP($F59, codebooks_data_reordered!$A:$I, 5, FALSE) -> 138 | K59: =VLOOKUP($F59, codebooks_data_reordered!$A:$I, 6, FALSE) -> State expenditures on Ecology | L59: =VLOOKUP($F59, codebooks_data_reordered!$A:$I, 7, FALSE) -> Should the country spend more money, less money or the same as it does today on the following issues: | M59: =VLOOKUP($F59, codebooks_data_reordered!$A:$I, 9, FALSE) -> 1: More; 2: Less; 3: The same as today | O59: =SUBSTITUTE(M59, ";", CHAR(10)) -> 1: More 2: Less 3: The same as today
... A158: ישראל כללי | B158: $S$11 | C158: יניב שפירא: 1 = המערך 2 = הליכוד 3 = שניהם אותו דבר 4 = אף אחד מהם | D158: scale | E158: 1 = המערך 2 = הליכוד 3 = שניהם אותו דבר 4 = אף אחד מהם | F158: v25 | G158: =VLOOKUP($F158, codebooks_data_reordered!$A:$I, 2, FALSE) -> 1999_1 | H158: =VLOOKUP($F158, codebooks_data_reordered!$A:$I, 3, FALSE) -> GENERAL POLITICAL ATTITUDE | I158: =VLOOKUP($F158, codebooks_data_reordered!$A:$I, 4, FALSE) -> 1 | J158: =VLOOKUP($F158, codebooks_data_reordered!$A:$I, 5, FALSE) -> 30 | K158: =VLOOKUP($F158, codebooks_data_reordered!$A:$I, 6, FALSE) -> What should be emphasized to prevent war between Israel and the Arab world? | L158: =VLOOKUP($F158, codebooks_data_reordered!$A:$I, 7, FALSE) -> 0 | M158: =VLOOKUP($F158, codebooks_data_reordered!$A:$I, 9, FALSE) -> 1: Focus on Peace talks; 2: Increase military power | O158: =SUBSTITUTE(M158, ";", CHAR(10)) -> 1: Focus on Peace talks 2: Increase military power
A159: ישראל כללי | B159: $A$12 | C159: יניב שפירא: אין קידוד גם ב2020 וגם ב2021 | D159: scale | E159: אין קידוד גם ב2020 וגם ב2021 | F159: מבין הדברים הבאים, מה לדעתך הכי מאיים על המערכת הפוליטית כיום? | G159: =VLOOKUP($F159, codebooks_data_reordered!$A:$I, 2, FALSE) -> #N/A | H159: =VLOOKUP($F159, codebooks_data_reordered!$A:$I, 3, FALSE) -> #N/A | I159: =VLOOKUP($F159, codebooks_data_reordered!$A:$I, 4, FALSE) -> #N/A | J159: =VLOOKUP($F159, codebooks_data_reordered!$A:$I, 5, FALSE) -> #N/A | K159: =VLOOKUP($F159, codebooks_data_reordered!$A:$I, 6, FALSE) -> #N/A | L159: =VLOOKUP($F159, codebooks_data_reordered!$A:$I, 7, FALSE) -> #N/A | M159: =VLOOKUP($F159, codebooks_data_reordered!$A:$I, 9, FALSE) -> #N/A | N159: 2020, 2021 | O159: =SUBSTITUTE(M159, ";", CHAR(10)) -> #N/A
A160: ישראל כללי | B160: $D$12 | C160: יניב שפירא: 1 = שחיתות 2 = פוליטיקאים שלא מקיימים הבטחות 3 = גורמים שמתערבים בבחירות כך שהתוצאות לא מייצגות את רצון הבוחר 4 = שיטת הבחירות שמעוותת את רצון הבוחרים | D160: scale | E160: 1 = שחיתות 2 = פוליטיקאים שלא מקיימים הבטחות 3 = גורמים שמתערבים בבחירות כך שהתוצאות לא מייצגות את רצון הבוחר 4 = שיטת הבחירות שמעוותת את רצון הבוחרים | F160: 0 | G160: =VLOOKUP($F160, codebooks_data_reordered!$A:$I, 2, FALSE) -> #N/A | H160: =VLOOKUP($F160, codebooks_data_reordered!$A:$I, 3, FALSE) -> #N/A | I160: =VLOOKUP($F160, codebooks_data_reordered!$A:$I, 4, FALSE) -> #N/A | J160: =VLOOKUP($F160, codebooks_data_reordered!$A:$I, 5, FALSE) -> #N/A | K160: =VLOOKUP($F160, codebooks_data_reordered!$A:$I, 6, FALSE) -> #N/A | L160: =VLOOKUP($F160, codebooks_data_reordered!$A:$I, 7, FALSE) -> #N/A | M160: =VLOOKUP($F160, codebooks_data_reordered!$A:$I, 9, FALSE) -> #N/A | O160: =SUBSTITUTE(M160, ";", CHAR(10)) -> #N/A
A161: ישראל כללי | B161: $D$13 | C161: יניב שפירא: 1-10 1 = כלל לא מרוצה 10 = מרוצה לגמרי | D161: scale | E161: 1-10 1 = כלל לא מרוצה 10 = מרוצה לגמרי | F161: v116 | G161: =VLOOKUP($F161, codebooks_data_reordered!$A:$I, 2, FALSE) -> 1988_Panel_N=416 | H161: =VLOOKUP($F161, codebooks_data_reordered!$A:$I, 3, FALSE) -> WHICH OF THE FOLLOWING WOULD YOU BE WILLING TO GIVE TO MAINTAIN/STRENGTHEN THE SECURITY | I161: =VLOOKUP($F161, codebooks_data_reordered!$A:$I, 4, FALSE) -> 1 | J161: =VLOOKUP($F161, codebooks_data_reordered!$A:$I, 5, FALSE) -> 112 | K161: =VLOOKUP($F161, codebooks_data_reordered!$A:$I, 6, FALSE) -> Should security considerations override other social/ecconomic considerations | L161: =VLOOKUP($F161, codebooks_data_reordered!$A:$I, 7, FALSE) -> 0 | M161: =VLOOKUP($F161, codebooks_data_reordered!$A:$I, 9, FALSE) -> 1: Security considerations should override all others; 7: Security should not override | O161: =SUBSTITUTE(M161, ";", CHAR(10)) -> 1: Security considerations should override all others 7: Security should not override
A162: ישראל כללי | B162: $A$14 | C162: יניב שפירא: שאלות 12A-14A בפוסט בחירות 2019 לא מקודדות בstata | D162: stataIsNotCoded | E162: שאלות 12A-14A בפוסט בחירות 2019 לא מקודדות בstata | F162: כאשר אתה חושב על תולדות מדינת ישראל ועם ישראל, איזה אירוע מהעבר נראה לך החשוב ביותר? | G162: =VLOOKUP($F162, codebooks_data_reordered!$A:$I, 2, FALSE) -> #N/A | H162: =VLOOKUP($F162, codebooks_data_reordered!$A:$I, 3, FALSE) -> #N/A | I162: =VLOOKUP($F162, codebooks_data_reordered!$A:$I, 4, FALSE) -> #N/A | J162: =VLOOKUP($F162, codebooks_data_reordered!$A:$I, 5, FALSE) -> #N/A | K162: =VLOOKUP($F162, codebooks_data_reordered!$A:$I, 6, FALSE) -> #N/A | L162: =VLOOKUP($F162, codebooks_data_reordered!$A:$I, 7, FALSE) -> #N/A | M162: =VLOOKUP($F162, codebooks_data_reordered!$A:$I, 9, FALSE) -> #N/A | N162: 2019 | O162: =SUBSTITUTE(M162, ";", CHAR(10)) -> #N/A
A163: ישראל כללי | B163: $B$14 | C163: adi: שאלות 709-711 לא מקודדות בנתונים | D163: stataIsNotCoded | E163: שאלות 709-711 לא מקודדות בנתונים | F163: 0 | G163: =VLOOKUP($F163, codebooks_data_reordered!$A:$I, 2, FALSE) -> #N/A | H163: =VLOOKUP($F163, codebooks_data_reordered!$A:$I, 3, FALSE) -> #N/A | I163: =VLOOKUP($F163, codebooks_data_reordered!$A:$I, 4, FALSE) -> #N/A | J163: =VLOOKUP($F163, codebooks_data_reordered!$A:$I, 5, FALSE) -> #N/A | K163: =VLOOKUP($F163, codebooks_data_reordered!$A:$I, 6, FALSE) -> #N/A | L163: =VLOOKUP($F163, codebooks_data_reordered!$A:$I, 7, FALSE) -> #N/A | M163: =VLOOKUP($F163, codebooks_data_reordered!$A:$I, 9, FALSE) -> #N/A | O163: =SUBSTITUTE(M163, ";", CHAR(10)) -> #N/A
A164: ישראל כללי | B164: $B$15 | C164: adi: שאלות 709-711 לא מקודדות בנתונים | D164: stataIsNotCoded | E164: שאלות 709-711 לא מקודדות בנתונים | F164: 0 | G164: =VLOOKUP($F164, codebooks_data_reordered!$A:$I, 2, FALSE) -> #N/A | H164: =VLOOKUP($F164, codebooks_data_reordered!$A:$I, 3, FALSE) -> #N/A | I164: =VLOOKUP($F164, codebooks_data_reordered!$A:$I, 4, FALSE) -> #N/A | J164: =VLOOKUP($F164, codebooks_data_reordered!$A:$I, 5, FALSE) -> #N/A | K164: =VLOOKUP($F164, codebooks_data_reordered!$A:$I, 6, FALSE) -> #N/A | L164: =VLOOKUP($F164, codebooks_data_reordered!$A:$I, 7, FALSE) -> #N/A | M164: =VLOOKUP($F164, codebooks_data_reordered!$A:$I, 9, FALSE) -> #N/A | O164: =SUBSTITUTE(M164, ";", CHAR(10)) -> #N/A
A165: ישראל כללי | B165: $B$16 | C165: adi: שאלות 709-711 לא מקודדות בנתונים | D165: stataIsNotCoded | E165: שאלות 709-711 לא מקודדות בנתונים | F165: 0 | G165: =VLOOKUP($F165, codebooks_data_reordered!$A:$I, 2, FALSE) -> #N/A | H165: =VLOOKUP($F165, codebooks_data_reordered!$A:$I, 3, FALSE) -> #N/A | I165: =VLOOKUP($F165, codebooks_data_reordered!$A:$I, 4, FALSE) -> #N/A | J165: =VLOOKUP($F165, codebooks_data_reordered!$A:$I, 5, FALSE) -> #N/A | K165: =VLOOKUP($F165, codebooks_data_reordered!$A:$I, 6, FALSE) -> #N/A | L165: =VLOOKUP($F165, codebooks_data_reordered!$A:$I, 7, FALSE) -> #N/A | M165: =VLOOKUP($F165, codebooks_data_reordered!$A:$I, 9, FALSE) -> #N/A | O165: =SUBSTITUTE(M165, ";", CHAR(10)) -> #N/A
A166: ישראל כללי | B166: $G$17 | C166: יניב שפירא: 1 = בהחלט לא מסכים 2 = לא מסכים 3 = מסכים 4 = מסכים מאד | D166: scale | E166: 1 = בהחלט לא מסכים 2 = לא מסכים 3 = מסכים 4 = מסכים מאד | F166: v33 | G166: =VLOOKUP($F166, codebooks_data_reordered!$A:$I, 2, FALSE) -> 1999_1 | H166: =VLOOKUP($F166, codebooks_data_reordered!$A:$I, 3, FALSE) -> VALUES AND TRUST | I166: =VLOOKUP($F166, codebooks_data_reordered!$A:$I, 4, FALSE) -> 1 | J166: =VLOOKUP($F166, codebooks_data_reordered!$A:$I, 5, FALSE) -> 38 | K166: =VLOOKUP($F166, codebooks_data_reordered!$A:$I, 6, FALSE) -> Extend of faith in the Supreme Court | L166: =VLOOKUP($F166, codebooks_data_reordered!$A:$I, 7, FALSE) -> 0 | M166: =VLOOKUP($F166, codebooks_data_reordered!$A:$I, 9, FALSE) -> 1: Not at all; 2: A little faith; 3: Some faith; 4: Strong faith | O166: =SUBSTITUTE(M166, ";", CHAR(10)) -> 1: Not at all 2: A little faith 3: Some faith 4: Strong faith
A167: ישראל כללי | B167: $H$18 | C167: יניב שפירא: 1 = בהחלט לא מסכים 2 = לא מסכים 3 = מסכים 4 = מסכים מאד | D167: scale | E167: 1 = בהחלט לא מסכים 2 = לא מסכים 3 = מסכים 4 = מסכים מאד | F167: v40 | G167: =VLOOKUP($F167, codebooks_data_reordered!$A:$I, 2, FALSE) -> 1999_1 | H167: =VLOOKUP($F167, codebooks_data_reordered!$A:$I, 3, FALSE) -> VALUES AND TRUST | I167: =VLOOKUP($F167, codebooks_data_reordered!$A:$I, 4, FALSE) -> 1 | J167: =VLOOKUP($F167, codebooks_data_reordered!$A:$I, 5, FALSE) -> 45 | K167: =VLOOKUP($F167, codebooks_data_reordered!$A:$I, 6, FALSE) -> Peace as a significant value | L167: =VLOOKUP($F167, codebooks_data_reordered!$A:$I, 7, FALSE) -> 0 | M167: =VLOOKUP($F167, codebooks_data_reordered!$A:$I, 9, FALSE) -> 1: Most important value; 2: Second value; 3: Third value; 4: Fourth value | O167: =SUBSTITUTE(M167, ";", CHAR(10)) -> 1: Most important value 2: Second value 3: Third value 4: Fourth value
A168: ישראל כללי | B168: $G$19 | C168: יניב שפירא: 1 = שמירה על כלכלה יציבה 2 = יצירה של סביבה אנושית יותר, שמדגישה יותר יחסי אנוש 3 = יצירת סביבה בה רעיונות נחשבים יותר מכסף 4 = מלחמה בפשע | D168: scale | E168: 1 = שמירה על כלכלה יציבה 2 = יצירה של סביבה אנושית יותר, שמדגישה יותר יחסי אנוש 3 = יצירת סביבה בה רעיונות נחשבים יותר מכסף 4 = מלחמה בפשע | F168: v107 | G168: =VLOOKUP($F168, codebooks_data_reordered!$A:$I, 2, FALSE) -> 1988_Panel_N=416 | H168: =VLOOKUP($F168, codebooks_data_reordered!$A:$I, 3, FALSE) -> WHICH OF THE FOLLOWING WOULD YOU BE WILLING TO GIVE TO MAINTAIN/STRENGTHEN THE SECURITY | I168: =VLOOKUP($F168, codebooks_data_reordered!$A:$I, 4, FALSE) -> 1 | J168: =VLOOKUP($F168, codebooks_data_reordered!$A:$I, 5, FALSE) -> 103 | K168: =VLOOKUP($F168, codebooks_data_reordered!$A:$I, 6, FALSE) -> What is your opinion on the length of military service | L168: =VLOOKUP($F168, codebooks_data_reordered!$A:$I, 7, FALSE) -> 0 | M168: =VLOOKUP($F168, codebooks_data_reordered!$A:$I, 9, FALSE) -> 1: Too long; 2: Appropriate; 3: Too short | O168: =SUBSTITUTE(M168, ";", CHAR(10)) -> 1: Too long 2: Appropriate 3: Too short
...
