Workbook

Sheet Comments_Output
A1: Sheet Name | B1: Cell Address | C1: Comment | D1: Name | E1: type | F1: Comment Content | G1: isSector | H1: isOpen | I1: otherType | J1: comment2 | K1: finalType | L1: Content Only | Q1: יהודים בלבד | R1: ליהודים בלבד | T1: ערבים בלבד | U1: לערבים בלבד | W1: שאלה פתוחה | X1: פתוח | Z1: לנשים בלבד
A2: דמוגרפיה | B2: $L$3 | C2: יניב שפירא: 1 = ינואר 2 = פברואר | E2: scale | F2: יניב שפירא: 1 = ינואר 2 = פברואר | G2: =IF(EXACT($F2, $Q$1), "sector", "unknown") -> unknown | H2: =IF(EXACT(F2,$W$1), "open", IF(EXACT(F2,$X$1), "open", "unknown")) -> unknown | K2: =IF(AND(E2<>"", E2<>"unknown"), E2, IF(AND(G2<>"", G2<>"unknown"), G2, IF(AND(H2<>"", H2<>"unknown"), H2, IF(I2<>"", I2, "ERROR")))) -> scale
A3: דמוגרפיה | B3: $A$5 | C3: יניב שפירא: שאלה 145 אין קידוד בstata גם ב2020 וגם ב2019 גם ב2021 | E3: scale | F3: יניב שפירא: שאלה 145 אין קידוד בstata גם ב2020 וגם ב2019 גם ב2021 | G3: =IF(EXACT($F3, $Q$1), "sector", "unknown") -> unknown | H3: =IF(EXACT(F3,$W$1), "open", IF(EXACT(F3,$X$1), "open", "unknown")) -> unknown | K3: =IF(AND(E3<>"", E3<>"unknown"), E3, IF(AND(G3<>"", G3<>"unknown"), G3, IF(AND(H3<>"", H3<>"unknown"), H3, IF(I3<>"", I3, "ERROR")))) -> scale
A4: דמוגרפיה | B4: $D$6 | C4: יניב שפירא: 1 = יהודי 2 = ערבי | E4: scale | F4: יניב שפירא: 1 = יהודי 2 = ערבי | G4: =IF(EXACT($F4, $Q$1), "sector", "unknown") -> unknown | H4: =IF(EXACT(F4,$W$1), "open", IF(EXACT(F4,$X$1), "open", "unknown")) -> unknown | K4: =IF(AND(E4<>"", E4<>"unknown"), E4, IF(AND(G4<>"", G4<>"unknown"), G4, IF(AND(H4<>"", H4<>"unknown"), H4, IF(I4<>"", I4, "ERROR")))) -> scale
A5: דמוגרפיה | B5: $F$8 | C5: יניב שפירא: 1 = גרסה A 2 = גרסה B | E5: scale | F5: יניב שפירא: 1 = גרסה A 2 = גרסה B | G5: =IF(EXACT($F5, $Q$1), "sector", "unknown") -> unknown | H5: =IF(EXACT(F5,$W$1), "open", IF(EXACT(F5,$X$1), "open", "unknown")) -> unknown | K5: =IF(AND(E5<>"", E5<>"unknown"), E5, IF(AND(G5<>"", G5<>"unknown"), G5, IF(AND(H5<>"", H5<>"unknown"), H5, IF(I5<>"", I5, "ERROR")))) -> scale
A6: דמוגרפיה | B6: $I$8 | C6: יניב שפירא: a , b, c | D6: יניב שפירא | E6: scale | F6: a , b, c | G6: =IF(EXACT($F6, $Q$1), "sector", "unknown") -> unknown | H6: =IF(EXACT(F6,$W$1), "open", IF(EXACT(F6,$X$1), "open", "unknown")) -> unknown | K6: =IF(AND(E6<>"", E6<>"unknown"), E6, IF(AND(G6<>"", G6<>"unknown"), G6, IF(AND(H6<>"", H6<>"unknown"), H6, IF(I6<>"", I6, "ERROR")))) -> scale
A7: דמוגרפיה | B7: $L$9 | C7: יניב שפירא: 1 = עברית 2 = ערבית 3 = רוסית | E7: scale | F7: יניב שפירא: 1 = עברית 2 = ערבית 3 = רוסית | G7: =IF(EXACT($F7, $Q$1), "sector", "unknown") -> unknown | H7: =IF(EXACT(F7,$W$1), "open", IF(EXACT(F7,$X$1), "open", "unknown")) -> unknown | K7: =IF(AND(E7<>"", E7<>"unknown"), E7, IF(AND(G7<>"", G7<>"unknown"), G7, IF(AND(H7<>"", H7<>"unknown"), H7, IF(I7<>"", I7, "ERROR")))) -> scale
A8: דמוגרפיה | B8: $W$10 | C8: יניב שפירא: 1 = 20-25 2 = 25-29 3 = 30-34 4 = 35-39 5 = 40-44 6 = 45-49 7 = 50-54 8 = 55-64 9 = 65+ | E8: scale | F8: יניב שפירא: 1 = 20-25 2 = 25-29 3 = 30-34 4 = 35-39 5 = 40-44 6 = 45-49 7 = 50-54 8 = 55-64 9 = 65+ | G8: =IF(EXACT($F8, $Q$1), "sector", "unknown") -> unknown | H8: =IF(EXACT(F8,$W$1), "open", IF(EXACT(F8,$X$1), "open", "unknown")) -> unknown | K8: =IF(AND(E8<>"", E8<>"unknown"), E8, IF(AND(G8<>"", G8<>"unknown"), G8, IF(AND(H8<>"", H8<>"unknown"), H8, IF(I8<>"", I8, "ERROR")))) -> scale
A9: דמוגרפיה | B9: $AB$10 | C9: יניב שפירא: 1 = 20-24 2 = 25-29 3 = 30-34 4 = 35-39 5 = 40-44 6 = 45-49 7 = 50-54 8 = 55-64 9 = 65+ | E9: scale | F9: יניב שפירא: 1 = 20-24 2 = 25-29 3 = 30-34 4 = 35-39 5 = 40-44 6 = 45-49 7 = 50-54 8 = 55-64 9 = 65+ | G9: =IF(EXACT($F9, $Q$1), "sector", "unknown") -> unknown | H9: =IF(EXACT(F9,$W$1), "open", IF(EXACT(F9,$X$1), "open", "unknown")) -> unknown | K9: =IF(AND(E9<>"", E9<>"unknown"), E9, IF(AND(G9<>"", G9<>"unknown"), G9, IF(AND(H9<>"", H9<>"unknown"), H9, IF(I9<>"", I9, "ERROR")))) -> scale
A10: דמוגרפיה | B10: $AH$10 | C10: יניב שפירא: 1 = 18-24 2 = 25-29 3 = 30-34 4 = 35-39 5 = 40-44 6 = 45-49 7 = 50-54 8 = 55-64 9 = 65+ | E10: scale | F10: יניב שפירא: 1 = 18-24 2 = 25-29 3 = 30-34 4 = 35-39 5 = 40-44 6 = 45-49 7 = 50-54 8 = 55-64 9 = 65+ | G10: =IF(EXACT($F10, $Q$1), "sector", "unknown") -> unknown | H10: =IF(EXACT(F10,$W$1), "open", IF(EXACT(F10,$X$1), "open", "unknown")) -> unknown | K10: =IF(AND(E10<>"", E10<>"unknown"), E10, IF(AND(G10<>"", G10<>"unknown"), G10, IF(AND(H10<>"", H10<>"unknown"), H10, IF(I10<>"", I10, "ERROR")))) -> scale
A11: דמוגרפיה | B11: $D$12 | C11: יניב שפירא: 1 = 18-22 2 = 23-29 3 = 30-39 4 = 40-49 5 = 50-59 6 = 60-69 7 = 70-79 8 = 80 ומעלה | E11: scale | F11: יניב שפירא: 1 = 18-22 2 = 23-29 3 = 30-39 4 = 40-49 5 = 50-59 6 = 60-69 7 = 70-79 8 = 80 ומעלה | G11: =IF(EXACT($F11, $Q$1), "sector", "unknown") -> unknown | H11: =IF(EXACT(F11,$W$1), "open", IF(EXACT(F11,$X$1), "open", "unknown")) -> unknown | K11: =IF(AND(E11<>"", E11<>"unknown"), E11, IF(AND(G11<>"", G11<>"unknown"), G11, IF(AND(H11<>"", H11<>"unknown"), H11, IF(I11<>"", I11, "ERROR")))) -> scale
A12: דמוגרפיה | B12: $D$13 | C12: יניב שפירא: 1 = male 2 = female | E12: scale | F12: יניב שפירא: 1 = male 2 = female | G12: =IF(EXACT($F12, $Q$1), "sector", "unknown") -> unknown | H12: =IF(EXACT(F12,$W$1), "open", IF(EXACT(F12,$X$1), "open", "unknown")) -> unknown | K12: =IF(AND(E12<>"", E12<>"unknown"), E12, IF(AND(G12<>"", G12<>"unknown"), G12, IF(AND(H12<>"", H12<>"unknown"), H12, IF(I12<>"", I12, "ERROR")))) -> scale
A13: דמוגרפיה | B13: $M$13 | C13: יניב שפירא: 1 = אישה 2 = גבר | E13: scale | F13: יניב שפירא: 1 = אישה 2 = גבר | G13: =IF(EXACT($F13, $Q$1), "sector", "unknown") -> unknown | H13: =IF(EXACT(F13,$W$1), "open", IF(EXACT(F13,$X$1), "open", "unknown")) -> unknown | K13: =IF(AND(E13<>"", E13<>"unknown"), E13, IF(AND(G13<>"", G13<>"unknown"), G13, IF(AND(H13<>"", H13<>"unknown"), H13, IF(I13<>"", I13, "ERROR")))) -> scale
A14: דמוגרפיה | B14: $N$13 | C14: יניב שפירא: 1 = זכר 2 = נקבה | E14: scale | F14: יניב שפירא: 1 = זכר 2 = נקבה | G14: =IF(EXACT($F14, $Q$1), "sector", "unknown") -> unknown | H14: =IF(EXACT(F14,$W$1), "open", IF(EXACT(F14,$X$1), "open", "unknown")) -> unknown | K14: =IF(AND(E14<>"", E14<>"unknown"), E14, IF(AND(G14<>"", G14<>"unknown"), G14, IF(AND(H14<>"", H14<>"unknown"), H14, IF(I14<>"", I14, "ERROR")))) -> scale
A15: דמוגרפיה | B15: $O$13 | C15: יניב שפירא: 1 = אישה 2 = גבר | E15: scale | F15: יניב שפירא: 1 = אישה 2 = גבר | G15: =IF(EXACT($F15, $Q$1), "sector", "unknown") -> unknown | H15: =IF(EXACT(F15,$W$1), "open", IF(EXACT(F15,$X$1), "open", "unknown")) -> unknown | K15: =IF(AND(E15<>"", E15<>"unknown"), E15, IF(AND(G15<>"", G15<>"unknown"), G15, IF(AND(H15<>"", H15<>"unknown"), H15, IF(I15<>"", I15, "ERROR")))) -> scale
A16: דמוגרפיה | B16: $T$13 | C16: יניב שפירא: 1 = גבר 2 = אישה | E16: scale | F16: יניב שפירא: 1 = גבר 2 = אישה | G16: =IF(EXACT($F16, $Q$1), "sector", "unknown") -> unknown | H16: =IF(EXACT(F16,$W$1), "open", IF(EXACT(F16,$X$1), "open", "unknown")) -> unknown | K16: =IF(AND(E16<>"", E16<>"unknown"), E16, IF(AND(G16<>"", G16<>"unknown"), G16, IF(AND(H16<>"", H16<>"unknown"), H16, IF(I16<>"", I16, "ERROR")))) -> scale
A17: דמוגרפיה | B17: $D$14 | C17: יניב שפירא: 1 = עממית או פחות 2 = תיכונית חלקית 3 = תיכונית מלאה - ללא בגרות 4 = תיכונית מלאה - עם בגרות 5 = על תיכונית לא אקדמית 6 = תואר אקדמאי חלקי 7 = תואר ראשון 8 = תואר שני ומעלה | E17: scale | F17: יניב שפירא: 1 = עממית או פחות 2 = תיכונית חלקית 3 = תיכונית מלאה - ללא בגרות 4 = תיכונית מלאה - עם בגרות 5 = על תיכונית לא אקדמית 6 = תואר אקדמאי חלקי 7 = תואר ראשון 8 = תואר שני ומעלה | G17: =IF(EXACT($F17, $Q$1), "sector", "unknown") -> unknown | H17: =IF(EXACT(F17,$W$1), "open", IF(EXACT(F17,$X$1), "open", "unknown")) -> unknown | K17: =IF(AND(E17<>"", E17<>"unknown"), E17, IF(AND(G17<>"", G17<>"unknown"), G17, IF(AND(H17<>"", H17<>"unknown"), H17, IF(I17<>"", I17, "ERROR")))) -> scale
A18: דמוגרפיה | B18: $S$15 | C18: יניב שפירא: 1 = לא למד בכלל 2 = עד 4 שנים 3 = 5-8 4 = 9-10 5 = 11 6 = 12 7 = 13 + (בלי תואר) 8 = בעל תואר | E18: scale | F18: יניב שפירא: 1 = לא למד בכלל 2 = עד 4 שנים 3 = 5-8 4 = 9-10 5 = 11 6 = 12 7 = 13 + (בלי תואר) 8 = בעל תואר | G18: =IF(EXACT($F18, $Q$1), "sector", "unknown") -> unknown | H18: =IF(EXACT(F18,$W$1), "open", IF(EXACT(F18,$X$1), "open", "unknown")) -> unknown | K18: =IF(AND(E18<>"", E18<>"unknown"), E18, IF(AND(G18<>"", G18<>"unknown"), G18, IF(AND(H18<>"", H18<>"unknown"), H18, IF(I18<>"", I18, "ERROR")))) -> scale
A19: דמוגרפיה | B19: $D$16 | C19: יניב שפירא: 1 = yes 2 = no | E19: scale | F19: יניב שפירא: 1 = yes 2 = no | G19: =IF(EXACT($F19, $Q$1), "sector", "unknown") -> unknown | H19: =IF(EXACT(F19,$W$1), "open", IF(EXACT(F19,$X$1), "open", "unknown")) -> unknown | K19: =IF(AND(E19<>"", E19<>"unknown"), E19, IF(AND(G19<>"", G19<>"unknown"), G19, IF(AND(H19<>"", H19<>"unknown"), H19, IF(I19<>"", I19, "ERROR")))) -> scale
A20: דמוגרפיה | B20: $A$17 | C20: יניב שפירא: שאלה פתוחה | D20: יניב שפירא | E20: unknown | F20: שאלה פתוחה | G20: =IF(EXACT($F20, $Q$1), "sector", IF(EXACT($F20, $R$1), "sector", IF(EXACT($F20, $T$1), "sector", IF(EXACT($F20, $U$1), "sector", "unknown")))) -> unknown | H20: =IF(EXACT(F20,$W$1), "open", IF(EXACT(F20,$X$1), "open", "unknown")) -> open | K20: =IF(AND(E20<>"", E20<>"unknown"), E20, IF(AND(G20<>"", G20<>"unknown"), G20, IF(AND(H20<>"", H20<>"unknown"), H20, IF(I20<>"", I20, "ERROR")))) -> open
A21: דמוגרפיה | B21: $I$17 | C21: יניב שפירא: קידוד לתשובות תחת nv176 | E21: scale | F21: יניב שפירא: קידוד לתשובות תחת nv176 | G21: =IF(EXACT($F21, $Q$1), "sector", "unknown") -> unknown | H21: =IF(EXACT(F21,$W$1), "open", IF(EXACT(F21,$X$1), "open", "unknown")) -> unknown | K21: =IF(AND(E21<>"", E21<>"unknown"), E21, IF(AND(G21<>"", G21<>"unknown"), G21, IF(AND(H21<>"", H21<>"unknown"), H21, IF(I21<>"", I21, "ERROR")))) -> scale
A22: דמוגרפיה | B22: $AF$17 | C22: יניב שפירא: 1 = צבר 2 = אירופה התיכונית והמזרחית 3 = אירופה הדרומית 4 = אירופה המערבית 5 = ארצות דוברות אנגלית 6 = צפון אפריקה 7 = המזרח התיכון 8 = המזרח הרחוק 9 = דרום אמריקה | E22: scale | F22: יניב שפירא: 1 = צבר 2 = אירופה התיכונית והמזרחית 3 = אירופה הדרומית 4 = אירופה המערבית 5 = ארצות דוברות אנגלית 6 = צפון אפריקה 7 = המזרח התיכון 8 = המזרח הרחוק 9 = דרום אמריקה | G22: =IF(EXACT($F22, $Q$1), "sector", "unknown") -> unknown | H22: =IF(EXACT(F22,$W$1), "open", IF(EXACT(F22,$X$1), "open", "unknown")) -> unknown | K22: =IF(AND(E22<>"", E22<>"unknown"), E22, IF(AND(G22<>"", G22<>"unknown"), G22, IF(AND(H22<>"", H22<>"unknown"), H22, IF(I22<>"", I22, "ERROR")))) -> scale
A23: דמוגרפיה | B23: $A$18 | C23: יניב שפירא: יהודים בלבד | D23: יניב שפירא | E23: =IF(EXACT($F23, $Q$1), "sector", "unknown") -> sector | F23: יהודים בלבד | G23: =IF(EXACT($F23, $Q$1), "sector", "unknown") -> sector | H23: =IF(EXACT(F23,$W$1), "open", IF(EXACT(F23,$X$1), "open", "unknown")) -> unknown | K23: =IF(AND(E23<>"", E23<>"unknown"), E23, IF(AND(G23<>"", G23<>"unknown"), G23, IF(AND(H23<>"", H23<>"unknown"), H23, IF(I23<>"", I23, "ERROR")))) -> sector
A24: דמוגרפיה | B24: $D$18 | C24: יניב שפירא: 1 = יליד אסיה/אפריקה 2 = יליד אירופה/אמריקה 3 = יליד ברה"מ/חבר העמים 4 = יליד ישראל, אב יליד ישראל 5 = יליד ישראל, אב יליד אסיה/אפריקה 6 = יליד ישראל, אב יליד אירופה/אמריקה 7 = יליד ישראל, אב יליד בהר"מ/חבר העמים 8 = מסרב להשיב | E24: scale | F24: יניב שפירא: 1 = יליד אסיה/אפריקה 2 = יליד אירופה/אמריקה 3 = יליד ברה"מ/חבר העמים 4 = יליד ישראל, אב יליד ישראל 5 = יליד ישראל, אב יליד אסיה/אפריקה 6 = יליד ישראל, אב יליד אירופה/אמריקה 7 = יליד ישראל, אב יליד בהר"מ/חבר העמים 8 = מסרב להשיב | G24: =IF(EXACT($F24, $Q$1), "sector", "unknown") -> unknown | H24: =IF(EXACT(F24,$W$1), "open", IF(EXACT(F24,$X$1), "open", "unknown")) -> unknown | K24: =IF(AND(E24<>"", E24<>"unknown"), E24, IF(AND(G24<>"", G24<>"unknown"), G24, IF(AND(H24<>"", H24<>"unknown"), H24, IF(I24<>"", I24, "ERROR")))) -> scale
A25: דמוגרפיה | B25: $F$18 | C25: יניב שפירא: 1 = ישראל 2 = אסיה או אפריקה 3 = אירופה או אמריקה 4 = בהר"מ/חבר העמים | E25: scale | F25: יניב שפירא: 1 = ישראל 2 = אסיה או אפריקה 3 = אירופה או אמריקה 4 = בהר"מ/חבר העמים | G25: =IF(EXACT($F25, $Q$1), "sector", "unknown") -> unknown | H25: =IF(EXACT(F25,$W$1), "open", IF(EXACT(F25,$X$1), "open", "unknown")) -> unknown | K25: =IF(AND(E25<>"", E25<>"unknown"), E25, IF(AND(G25<>"", G25<>"unknown"), G25, IF(AND(H25<>"", H25<>"unknown"), H25, IF(I25<>"", I25, "ERROR")))) -> scale
A26: דמוגרפיה | B26: $L$18 | C26: יניב שפירא: 1 = צפון אפריקה 2 = אסיה 3 = מזרח אירופה 4 = מערב/מרכז אירופה 5 = אמריקה,אפריקה,אוסטרליה 6 = צבר, אב צבר 7 = צבר, אבא צפון אפריקה 8 = צבא, אבא אסיה 9 = צבר, אבא מזרח אירופה 10 = צבר, אבא מערב/מרכז אירופה 11 = צבר, אבא אמריקה,אפריקה,אוסטלריה | E26: scale | F26: יניב שפירא: 1 = צפון אפריקה 2 = אסיה 3 = מזרח אירופה 4 = מערב/מרכז אירופה 5 = אמריקה,אפריקה,אוסטרליה 6 = צבר, אב צבר 7 = צבר, אבא צפון אפריקה 8 = צבא, אבא אסיה 9 = צבר, אבא מזרח אירופה 10 = צבר, אבא מערב/מרכז אירופה 11 = צבר, אבא אמריקה,אפריקה,אוסטלריה | G26: =IF(EXACT($F26, $Q$1), "sector", "unknown") -> unknown | H26: =IF(EXACT(F26,$W$1), "open", IF(EXACT(F26,$X$1), "open", "unknown")) -> unknown | K26: =IF(AND(E26<>"", E26<>"unknown"), E26, IF(AND(G26<>"", G26<>"unknown"), G26, IF(AND(H26<>"", H26<>"unknown"), H26, IF(I26<>"", I26, "ERROR")))) -> scale
A27: דמוגרפיה | B27: $T$18 | C27: יניב שפירא: 1 = ישראל-ישראל 2 = ישראל- אסיה/אפריקה 3 = ישראל- אירופה/אמריקה 4 = אסיה/אפריקה-אסיה/אפריקה 5 = אירופה/אמריקה- אירופה/אמריקה 6 = כל צירוף אחר | E27: scale | F27: יניב שפירא: 1 = ישראל-ישראל 2 = ישראל- אסיה/אפריקה 3 = ישראל- אירופה/אמריקה 4 = אסיה/אפריקה-אסיה/אפריקה 5 = אירופה/אמריקה- אירופה/אמריקה 6 = כל צירוף אחר | G27: =IF(EXACT($F27, $Q$1), "sector", "unknown") -> unknown | H27: =IF(EXACT(F27,$W$1), "open", IF(EXACT(F27,$X$1), "open", "unknown")) -> unknown | K27: =IF(AND(E27<>"", E27<>"unknown"), E27, IF(AND(G27<>"", G27<>"unknown"), G27, IF(AND(H27<>"", H27<>"unknown"), H27, IF(I27<>"", I27, "ERROR")))) -> scale
A28: דמוגרפיה | B28: $AF$18 | C28: יניב שפירא: 1 = אסיה וצפון אפריקה 2 = אירופה ואנגלו-סכסיות 3 = ישראל והאב מאסיה צפון אפריקה 4 = ישראל והאב אירופה או האנגלו-סכסיות 5 = ישראל וגם האב ישראל | E28: scale | F28: יניב שפירא: 1 = אסיה וצפון אפריקה 2 = אירופה ואנגלו-סכסיות 3 = ישראל והאב מאסיה צפון אפריקה 4 = ישראל והאב אירופה או האנגלו-סכסיות 5 = ישראל וגם האב ישראל | G28: =IF(EXACT($F28, $Q$1), "sector", "unknown") -> unknown | H28: =IF(EXACT(F28,$W$1), "open", IF(EXACT(F28,$X$1), "open", "unknown")) -> unknown | K28: =IF(AND(E28<>"", E28<>"unknown"), E28, IF(AND(G28<>"", G28<>"unknown"), G28, IF(AND(H28<>"", H28<>"unknown"), H28, IF(I28<>"", I28, "ERROR")))) -> scale
A29: דמוגרפיה | B29: $A$19 | C29: יניב שפירא: יהודים בלבד | D29: יניב שפירא | E29: unknown | F29: יהודים בלבד | G29: =IF(EXACT($F29, $Q$1), "sector", IF(EXACT($F29, $R$1), "sector", IF(EXACT($F29, $T$1), "sector", IF(EXACT($F29, $U$1), "sector", "unknown")))) -> sector | H29: =IF(EXACT(F29,$W$1), "open", IF(EXACT(F29,$X$1), "open", "unknown")) -> unknown | K29: =IF(AND(E29<>"", E29<>"unknown"), E29, IF(AND(G29<>"", G29<>"unknown"), G29, IF(AND(H29<>"", H29<>"unknown"), H29, IF(I29<>"", I29, "ERROR")))) -> sector
A30: דמוגרפיה | B30: $Q$19 | C30: יניב שפירא: 1 = יליד הארץ 2 = לפני 1948 3 = 1948-1954 4 = 1955-1960 5 = 61-66 6 = 67-72 7 = 73-77 8 = 78-83 9 = 1984 ומעלה | E30: scale | F30: יניב שפירא: 1 = יליד הארץ 2 = לפני 1948 3 = 1948-1954 4 = 1955-1960 5 = 61-66 6 = 67-72 7 = 73-77 8 = 78-83 9 = 1984 ומעלה | G30: =IF(EXACT($F30, $Q$1), "sector", "unknown") -> unknown | H30: =IF(EXACT(F30,$W$1), "open", IF(EXACT(F30,$X$1), "open", "unknown")) -> unknown | K30: =IF(AND(E30<>"", E30<>"unknown"), E30, IF(AND(G30<>"", G30<>"unknown"), G30, IF(AND(H30<>"", H30<>"unknown"), H30, IF(I30<>"", I30, "ERROR")))) -> scale
A31: דמוגרפיה | B31: $T$19 | C31: יניב שפירא: 1 = יליד הארץ 2 = לפני 1948 3 = 1948-1954 4 = 1955-1960 5 = 61-66 6 = 67-72 7 = 73-77 8 = 78-79 9 = 1980 ואלך | E31: scale | F31: יניב שפירא: 1 = יליד הארץ 2 = לפני 1948 3 = 1948-1954 4 = 1955-1960 5 = 61-66 6 = 67-72 7 = 73-77 8 = 78-79 9 = 1980 ואלך | G31: =IF(EXACT($F31, $Q$1), "sector", "unknown") -> unknown | H31: =IF(EXACT(F31,$W$1), "open", IF(EXACT(F31,$X$1), "open", "unknown")) -> unknown | K31: =IF(AND(E31<>"", E31<>"unknown"), E31, IF(AND(G31<>"", G31<>"unknown"), G31, IF(AND(H31<>"", H31<>"unknown"), H31, IF(I31<>"", I31, "ERROR")))) -> scale
A32: דמוגרפיה | B32: $A$20 | C32: יניב שפירא: יהודים בלבד | D32: יניב שפירא | E32: unknown | F32: יהודים בלבד | G32: =IF(EXACT($F32, $Q$1), "sector", IF(EXACT($F32, $R$1), "sector", IF(EXACT($F32, $T$1), "sector", IF(EXACT($F32, $U$1), "sector", "unknown")))) -> sector | H32: =IF(EXACT(F32,$W$1), "open", IF(EXACT(F32,$X$1), "open", "unknown")) -> unknown | K32: =IF(AND(E32<>"", E32<>"unknown"), E32, IF(AND(G32<>"", G32<>"unknown"), G32, IF(AND(H32<>"", H32<>"unknown"), H32, IF(I32<>"", I32, "ERROR")))) -> sector
A33: דמוגרפיה | B33: $B$20 | C33: adi: 1 = אשכנזי 2 = ספרדי 3 = מזרחי 4 = אחר (פרט):_____ | E33: scale | F33: adi: 1 = אשכנזי 2 = ספרדי 3 = מזרחי 4 = אחר (פרט):_____ | G33: =IF(EXACT($F33, $Q$1), "sector", "unknown") -> unknown | H33: =IF(EXACT(F33,$W$1), "open", IF(EXACT(F33,$X$1), "open", "unknown")) -> unknown | K33: =IF(AND(E33<>"", E33<>"unknown"), E33, IF(AND(G33<>"", G33<>"unknown"), G33, IF(AND(H33<>"", H33<>"unknown"), H33, IF(I33<>"", I33, "ERROR")))) -> scale
A34: דמוגרפיה | B34: $D$20 | C34: יניב שפירא: 1 = אשכנזי 2 = ספרדי 3 = מזרחי 4 = אחר 5 = מעורב 6 = לא זה ולא זה, לא מגדיר את עצמי לפי מוצא עדתי | E34: scale | F34: יניב שפירא: 1 = אשכנזי 2 = ספרדי 3 = מזרחי 4 = אחר 5 = מעורב 6 = לא זה ולא זה, לא מגדיר את עצמי לפי מוצא עדתי | G34: =IF(EXACT($F34, $Q$1), "sector", "unknown") -> unknown | H34: =IF(EXACT(F34,$W$1), "open", IF(EXACT(F34,$X$1), "open", "unknown")) -> unknown | K34: =IF(AND(E34<>"", E34<>"unknown"), E34, IF(AND(G34<>"", G34<>"unknown"), G34, IF(AND(H34<>"", H34<>"unknown"), H34, IF(I34<>"", I34, "ERROR")))) -> scale
A35: דמוגרפיה | B35: $N$20 | C35: יניב שפירא: 1 = אשכנזי 2 = ספרדי 3 = לא זה ולא זה | E35: scale | F35: יניב שפירא: 1 = אשכנזי 2 = ספרדי 3 = לא זה ולא זה | G35: =IF(EXACT($F35, $Q$1), "sector", "unknown") -> unknown | H35: =IF(EXACT(F35,$W$1), "open", IF(EXACT(F35,$X$1), "open", "unknown")) -> unknown | K35: =IF(AND(E35<>"", E35<>"unknown"), E35, IF(AND(G35<>"", G35<>"unknown"), G35, IF(AND(H35<>"", H35<>"unknown"), H35, IF(I35<>"", I35, "ERROR")))) -> scale
A36: דמוגרפיה | B36: $O$20 | C36: יניב שפירא: 1 = אשכנזי 2 = ספרדי 3 = לא זה ולא זה 4 = שניהם | E36: scale | F36: יניב שפירא: 1 = אשכנזי 2 = ספרדי 3 = לא זה ולא זה 4 = שניהם | G36: =IF(EXACT($F36, $Q$1), "sector", "unknown") -> unknown | H36: =IF(EXACT(F36,$W$1), "open", IF(EXACT(F36,$X$1), "open", "unknown")) -> unknown | K36: =IF(AND(E36<>"", E36<>"unknown"), E36, IF(AND(G36<>"", G36<>"unknown"), G36, IF(AND(H36<>"", H36<>"unknown"), H36, IF(I36<>"", I36, "ERROR")))) -> scale
A37: דמוגרפיה | B37: $P$20 | C37: יניב שפירא: 1 = אשכנזי 2 = ספרדי 3 = לא זה ולא זה | E37: scale | F37: יניב שפירא: 1 = אשכנזי 2 = ספרדי 3 = לא זה ולא זה | G37: =IF(EXACT($F37, $Q$1), "sector", "unknown") -> unknown | H37: =IF(EXACT(F37,$W$1), "open", IF(EXACT(F37,$X$1), "open", "unknown")) -> unknown | K37: =IF(AND(E37<>"", E37<>"unknown"), E37, IF(AND(G37<>"", G37<>"unknown"), G37, IF(AND(H37<>"", H37<>"unknown"), H37, IF(I37<>"", I37, "ERROR")))) -> scale
A38: דמוגרפיה | B38: $Q$20 | C38: יניב שפירא: 1 = אשכנזי 2 = ספרדי 3 = לא זה ולא זה 4 = שניהם | E38: scale | F38: יניב שפירא: 1 = אשכנזי 2 = ספרדי 3 = לא זה ולא זה 4 = שניהם | G38: =IF(EXACT($F38, $Q$1), "sector", "unknown") -> unknown | H38: =IF(EXACT(F38,$W$1), "open", IF(EXACT(F38,$X$1), "open", "unknown")) -> unknown | K38: =IF(AND(E38<>"", E38<>"unknown"), E38, IF(AND(G38<>"", G38<>"unknown"), G38, IF(AND(H38<>"", H38<>"unknown"), H38, IF(I38<>"", I38, "ERROR")))) -> scale
A39: דמוגרפיה | B39: $S$20 | C39: יניב שפירא: 1 = אשכנזי 2 = ספרדי 3 = לא זה ולא זה | E39: scale | F39: יניב שפירא: 1 = אשכנזי 2 = ספרדי 3 = לא זה ולא זה | G39: =IF(EXACT($F39, $Q$1), "sector", "unknown") -> unknown | H39: =IF(EXACT(F39,$W$1), "open", IF(EXACT(F39,$X$1), "open", "unknown")) -> unknown | K39: =IF(AND(E39<>"", E39<>"unknown"), E39, IF(AND(G39<>"", G39<>"unknown"), G39, IF(AND(H39<>"", H39<>"unknown"), H39, IF(I39<>"", I39, "ERROR")))) -> scale
A40: דמוגרפיה | B40: $L$21 | C40: יניב שפירא: 1 = כן 2 = לא | E40: scale | F40: יניב שפירא: 1 = כן 2 = לא | G40: =IF(EXACT($F40, $Q$1), "sector", "unknown") -> unknown | H40: =IF(EXACT(F40,$W$1), "open", IF(EXACT(F40,$X$1), "open", "unknown")) -> unknown | K40: =IF(AND(E40<>"", E40<>"unknown"), E40, IF(AND(G40<>"", G40<>"unknown"), G40, IF(AND(H40<>"", H40<>"unknown"), H40, IF(I40<>"", I40, "ERROR")))) -> scale
...

Sheet Comment types
A1: Sheet Name | B1: Cell Address | C1: Comment | D1: finalType | E1: Content Only | F1: Question Id | G1: Survey - Index | H1: Survey - Codebook | I1: PrevCodebook | J1: cb_id_curr | K1: cb_id_prev | L1: category | M1: record | N1: columns | O1: question_title | P1: question_description | Q1: answers | R1: Affected Surveys | S1: Answers but better
A2: דמוגרפיה | B2: $L$3 | C2: יניב שפירא: 1 = ינואר 2 = פברואר | D2: scale | E2: 1 = ינואר 2 = פברואר | F2: {=INDIRECT("'" & A2 & "'!" & B2)} -> b51 | G2: {=INDIRECT("'" & A2 & "'!" & ADDRESS(1, COLUMN(INDIRECT("'" & A2 & "'!" & B2))))} -> 2001 | H2: =VLOOKUP($G2, survey_codes_dict!A:C, 2, FALSE) -> 2001 | I2: =VLOOKUP($G2, survey_codes_dict!A:D, 4, FALSE) -> 1999_1 | J2: =_xlfn.CONCAT($H2, "__", F2) -> 2001__b51 | K2: =_xlfn.CONCAT($I2, "__", F2) -> 1999_1__b51
A3: דמוגרפיה | B3: $A$5 | C3: יניב שפירא: שאלה 145 אין קידוד בstata גם ב2020 וגם ב2019 גם ב2021 | D3: scale | E3: שאלה 145 אין קידוד בstata גם ב2020 וגם ב2019 גם ב2021 | F3: {=INDIRECT("'" & A3 & "'!" & B3)} -> מקום הראיון | G3: {=INDIRECT("'" & A3 & "'!" & ADDRESS(1, COLUMN(INDIRECT("'" & A3 & "'!" & B3))))} -> שאלה | H3: =VLOOKUP($G3, survey_codes_dict!A:C, 2, FALSE) -> #N/A | I3: =VLOOKUP($G3, survey_codes_dict!A:D, 4, FALSE) -> #N/A | J3: =_xlfn.CONCAT($H3, "__", F3) -> #N/A | K3: =_xlfn.CONCAT($I3, "__", F3) -> #N/A
A4: דמוגרפיה | B4: $D$6 | C4: יניב שפירא: 1 = יהודי 2 = ערבי | D4: scale | E4: 1 = יהודי 2 = ערבי | F4: {=INDIRECT("'" & A4 & "'!" & B4)} -> sector | G4: {=INDIRECT("'" & A4 & "'!" & ADDRESS(1, COLUMN(INDIRECT("'" & A4 & "'!" & B4))))} -> 2020 | H4: =VLOOKUP($G4, survey_codes_dict!A:C, 2, FALSE) -> #N/A | I4: =VLOOKUP($G4, survey_codes_dict!A:D, 4, FALSE) -> #N/A | J4: =_xlfn.CONCAT($H4, "__", F4) -> #N/A | K4: =_xlfn.CONCAT($I4, "__", F4) -> #N/A
A5: דמוגרפיה | B5: $F$8 | C5: יניב שפירא: 1 = גרסה A 2 = גרסה B | D5: scale | E5: 1 = גרסה A 2 = גרסה B | F5: {=INDIRECT("'" & A5 & "'!" & B5)} -> version | G5: {=INDIRECT("'" & A5 & "'!" & ADDRESS(1, COLUMN(INDIRECT("'" & A5 & "'!" & B5))))} -> 43556 | H5: =VLOOKUP($G5, survey_codes_dict!A:C, 2, FALSE) -> #N/A | I5: =VLOOKUP($G5, survey_codes_dict!A:D, 4, FALSE) -> #N/A | J5: =_xlfn.CONCAT($H5, "__", F5) -> #N/A | K5: =_xlfn.CONCAT($I5, "__", F5) -> #N/A
A6: דמוגרפיה | B6: $I$8 | C6: יניב שפירא: a , b, c | D6: scale | E6: a , b, c | F6: {=INDIRECT("'" & A6 & "'!" & B6)} -> version | G6: {=INDIRECT("'" & A6 & "'!" & ADDRESS(1, COLUMN(INDIRECT("'" & A6 & "'!" & B6))))} -> 2009 | H6: =VLOOKUP($G6, survey_codes_dict!A:C, 2, FALSE) -> #N/A | I6: =VLOOKUP($G6, survey_codes_dict!A:D, 4, FALSE) -> #N/A | J6: =_xlfn.CONCAT($H6, "__", F6) -> #N/A | K6: =_xlfn.CONCAT($I6, "__", F6) -> #N/A
A7: דמוגרפיה | B7: $L$9 | C7: יניב שפירא: 1 = עברית 2 = ערבית 3 = רוסית | D7: scale | E7: 1 = עברית 2 = ערבית 3 = רוסית | F7: {=INDIRECT("'" & A7 & "'!" & B7)} -> b55 | G7: {=INDIRECT("'" & A7 & "'!" & ADDRESS(1, COLUMN(INDIRECT("'" & A7 & "'!" & B7))))} -> 2001 | H7: =VLOOKUP($G7, survey_codes_dict!A:C, 2, FALSE) -> 2001 | I7: =VLOOKUP($G7, survey_codes_dict!A:D, 4, FALSE) -> 1999_1 | J7: =_xlfn.CONCAT($H7, "__", F7) -> 2001__b55 | K7: =_xlfn.CONCAT($I7, "__", F7) -> 1999_1__b55
A8: דמוגרפיה | B8: $W$10 | C8: יניב שפירא: 1 = 20-25 2 = 25-29 3 = 30-34 4 = 35-39 5 = 40-44 6 = 45-49 7 = 50-54 8 = 55-64 9 = 65+ | D8: scale | E8: 1 = 20-25 2 = 25-29 3 = 30-34 4 = 35-39 5 = 40-44 6 = 45-49 7 = 50-54 8 = 55-64 9 = 65+ | F8: {=INDIRECT("'" & A8 & "'!" & B8)} -> c24 | G8: {=INDIRECT("'" & A8 & "'!" & ADDRESS(1, COLUMN(INDIRECT("'" & A8 & "'!" & B8))))} -> 1977 - 4 | H8: =VLOOKUP($G8, survey_codes_dict!A:C, 2, FALSE) -> 1977_4 | I8: =VLOOKUP($G8, survey_codes_dict!A:D, 4, FALSE) -> 1977_3 | J8: =_xlfn.CONCAT($H8, "__", F8) -> 1977_4__c24 | K8: =_xlfn.CONCAT($I8, "__", F8) -> 1977_3__c24
A9: דמוגרפיה | B9: $AB$10 | C9: יניב שפירא: 1 = 20-24 2 = 25-29 3 = 30-34 4 = 35-39 5 = 40-44 6 = 45-49 7 = 50-54 8 = 55-64 9 = 65+ | D9: scale | E9: 1 = 20-24 2 = 25-29 3 = 30-34 4 = 35-39 5 = 40-44 6 = 45-49 7 = 50-54 8 = 55-64 9 = 65+ | F9: {=INDIRECT("'" & A9 & "'!" & B9)} -> g62 | G9: {=INDIRECT("'" & A9 & "'!" & ADDRESS(1, COLUMN(INDIRECT("'" & A9 & "'!" & B9))))} -> 1973 - 4 | H9: =VLOOKUP($G9, survey_codes_dict!A:C, 2, FALSE) -> 1973_4 | I9: =VLOOKUP($G9, survey_codes_dict!A:D, 4, FALSE) -> 1973_3 | J9: =_xlfn.CONCAT($H9, "__", F9) -> 1973_4__g62 | K9: =_xlfn.CONCAT($I9, "__", F9) -> 1973_3__g62
A10: דמוגרפיה | B10: $AH$10 | C10: יניב שפירא: 1 = 18-24 2 = 25-29 3 = 30-34 4 = 35-39 5 = 40-44 6 = 45-49 7 = 50-54 8 = 55-64 9 = 65+ | D10: scale | E10: 1 = 18-24 2 = 25-29 3 = 30-34 4 = 35-39 5 = 40-44 6 = 45-49 7 = 50-54 8 = 55-64 9 = 65+ | F10: {=INDIRECT("'" & A10 & "'!" & B10)} -> c79 | G10: {=INDIRECT("'" & A10 & "'!" & ADDRESS(1, COLUMN(INDIRECT("'" & A10 & "'!" & B10))))} -> 1969 - 1 | H10: =VLOOKUP($G10, survey_codes_dict!A:C, 2, FALSE) -> 1969_1 | I10: =VLOOKUP($G10, survey_codes_dict!A:D, 4, FALSE) -> 0 | J10: =_xlfn.CONCAT($H10, "__", F10) -> 1969_1__c79 | K10: =_xlfn.CONCAT($I10, "__", F10) -> 0__c79
A11: דמוגרפיה | B11: $D$12 | C11: יניב שפירא: 1 = 18-22 2 = 23-29 3 = 30-39 4 = 40-49 5 = 50-59 6 = 60-69 7 = 70-79 8 = 80 ומעלה | D11: scale | E11: 1 = 18-22 2 = 23-29 3 = 30-39 4 = 40-49 5 = 50-59 6 = 60-69 7 = 70-79 8 = 80 ומעלה | F11: {=INDIRECT("'" & A11 & "'!" & B11)} -> agegroup | G11: {=INDIRECT("'" & A11 & "'!" & ADDRESS(1, COLUMN(INDIRECT("'" & A11 & "'!" & B11))))} -> 2020 | H11: =VLOOKUP($G11, survey_codes_dict!A:C, 2, FALSE) -> #N/A | I11: =VLOOKUP($G11, survey_codes_dict!A:D, 4, FALSE) -> #N/A | J11: =_xlfn.CONCAT($H11, "__", F11) -> #N/A | K11: =_xlfn.CONCAT($I11, "__", F11) -> #N/A
A12: דמוגרפיה | B12: $D$13 | C12: יניב שפירא: 1 = male 2 = female | D12: scale | E12: 1 = male 2 = female | F12: {=INDIRECT("'" & A12 & "'!" & B12)} -> gender | G12: {=INDIRECT("'" & A12 & "'!" & ADDRESS(1, COLUMN(INDIRECT("'" & A12 & "'!" & B12))))} -> 2020 | H12: =VLOOKUP($G12, survey_codes_dict!A:C, 2, FALSE) -> #N/A | I12: =VLOOKUP($G12, survey_codes_dict!A:D, 4, FALSE) -> #N/A | J12: =_xlfn.CONCAT($H12, "__", F12) -> #N/A | K12: =_xlfn.CONCAT($I12, "__", F12) -> #N/A
A13: דמוגרפיה | B13: $M$13 | C13: יניב שפירא: 1 = אישה 2 = גבר | D13: scale | E13: 1 = אישה 2 = גבר | F13: {=INDIRECT("'" & A13 & "'!" & B13)} -> c39 | G13: {=INDIRECT("'" & A13 & "'!" & ADDRESS(1, COLUMN(INDIRECT("'" & A13 & "'!" & B13))))} -> 1999 | H13: =VLOOKUP($G13, survey_codes_dict!A:C, 2, FALSE) -> 1999_1 | I13: =VLOOKUP($G13, survey_codes_dict!A:D, 4, FALSE) -> 1996_Jews | J13: =_xlfn.CONCAT($H13, "__", F13) -> 1999_1__c39 | K13: =_xlfn.CONCAT($I13, "__", F13) -> 1996_Jews__c39
... A1403: תקשורת | B1403: $AF$94 | C1403: יניב שפירא: 1 = שידורים שבהם מופיע מנהיג פוליטי ומציג את עמדת המפלגה 2 = שידור שבו מוצג סרט מחיי הארץ המציג את עמדת המפלגה 3 = אחר | D1403: scale | E1403: 1 = שידורים שבהם מופיע מנהיג פוליטי ומציג את עמדת המפלגה 2 = שידור שבו מוצג סרט מחיי הארץ המציג את עמדת המפלגה 3 = אחר | F1403: {=INDIRECT("'" & A1403 & "'!" & B1403)} -> b39 | G1403: {=INDIRECT("'" & A1403 & "'!" & ADDRESS(1, COLUMN(INDIRECT("'" & A1403 & "'!" & B1403))))} -> 1969 - 3 | H1403: =VLOOKUP($G1403, survey_codes_dict!A:C, 2, FALSE) -> #N/A | I1403: =VLOOKUP($G1403, survey_codes_dict!A:D, 4, FALSE) -> #N/A | J1403: =_xlfn.CONCAT($H1403, "__", F1403) -> #N/A | K1403: =_xlfn.CONCAT($I1403, "__", F1403) -> #N/A
A1404: תקשורת | B1404: $AG$95 | C1404: יניב שפירא: | D1404: blank | F1404: {=INDIRECT("'" & A1404 & "'!" & B1404)} -> a9 | G1404: {=INDIRECT("'" & A1404 & "'!" & ADDRESS(1, COLUMN(INDIRECT("'" & A1404 & "'!" & B1404))))} -> 1969 - 2 | H1404: =VLOOKUP($G1404, survey_codes_dict!A:C, 2, FALSE) -> 1969_2 | I1404: =VLOOKUP($G1404, survey_codes_dict!A:D, 4, FALSE) -> 1969_1 | J1404: =_xlfn.CONCAT($H1404, "__", F1404) -> 1969_2__a9 | K1404: =_xlfn.CONCAT($I1404, "__", F1404) -> 1969_1__a9
A1405: תקשורת | B1405: $AH$96 | C1405: יניב שפירא: 1 = כל יום 2 = כמה פעמים בשבוע 3 = פעם בשבוע 4 = לעיתים רחוקות יותר 5 = לא קורא | D1405: scale | E1405: 1 = כל יום 2 = כמה פעמים בשבוע 3 = פעם בשבוע 4 = לעיתים רחוקות יותר 5 = לא קורא | F1405: {=INDIRECT("'" & A1405 & "'!" & B1405)} -> a17 | G1405: {=INDIRECT("'" & A1405 & "'!" & ADDRESS(1, COLUMN(INDIRECT("'" & A1405 & "'!" & B1405))))} -> 1969 - 1 | H1405: =VLOOKUP($G1405, survey_codes_dict!A:C, 2, FALSE) -> 1969_1 | I1405: =VLOOKUP($G1405, survey_codes_dict!A:D, 4, FALSE) -> 0 | J1405: =_xlfn.CONCAT($H1405, "__", F1405) -> 1969_1__a17 | K1405: =_xlfn.CONCAT($I1405, "__", F1405) -> 0__a17
A1406: תקשורת | B1406: $AH$109 | C1406: יניב שפירא: 1 = בדר"כ כן 2 = לפעמים כן לפעמים לא 3 = בדר"כ לא 4 = לא מקבל אינפורמציה | D1406: scale | E1406: 1 = בדר"כ כן 2 = לפעמים כן לפעמים לא 3 = בדר"כ לא 4 = לא מקבל אינפורמציה | F1406: {=INDIRECT("'" & A1406 & "'!" & B1406)} -> a89 | G1406: {=INDIRECT("'" & A1406 & "'!" & ADDRESS(1, COLUMN(INDIRECT("'" & A1406 & "'!" & B1406))))} -> 1969 - 1 | H1406: =VLOOKUP($G1406, survey_codes_dict!A:C, 2, FALSE) -> 1969_1 | I1406: =VLOOKUP($G1406, survey_codes_dict!A:D, 4, FALSE) -> 0 | J1406: =_xlfn.CONCAT($H1406, "__", F1406) -> 1969_1__a89 | K1406: =_xlfn.CONCAT($I1406, "__", F1406) -> 0__a89
A1407: תקשורת | B1407: $AH$110 | C1407: יניב שפירא: 1 = בדר"כ כן 2 = לפעמים כן לפעמים לא 3 = בדר"כ לא 4 = לא מקבל אינפורמציה | D1407: scale | E1407: 1 = בדר"כ כן 2 = לפעמים כן לפעמים לא 3 = בדר"כ לא 4 = לא מקבל אינפורמציה | F1407: {=INDIRECT("'" & A1407 & "'!" & B1407)} -> a91 | G1407: {=INDIRECT("'" & A1407 & "'!" & ADDRESS(1, COLUMN(INDIRECT("'" & A1407 & "'!" & B1407))))} -> 1969 - 1 | H1407: =VLOOKUP($G1407, survey_codes_dict!A:C, 2, FALSE) -> 1969_1 | I1407: =VLOOKUP($G1407, survey_codes_dict!A:D, 4, FALSE) -> 0 | J1407: =_xlfn.CONCAT($H1407, "__", F1407) -> 1969_1__a91 | K1407: =_xlfn.CONCAT($I1407, "__", F1407) -> 0__a91
A1408: ידע כללי | B1408: $D$2 | C1408: יניב שפירא: 1 = תשובה נכונה 2 = תשובה לא נכונה 3 = לא יודע | D1408: scale | E1408: 1 = תשובה נכונה 2 = תשובה לא נכונה 3 = לא יודע | F1408: {=INDIRECT("'" & A1408 & "'!" & B1408)} -> v73 | G1408: {=INDIRECT("'" & A1408 & "'!" & ADDRESS(1, COLUMN(INDIRECT("'" & A1408 & "'!" & B1408))))} -> 2020 | H1408: =VLOOKUP($G1408, survey_codes_dict!A:C, 2, FALSE) -> #N/A | I1408: =VLOOKUP($G1408, survey_codes_dict!A:D, 4, FALSE) -> #N/A | J1408: =_xlfn.CONCAT($H1408, "__", F1408) -> #N/A | K1408: =_xlfn.CONCAT($I1408, "__", F1408) -> #N/A
A1409: ידע כללי | B1409: $D$3 | C1409: יניב שפירא: 1 = תשובה נכונה (אסתר חיות) 2 = תשובה לא נכונה 3 = לא יודע | D1409: scale | E1409: 1 = תשובה נכונה (אסתר חיות) 2 = תשובה לא נכונה 3 = לא יודע | F1409: {=INDIRECT("'" & A1409 & "'!" & B1409)} -> v510 | G1409: {=INDIRECT("'" & A1409 & "'!" & ADDRESS(1, COLUMN(INDIRECT("'" & A1409 & "'!" & B1409))))} -> 2020 | H1409: =VLOOKUP($G1409, survey_codes_dict!A:C, 2, FALSE) -> #N/A | I1409: =VLOOKUP($G1409, survey_codes_dict!A:D, 4, FALSE) -> #N/A | J1409: =_xlfn.CONCAT($H1409, "__", F1409) -> #N/A | K1409: =_xlfn.CONCAT($I1409, "__", F1409) -> #N/A
A1410: ידע כללי | B1410: $D$4 | C1410: יניב שפירא: 1 = לא יודע 2 = בינוי ושיכון 3 = בריאות 4 = חינוך 5 = תחבורה | D1410: scale | E1410: 1 = לא יודע 2 = בינוי ושיכון 3 = בריאות 4 = חינוך 5 = תחבורה | F1410: {=INDIRECT("'" & A1410 & "'!" & B1410)} -> v511 | G1410: {=INDIRECT("'" & A1410 & "'!" & ADDRESS(1, COLUMN(INDIRECT("'" & A1410 & "'!" & B1410))))} -> 2020 | H1410: =VLOOKUP($G1410, survey_codes_dict!A:C, 2, FALSE) -> #N/A | I1410: =VLOOKUP($G1410, survey_codes_dict!A:D, 4, FALSE) -> #N/A | J1410: =_xlfn.CONCAT($H1410, "__", F1410) -> #N/A | K1410: =_xlfn.CONCAT($I1410, "__", F1410) -> #N/A
A1411: ידע כללי | B1411: $F$5 | C1411: יניב שפירא: 1 = יולי אדלשטיין 2 = תשובה לא נכונה 3 = לא יודע | D1411: scale | E1411: 1 = יולי אדלשטיין 2 = תשובה לא נכונה 3 = לא יודע | F1411: {=INDIRECT("'" & A1411 & "'!" & B1411)} -> v112 | G1411: {=INDIRECT("'" & A1411 & "'!" & ADDRESS(1, COLUMN(INDIRECT("'" & A1411 & "'!" & B1411))))} -> 43556 | H1411: =VLOOKUP($G1411, survey_codes_dict!A:C, 2, FALSE) -> #N/A | I1411: =VLOOKUP($G1411, survey_codes_dict!A:D, 4, FALSE) -> #N/A | J1411: =_xlfn.CONCAT($H1411, "__", F1411) -> #N/A | K1411: =_xlfn.CONCAT($I1411, "__", F1411) -> #N/A
A1412: ידע כללי | B1412: $G$5 | C1412: יניב שפירא: 1 = יולי אדלשטיין 2 = לא נכון 8 = לא יודע | D1412: scale | E1412: 1 = יולי אדלשטיין 2 = לא נכון 8 = לא יודע | F1412: {=INDIRECT("'" & A1412 & "'!" & B1412)} -> v110 | G1412: {=INDIRECT("'" & A1412 & "'!" & ADDRESS(1, COLUMN(INDIRECT("'" & A1412 & "'!" & B1412))))} -> 2015 | H1412: =VLOOKUP($G1412, survey_codes_dict!A:C, 2, FALSE) -> #N/A | I1412: =VLOOKUP($G1412, survey_codes_dict!A:D, 4, FALSE) -> #N/A | J1412: =_xlfn.CONCAT($H1412, "__", F1412) -> #N/A | K1412: =_xlfn.CONCAT($I1412, "__", F1412) -> #N/A
A1413: ידע כללי | B1413: $F$6 | C1413: יניב שפירא: 1 = לא יודע 2 = ברזיל 3 = סעודיה 4 = צפון קוריאה 5 = צ'אד (תשובה נכונה) | D1413: scale | E1413: 1 = לא יודע 2 = ברזיל 3 = סעודיה 4 = צפון קוריאה 5 = צ'אד (תשובה נכונה) | F1413: {=INDIRECT("'" & A1413 & "'!" & B1413)} -> v113 | G1413: {=INDIRECT("'" & A1413 & "'!" & ADDRESS(1, COLUMN(INDIRECT("'" & A1413 & "'!" & B1413))))} -> 43556 | H1413: =VLOOKUP($G1413, survey_codes_dict!A:C, 2, FALSE) -> #N/A | I1413: =VLOOKUP($G1413, survey_codes_dict!A:D, 4, FALSE) -> #N/A | J1413: =_xlfn.CONCAT($H1413, "__", F1413) -> #N/A | K1413: =_xlfn.CONCAT($I1413, "__", F1413) -> #N/A
A1414: ידע כללי | B1414: $G$7 | C1414: יניב שפירא: 1 = פחות מ10% 2 = בין 10% ל40% 3 = בין 40% ל75% 4 = יותר מ75% 8 = לא יודע | D1414: scale | E1414: 1 = פחות מ10% 2 = בין 10% ל40% 3 = בין 40% ל75% 4 = יותר מ75% 8 = לא יודע | F1414: {=INDIRECT("'" & A1414 & "'!" & B1414)} -> v109 | G1414: {=INDIRECT("'" & A1414 & "'!" & ADDRESS(1, COLUMN(INDIRECT("'" & A1414 & "'!" & B1414))))} -> 2015 | H1414: =VLOOKUP($G1414, survey_codes_dict!A:C, 2, FALSE) -> #N/A | I1414: =VLOOKUP($G1414, survey_codes_dict!A:D, 4, FALSE) -> #N/A | J1414: =_xlfn.CONCAT($H1414, "__", F1414) -> #N/A | K1414: =_xlfn.CONCAT($I1414, "__", F1414) -> #N/A
A1415: ידע כללי | B1415: $P$8 | C1415: יניב שפירא: 1 = ישראל 2 = צרפת 3 = ארה"ב 4 = בריטניה | D1415: scale | E1415: 1 = ישראל 2 = צרפת 3 = ארה"ב 4 = בריטניה | F1415: {=INDIRECT("'" & A1415 & "'!" & B1415)} -> a25 | G1415: {=INDIRECT("'" & A1415 & "'!" & ADDRESS(1, COLUMN(INDIRECT("'" & A1415 & "'!" & B1415))))} -> 1987* | H1415: =VLOOKUP($G1415, survey_codes_dict!A:C, 2, FALSE) -> #N/A | I1415: =VLOOKUP($G1415, survey_codes_dict!A:D, 4, FALSE) -> #N/A | J1415: =_xlfn.CONCAT($H1415, "__", F1415) -> #N/A | K1415: =_xlfn.CONCAT($I1415, "__", F1415) -> #N/A
A1416: ידע כללי | B1416: $P$9 | C1416: יניב שפירא: 1 = פחות ממיליארד דולר בשנה 2 = בין 1-2 מיליארד דולר בשנה 3 = בין 3-5 מיליארד דולר בשנה 4 = יותר מ-5 מיליארד דולר בשנה | D1416: scale | E1416: 1 = פחות ממיליארד דולר בשנה 2 = בין 1-2 מיליארד דולר בשנה 3 = בין 3-5 מיליארד דולר בשנה 4 = יותר מ-5 מיליארד דולר בשנה | F1416: {=INDIRECT("'" & A1416 & "'!" & B1416)} -> a26 | G1416: {=INDIRECT("'" & A1416 & "'!" & ADDRESS(1, COLUMN(INDIRECT("'" & A1416 & "'!" & B1416))))} -> 1987* | H1416: =VLOOKUP($G1416, survey_codes_dict!A:C, 2, FALSE) -> #N/A | I1416: =VLOOKUP($G1416, survey_codes_dict!A:D, 4, FALSE) -> #N/A | J1416: =_xlfn.CONCAT($H1416, "__", F1416) -> #N/A | K1416: =_xlfn.CONCAT($I1416, "__", F1416) -> #N/A
... A1472: ערבים בלבד | B1472: $C$16 | C1472: יניב שפירא: 1 = מאד מסכים 2 = די מסכים 3 = לא כ"כ מסכים 4 = לא מסכים כלל | D1472: scale | E1472: 1 = מאד מסכים 2 = די מסכים 3 = לא כ"כ מסכים 4 = לא מסכים כלל | F1472: {=INDIRECT("'" & A1472 & "'!" & B1472)} -> v605 | G1472: {=INDIRECT("'" & A1472 & "'!" & ADDRESS(1, COLUMN(INDIRECT("'" & A1472 & "'!" & B1472))))} -> 2021 | H1472: =VLOOKUP($G1472, survey_codes_dict!A:C, 2, FALSE) -> #N/A | I1472: =VLOOKUP($G1472, survey_codes_dict!A:D, 4, FALSE) -> #N/A | J1472: =_xlfn.CONCAT($H1472, "__", F1472) -> #N/A | K1472: =_xlfn.CONCAT($I1472, "__", F1472) -> #N/A

Sheet survey_codes_dict
A1: INDEX | B1: CODEBOOK | C1: INDEX-MISSING | D1: PrevCodebook | J1: WXL_SURVEY_ID | K1: DTA_SURVEY_ID | L1: year | M1: iteration | N1: SERIAL_NUM
A2: 1969 - 1 | B2: 1969_1 | J2: 1969 - 1 | K2: 1969-1 | L2: 1969 - 1 | M2: 1 | N2: 1
A3: 1969 - 2 | B3: 1969_2 | D3: 1969_1 | J3: 1969 - 2 | K3: 1969-2 | L3: 1969 - 2 | M3: 2 | N3: 2
A4: 1973 - 1 | B4: 1973_1 | D4: 1969_2 | J4: 1969 - 3 | K4: 1969-3 | L4: 1969 - 3 | M4: 3 | N4: 3
A5: 1973 - 2 | B5: 1973_2 | D5: 1973_1 | J5: 1973 - 1 | K5: 1973-1 | L5: 1973 - 1 | M5: 1 | N5: 4
A6: 1973 - 3 | B6: 1973_3 | D6: 1973_2 | J6: 1973 - 2 | K6: 1973-2 | L6: 1973 - 2 | M6: 2 | N6: 5
A7: 1973 - 4 | B7: 1973_4 | D7: 1973_3 | J7: 1973 - 3 | K7: 1973-3 | L7: 1973 - 3 | M7: 3 | N7: 6
A8: 1973 - 5 | B8: 1973_5 | D8: 1973_4 | J8: 1973 - 4 | K8: 1973-4 | L8: 1973 - 4 | M8: 4 | N8: 7
A9: 1977 - 1 | B9: 1977_1 | D9: 1973_5 | J9: 1973 - 5 | K9: 1973-5 | L9: 1973 - 5 | M9: 5 | N9: 8
A10: 1977 - 2 | B10: 1977_2 | D10: 1977_1 | J10: 1977 - 1 | K10: 1977-1 | L10: 1977 - 1 | M10: 1 | N10: 9
A11: 1977 - 3 | B11: 1977_3 | D11: 1977_2 | J11: 1977 - 2 | K11: 1977-2 | L11: 1977 - 2 | M11: 2 | N11: 10
A12: 1977 - 4 | B12: 1977_4 | D12: 1977_3 | J12: 1977 - 3 | K12: 1977-3 | L12: 1977 - 3 | M12: 3 | N12: 11
A13: 1981 - 1 | B13: 1981_1 | D13: 1977_4 | J13: 1977 - 4 | K13: 1977-4 | L13: 1977 - 4 | M13: 4 | N13: 12
A14: 1981 - 2 | D14: 1981_1 | J14: 1981 - 1 | K14: 1981-1 | L14: 1981 - 1 | M14: 1 | N14: 13
A15: 1981 - 3 | B15: 1981_3 | J15: 1981 - 2 | L15: 1981 - 2 | M15: 2 | N15: 14
A16: 1984 | B16: 1984 | D16: 1981_3 | J16: 1981 - 3 | K16: 1981-3 | L16: 1981 - 3 | M16: 3 | N16: 15
A17: 1988 | B17: 1988_Panel_N=416 | D17: 1984 | J17: 1984 | K17: 1984 | L17: 1984 | N17: 16
A18: 1988* | B18: 1988_N=873 | D18: 1988_Panel_N=416 | J18: 1987* | L18: 1987* | M18: 1 | N18: 17
A19: 1992 | B19: 1992 | D19: 1988_N=873 | J19: 1988 | K19: 1988_Panel_N=416 | L19: 1988 | M19: 2 | N19: 18
A20: 1996 | B20: 1996_Jews | D20: 1992 | J20: 1988* | K20: 1988_N=873 | L20: 1988* | M20: 2 | N20: 19
A21: 1999 | B21: 1999_1 | D21: 1996_Jews | J21: 1992 | K21: 1992 | L21: 1992 | N21: 20
A22: 2001 | B22: 2001 | D22: 1999_1 | J22: 1996 | K22: 1996j | L22: 1996 | N22: 21
A23: 2003 | B23: 2003 | D23: 2001 | J23: 1999 | K23: 1999-1 | L23: 1999 | N23: 22
A24: 2006 | B24: 2006 | D24: 2003 | J24: 2001 | K24: 2001 | L24: 2001 | N24: 23
C25: שאלה | J25: 2003 | K25: 2003 | L25: 2003 | N25: 24
C26: 1969 - 3 | J26: 2006 | K26: 2006 | L26: 2006 | N26: 25
C27: 1987* | J27: 2009 | K27: 2009 | L27: 2009 | N27: 26
C28: 2009 | J28: 2013 | K28: 2013 | L28: 2013 | N28: 27
C29: 2013 | J29: 2015 | K29: 2015 | L29: 2015 | N29: 28
C30: 2015 | J30: 43556 | K30: Apr-Sep_2019_update_STATA | L30: 43556 | M30: 1 | N30: 29
C31: 43556 | H31: 43556 | J31: 43709 | K31: Apr-Sep_2019_update_STATA | L31: 43709 | M31: 2 | N31: 30
C32: 43709 | H32: 43709 | J32: 2020 | K32: March_2020_data | L32: 2020 | M32: 3 | N32: 31
C33: 2020 | J33: 2021 | K33: March_2021_data_website_STATA | L33: 2021 | M33: 4 | N33: 32
C34: 2021 | J34: 2022 | K34: 2022_STATA | L34: 2022 | N34: 33
C35: 2022

Sheet דמוגרפיה
A1: שאלה | B1: 2022 | C1: 2021 | D1: 2020 | E1: 43709 | F1: 43556 | G1: 2015 | H1: 2013 | I1: 2009 | J1: 2006 | K1: 2003 | L1: 2001 | M1: 1999 | N1: 1996 | O1: 1992 | P1: 1987* | Q1: 1988* | R1: 1988 | S1: 1984 | T1: 1981 - 3 | U1: 1981 - 2 | V1: 1981 - 1 | W1: 1977 - 4 | X1: 1977 - 3 | Y1: 1977 - 2 | Z1: 1977 - 1 | AA1: 1973 - 5 | AB1: 1973 - 4 | AC1: 1973 - 3 | AD1: 1973 - 2 | AE1: 1973 - 1 | AF1: 1969 - 3 | AG1: 1969 - 2 | AH1: 1969 - 1 | AJ1: מספר חזרות | AL1: ספירה 84-19 | AN1: סה"כ מעל שתי חזרות
A2: ID | B2: ID | C2: resp_id | D2: id | E2: c_resp_id_~e | F2: resp_id | G2: ID | H2: id | J2: caseid | K2: id1 | L2: a1 | M2: v1 | O2: a1 | P2: v1 | S2: v1 | T2: v1 | U2: v1 | V2: v1 | W2: v1 | X2: v1 | Y2: v1 | Z2: v1 | AA2: v1 | AB2: v1 | AC2: v1 | AD2: v1 | AE2: v1 | AF2: b2 | AG2: a2 | AH2: a1 | AJ2: =COUNTA(B2:AH2) -> 29 | AL2: =COUNTA(F2:O2,R2:S2) -> 9 | AN2: =COUNTIF(AL2:AL87,">=2") -> 43
A3: תאריך | B3: date | C3: date | D3: date | E3: c_date_before | F3: date | G3: date | H3: date | L3: b51 | M3: c41 | N3: cccc26 | O3: i70 | Q3: c66 | R3: g91 | U3: a161 | Z3: v3 | AA3: h66 | AB3: g68 | AF3: c60 | AG3: d32 | AJ3: =COUNTA(B3:AH3) -> 19 | AL3: =COUNTA(F3:O3,R3:S3) -> 8
A4: תאריך פוסט בחירות | B4: date_after | C4: date_after | D4: date_after | E4: d_date_after | F4: date_after | G4: after_date | H4: a_date | AJ4: =COUNTA(B4:AH4) -> 7 | AL4: =COUNTA(F4:O4,R4:S4) -> 3
A5: מקום הראיון | G5: v146 | H5: v151 | I5: v193 | J5: c90 | K5: b93 | L5: b48 | M5: c40 | N5: cccc28 | O5: i68 | Q5: c64 | R5: g87 | S5: a65 | T5: b159 | U5: a160 | V5: v151 | Z5: v2 | AA5: h65 | AB5: g67 | AF5: c57 | AG5: d29 | AJ5: =COUNTA(B5:AH5) -> 20 | AL5: =COUNTA(F5:O5,R5:S5) -> 11
A6: סקטור | B6: sector | C6: sector | D6: sector | E6: c149 | F6: v149 | G6: v148 | H6: v153 | I6: v195 | M6: cccc41 | AJ6: =COUNTA(B6:AH6) -> 9 | AL6: =COUNTA(F6:O6,R6:S6) -> 5
A7: פאנל | I7: panel | Q7: c67 | R7: g93 | AJ7: =COUNTA(B7:AH7) -> 3 | AL7: =COUNTA(F7:O7,R7:S7) -> 2
A8: גרסה | B8: VERSION | E8: girsa_c | F8: version | G8: version | H8: version | I8: version | J8: c94 | K8: b99 | AJ8: =COUNTA(B8:AH8) -> 8 | AL8: =COUNTA(F8:O8,R8:S8) -> 6
A9: שפה | B9: LANGUAGE | L9: b55 | AJ9: =COUNTA(B9:AH9) -> 2 | AL9: =COUNTA(F9:O9,R9:S9) -> 1
A10: גיל | B10: age | C10: age | D10: age | F10: age | G10: age | H10: age | I10: age_1 | J10: c54 | K10: b74 | L10: b24 | M10: c20 | N10: ccc57 | O10: i61 | P10: a95 | Q10: c57 | R10: g78 | S10: a54 | T10: b137 | U10: a151 | V10: v134 | W10: c24 | X10: b17 | Y10: a17 | Z10: v116 | AA10: h60 | AB10: g62 | AC10: f54 | AD10: e17 | AE10: b25 | AF10: c30 | AG10: d11 | AH10: c79 | AJ10: =COUNTA(B10:AH10) -> 32 | AL10: =COUNTA(F10:O10,R10:S10) -> 12
A11: עדה | N11: sephashk | AJ11: =COUNTA(B11:AH11) -> 1 | AL11: =COUNTA(F11:O11,R11:S11) -> 1
A12: לאיזו קבוצת גיל אתה משתייך? | B12: age_group | C12: agegroup | D12: agegroup | F12: agegroup | G12: agegroup | H12: age_group | I12: agegroup_1 | AJ12: =COUNTA(B12:AH12) -> 7 | AL12: =COUNTA(F12:O12,R12:S12) -> 4
A13: מגדר | B13: sex | C13: gender | D13: gender | F13: gender | G13: sex | H13: sex | I13: sex_1 | J13: c89 | K13: b92 | L13: b47 | M13: c39 | N13: ccc56 | O13: i67 | P13: a119 | R13: g104 | S13: a58 | T13: b138 | U13: a146 | V13: v135 | W13: c19 | X13: b12 | Y13: a12 | Z13: v111 | AA13: h57 | AB13: g59 | AC13: f52 | AD13: e16 | AE13: b23 | AF13: c29 | AG13: d4 | AH13: c71 | AJ13: =COUNTA(B13:AH13) -> 31 | AL13: =COUNTA(F13:O13,R13:S13) -> 12
A14: מהי השכלתך? | B14: educ | C14: educ | D14: educ | F14: educ | G14: v128 | H14: v137 | AJ14: =COUNTA(B14:AH14) -> 6 | AL14: =COUNTA(F14:O14,R14:S14) -> 3
A15: כמה שנים למדת במסגרת מסודרת? | G15: v127 | H15: v136 | I15: v181_1 | J15: c75 | K15: b82 | L15: b38 | M15: c28 | N15: ccc63 | O15: i62 | P15: a99 | Q15: c58 | R15: g80 | S15: a53 | T15: b139 | U15: a147 | V15: v136 | W15: c20 | X15: b13 | Y15: a13 | Z15: v112 | AA15: h59 | AB15: g61 | AC15: f53 | AE15: b26 | AF15: c32 | AG15: d16 | AH15: c85 | AJ15: =COUNTA(B15:AH15) -> 27 | AL15: =COUNTA(F15:O15,R15:S15) -> 11
A16: האם אתה אזרח ישראלי? | B16: CITIZEN | D16: v5 | F16: v5 | G16: v5 | H16: v5 | I16: v5 | AJ16: =COUNTA(B16:AH16) -> 6 | AL16: =COUNTA(F16:O16,R16:S16) -> 4
A17: באיזו ארץ נולדת? | G17: v115 | I17: v176 | J17: c57 | AF17: c43 | AG17: d5 | AH17: c73 | AJ17: =COUNTA(B17:AH17) -> 6 | AL17: =COUNTA(F17:O17,R17:S17) -> 3
A18: ארץ לידה/מוצא אב | B18: v513 | C18: v513 | D18: v513 | F18: v131 | G18: v117 | H18: v133 | K18: b77 | L18: b33 | M18: c26 | N18: ccc59 | O18: i52 | P18: a97 | Q18: c48 | R18: g68 | S18: a49 | T18: b140 | U18: a157 | V18: v137 | W18: a29 | X18: b22 | Y18: a22 | Z18: v123 | AA18: h64 | AB18: g66 | AC18: f58 | AD18: e19 | AE18: b38 | AF18: c45 | AG18: d8 | AH18: c76 | AJ18: =COUNTA(B18:AH18) -> 30 | AL18: =COUNTA(F18:O18,R18:S18) -> 10
A19: אם לא נולד בארץ, באיזו שנה עלית ארצה? | B19: v134 | C19: v134 | D19: v134 | F19: v134 | G19: v118 | H19: v134 | I19: v177 | J19: c60 | K19: b79 | L19: b35 | M19: c27 | N19: ccc61 | O19: i53 | P19: a98 | Q19: c49 | R19: g70 | S19: a50 | T19: b141 | U19: a158 | V19: v138 | W19: c30 | X19: b23 | Y19: a23 | Z19: v124 | AE19: b39 | AF19: c48 | AG19: d15 | AH19: c84 | AJ19: =COUNTA(B19:AH19) -> 28 | AL19: =COUNTA(F19:O19,R19:S19) -> 12
A20: כיצד היית מגדיר את עצמך? (עדה) | B20: v131 | D20: v135 | F20: v135 | G20: v120 | N20: ccc55 | O20: i51 | P20: a96 | Q20: c47 | R20: g67 | S20: a47 | AJ20: =COUNTA(B20:AH20) -> 10 | AL20: =COUNTA(F20:O20,R20:S20) -> 6
A21: האם נולדת באחת מארצות ברה"מ ועלית ארצה אחרי 1988? | L21: b37 | AJ21: =COUNTA(B21:AH21) -> 1 | AL21: =COUNTA(F21:O21,R21:S21) -> 1
A22: איזה מבין המונחים הבאים מגדיר בצורה הטובה ביותר את זהותך? | B22: v707a | I22: v164 | J22: c43 | L22: b29 | M22: c22 | N22: ccc47 | AJ22: =COUNTA(B22:AH22) -> 6 | AL22: =COUNTA(F22:O22,R22:S22) -> 5
A23: והשני? | B23: v707b | I23: v165 | J23: c44 | L23: b30 | M23: c23 | N23: ccc48 | AJ23: =COUNTA(B23:AH23) -> 6 | AL23: =COUNTA(F23:O23,R23:S23) -> 5
A24: והשלישי? | B24: v707c | I24: v166 | J24: c45 | L24: b31 | M24: c24 | N24: ccc49 | AJ24: =COUNTA(B24:AH24) -> 6 | AL24: =COUNTA(F24:O24,R24:S24) -> 5
A25: והרביעי? | I25: v167 | J25: c46 | L25: b32 | M25: c25 | N25: ccc50 | AJ25: =COUNTA(B25:AH25) -> 5 | AL25: =COUNTA(F25:O25,R25:S25) -> 5
A26: האם למדת את לימודייך התיכוניים או העל-תיכוניים במסגרת דתית כלשהי? | B26: v137 | C26: v137 | D26: v137 | F26: v137 | G26: v129 | H26: v138 | AJ26: =COUNTA(B26:AH26) -> 6 | AL26: =COUNTA(F26:O26,R26:S26) -> 3
A27: ההוצאה החודשית הממוצעת של משפחה בישראל היא כ-16,500 ₪. בהתחשב בכל ההוצאות של משפחתכם, האם אתם מוציאים: | B27: v139 | C27: v139 | D27: v139 | F27: v139 | G27: v134 | I27: v184 | J27: c80 | K27: b85 | L27: b41 | M27: c30 | N27: ccc74 | O27: i65 | P27: a105 | Q27: c62 | R27: g85 | S27: a55 | AJ27: =COUNTA(B27:AH27) -> 16 | AL27: =COUNTA(F27:O27,R27:S27) -> 11
A28: כמה כסף מוציאה המשפחה שלכם בממוצע בחודש? | T28: b158 | V28: v150 | AJ28: =COUNTA(B28:AH28) -> 2 | AL28: =COUNTA(F28:O28,R28:S28) -> 0
A29: מה מספר החדרים שיש לכם בבית? | B29: v140 | C29: v140 | D29: v140 | F29: v140 | G29: v135 | H29: v146 | I29: v186 | J29: c82 | K29: b87 | L29: b42 | M29: c34 | N29: ccc65 | O29: i63 | P29: a106 | Q29: c60 | R29: g83 | T29: b149 | U29: a148 | V29: v144 | W29: c21 | X29: b14 | Y29: a14 | Z29: v113 | AE29: b40 | AJ29: =COUNTA(B29:AH29) -> 24 | AL29: =COUNTA(F29:O29,R29:S29) -> 11
A30: מה מספר הנפשות המתגוררות בבית? (כולל חיילים) | B30: v141 | C30: v141 | D30: v141 | F30: v141 | G30: v136 | H30: v147 | I30: v187 | J30: c84 | K30: b88 | L30: b44 | M30: c35 | N30: ccc67 | O30: i64 | P30: a107 | Q30: c61 | R30: g84 | T30: b151 | U30: a149 | V30: v145 | W30: c22 | X30: b15 | Y30: a15 | Z30: v114 | AE30: b41 | AF30: c52 | AJ30: =COUNTA(B30:AH30) -> 25 | AL30: =COUNTA(F30:O30,R30:S30) -> 11
A31: צפיפות בבית | S31: a57 | AF31: c50 | AG31: d26 | AH31: c56 | AJ31: =COUNTA(B31:AH31) -> 4 | AL31: =COUNTA(F31:O31,R31:S31) -> 1
A32: מהי דתך? | B32: v143_code | C32: v143_code | D32: v143_code | F32: v143_code | G32: v138 | H32: v149 | I32: v189_1 | J32: c87 | K32: b90 | L32: b28 | N32: ccc75 | AJ32: =COUNTA(B32:AH32) -> 11 | AL32: =COUNTA(F32:O32,R32:S32) -> 8
A33: כיצד היית מגדיר את עצמך מבחינה דתית? | B33: v144 | C33: v144 | D33: v144 | F33: v144 | G33: v139 | H33: v150 | I33: v190 | J33: c88 | K33: b91 | L33: b27 | M33: c38 | AJ33: =COUNTA(B33:AH33) -> 11 | AL33: =COUNTA(F33:O33,R33:S33) -> 8
A34: מהו מצבך המשפחתי? | F34: v129 | G34: v111 | H34: v126 | O34: i54 | P34: a69 | Q34: c24 | R34: g34 | T34: b144 | U34: a154 | V34: v142 | Z34: v119 | AD34: e18 | AE34: b43 | AF34: c36 | AG34: d13 | AH34: c81 | AJ34: =COUNTA(B34:AH34) -> 16 | AL34: =COUNTA(F34:O34,R34:S34) -> 5
A35: באיזו מידה אתה נוהג לשמור על המסורת הדתית? | B35: v130 | F35: v130 | G35: v114 | H35: v132 | I35: v175 | J35: c56 | K35: b76 | L35: b26 | M35: c21 | N35: ccc70 | O35: i50 | P35: a100 | Q35: c46 | R35: g66 | S35: a48 | T35: b145 | U35: a155 | V35: v143 | W35: c26 | X35: b19 | Y35: a19 | Z35: v120 | AA35: h62 | AB35: g64 | AC35: f56 | AE35: b37 | AF35: c20 | AG35: c30 | AH35: c49 | AJ35: =COUNTA(B35:AH35) -> 29 | AL35: =COUNTA(F35:O35,R35:S35) -> 12
A36: האם אתה נוסע בשבת? | T36: b146 | AH36: c68 | AJ36: =COUNTA(B36:AH36) -> 2 | AL36: =COUNTA(F36:O36,R36:S36) -> 0
A37: האם אתה אוכל רק אוכל כשר? | T37: b147 | AH37: c70 | AJ37: =COUNTA(B37:AH37) -> 2 | AL37: =COUNTA(F37:O37,R37:S37) -> 0
A38: כמה פעמים בשנה אתה נוהג לבקר בבית כנסת? | T38: b148 | AG38: c29 | AJ38: =COUNTA(B38:AH38) -> 2 | AL38: =COUNTA(F38:O38,R38:S38) -> 0
A39: היכן נולד אביך? | F39: v132 | G39: v116 | I39: v179 | J39: c69 | AF39: c44 | AG39: d7 | AH39: c74 | AJ39: =COUNTA(B39:AH39) -> 7 | AL39: =COUNTA(F39:O39,R39:S39) -> 4
A40: היכן נולדה אמך? | F40: v133 | I40: v180 | J40: c72 | AF40: c47 | AG40: d10 | AH40: c77 | AJ40: =COUNTA(B40:AH40) -> 6 | AL40: =COUNTA(F40:O40,R40:S40) -> 3
...

Sheet ישראל כללי
A1: שאלה | B1: 2022 | C1: 2021 | D1: 2020 | E1: 43709 | F1: 43556 | G1: 2015 | H1: 2013 | I1: 2009 | J1: 2006 | K1: 2003 | L1: 2001 | M1: 1999 | N1: 1996 | O1: 1992 | P1: 1987* | Q1: 1988* | R1: 1988 | S1: 1984 | T1: 1981 - 3 | U1: 1981 - 2 | V1: 1981 - 1 | W1: 1977 - 4 | X1: 1977 - 3 | Y1: 1977 - 2 | Z1: 1977 - 1 | AA1: 1973 - 5 | AB1: 1973 - 4 | AC1: 1973 - 3 | AD1: 1973 - 2 | AE1: 1973 - 1 | AF1: 1969 - 3 | AG1: 1969 - 2 | AH1: 1969 - 1 | AJ1: מספר חזרות | AL1: ספירה 84-19 | AN1: סה"כ מעל שתי חזרות
A2: מהו לדעתך מצבה של ישראל באופן כללי? | B2: v6 | C2: v6 | D2: v6 | F2: v6 | G2: v6 | H2: v6 | I2: v6 | J2: a6 | K2: a6 | L2: a6 | M2: v3 | N2: c6 | O2: a2 | Q2: b2 | R2: f6 | S2: v2 | T2: b2 | U2: a2 | V2: v2 | Z2: v4 | AJ2: =COUNTA(B2:AH2) -> 20 | AL2: =COUNTA(F2:O2,R2:S2) -> 12 | AN2: =COUNTIF(AL2:AL150,">=2") -> 14
A3: מה דעתך על הדרך שבה מטפלת הממשלה בבעיות שישנן כיום במדינה? | F3: v7 | G3: v7 | H3: v7 | I3: v7 | J3: a7 | K3: a7 | L3: a7 | M3: v4 | N3: c7 | O3: a3 | Q3: b3 | R3: f7 | S3: v3 | T3: b3 | U3: a3 | V3: v3 | Z3: v5 | AH3: a83 | AJ3: =COUNTA(B3:AH3) -> 18 | AL3: =COUNTA(F3:O3,R3:S3) -> 12
A4: מהי לדעתך הבעיה החשובה ביותר שעל הממשלה לטפל בה? | B4: v8_code1 | C4: v8c | D4: v8_code | E4: c8_code | F4: v8_code | G4: v8 | H4: v8 | I4: v8 | J4: a8 | K4: a8 | L4: a8 | M4: v5 | N4: c8 | O4: a7 | P4: a52 | Q4: b8 | R4: f11 | S4: v4 | T4: b6 | U4: a4 | V4: v4 | X4: b2 | Y4: a2 | Z4: v6 | AB4: g2 | AC4: f42 | AD4: c51 | AE4: v27 | AG4: b23 | AH4: b29 | AJ4: =COUNTA(B4:AH4) -> 30 | AL4: =COUNTA(F4:O4,R4:S4) -> 12
A5: והבעיה השנייה הכי חשובה? | B5: v8_code2 | AB5: g3 | AC5: f43 | AD5: c52 | AE5: v28 | AG5: b24 | AH5: b30 | AJ5: =COUNTA(B5:AH5) -> 7 | AL5: =COUNTA(F5:O5,R5:S5) -> 0
A6: והבעיה השלישית הכי חשובה? | B6: v8_code3 | AG6: b25 | AH6: b31 | AJ6: =COUNTA(B6:AH6) -> 3 | AL6: =COUNTA(F6:O6,R6:S6) -> 0
A7: האם אתה מאמין שהממשלה תפתור בקרוב את שתי הבעיות שציינת? | AD7: c53 | AE7: v29 | AJ7: =COUNTA(B7:AH7) -> 2 | AL7: =COUNTA(F7:O7,R7:S7) -> 0
A8: מי מהמועמדים לראשות הממשלה יוכל לטפל טוב יותר בבעיה? | M8: v6 | N8: c10 | T8: b5 | AJ8: =COUNTA(B8:AH8) -> 3 | AL8: =COUNTA(F8:O8,R8:S8) -> 2
A9: איזו מפלגה תוכל לטפל טוב יותר בבעיה שציינת? | N9: c11 | O9: a8 | Q9: b9 | R9: f13 | S9: v6 | V9: v6 | Z9: v9 | AJ9: =COUNTA(B9:AH9) -> 7 | AL9: =COUNTA(F9:O9,R9:S9) -> 4
A10: מהי לדעתך הבעיה החשובה ביותר שעל הממשלה לטפל בה? (אחרי הבחירות) | M10: d2 | AJ10: =COUNTA(B10:AH10) -> 1 | AL10: =COUNTA(F10:O10,R10:S10) -> 1
A11: בסך הכל, מי יטפל טוב יותר בכלל בעיות המדינה - הצוות של המערך או הצוות של הליכוד? | S11: v25 | AJ11: =COUNTA(B11:AH11) -> 1 | AL11: =COUNTA(F11:O11,R11:S11) -> 1
A12: מבין הדברים הבאים, מה לדעתך הכי מאיים על המערכת הפוליטית כיום? | AJ12: =COUNTA(B12:AH12) -> 0 | AL12: =COUNTA(F12:O12,R12:S12) -> 0
A13: באיזו מידה אתה מרוצה מהאופן בו המערכת הפוליטית בישראל מתפקדת כיום? | B13: v116 | C13: v116 | D13: v116 | F13: v116 | AJ13: =COUNTA(B13:AH13) -> 4 | AL13: =COUNTA(F13:O13,R13:S13) -> 1
A14: כאשר אתה חושב על תולדות מדינת ישראל ועם ישראל, איזה אירוע מהעבר נראה לך החשוב ביותר? | H14: a_v17 | AJ14: =COUNTA(B14:AH14) -> 1 | AL14: =COUNTA(F14:O14,R14:S14) -> 1
A15: כאשר אתה חושב על העתיד של מדינת ישראל ועם ישראל, איזה אירוע או התרחשות הייתה רוצה לראות? | H15: a_v18 | AJ15: =COUNTA(B15:AH15) -> 1 | AL15: =COUNTA(F15:O15,R15:S15) -> 1
A16: מיהי, לדעתך, הדמות המשמעותית ביותר בתולדות מדינת ישראל ועם ישראל? | H16: a_v19 | AJ16: =COUNTA(B16:AH16) -> 1 | AL16: =COUNTA(F16:O16,R16:S16) -> 1
A17: באיזו מידה אתה מסכים או לא מסכים עם המשפטים הבאים: לפעמים הפוליטיקה נראית כ"כ מסובכת שאדם כמוני לא יכול להבין באמת מה קורה | B17: v33 | G17: v33 | H17: v32 | AJ17: =COUNTA(B17:AH17) -> 3 | AL17: =COUNTA(F17:O17,R17:S17) -> 2
A18: באיזו מידה אתה מסכים או לא מסכים עם המשפטים הבאים: יש לגרש מהארץ את העובדים הזרים שאין להם רשיון עבודה וגם את ילדיהם | H18: v40 | AJ18: =COUNTA(B18:AH18) -> 1 | AL18: =COUNTA(F18:O18,R18:S18) -> 1
A19: לפעמים, אנשים שואלים את עצמם מה צריכות להיות המטרות של המדינה לעשר השנים הבאות? מבין המטרות הבאות, מה לדעתך, המטרה החשובה ביותר של המדינה? | G19: v107 | H19: v115 | AJ19: =COUNTA(B19:AH19) -> 2 | AL19: =COUNTA(F19:O19,R19:S19) -> 2
A20: ומה לדעתך, המטרה השנייה בחשיבותה? | G20: v108 | H20: v116 | AJ20: =COUNTA(B20:AH20) -> 2 | AL20: =COUNTA(F20:O20,R20:S20) -> 2
A21: כיצד היית מדרג את מצבך האישי בימים אלו? | I21: v57 | J21: a55 | N21: cc61 | O21: i33 | P21: a56 | T21: b61 | V21: v25 | AG21: a11 | AH21: a34 | AJ21: =COUNTA(B21:AH21) -> 9 | AL21: =COUNTA(F21:O21,R21:S21) -> 4
A22: ולפני 5 שנים מה היה מצבך האישי? | I22: v58 | J22: a56 | N22: cc62 | O22: i34 | P22: a57 | T22: b62 | V22: v26 | AG22: a12 | AH22: a35 | AJ22: =COUNTA(B22:AH22) -> 9 | AL22: =COUNTA(F22:O22,R22:S22) -> 4
A23: ובעוד 5 שנים מה יהיה מצבך האישי? | I23: v59 | J23: a57 | N23: cc63 | O23: i35 | P23: a58 | T23: b63 | V23: v27 | AG23: a13 | AH23: a36 | AJ23: =COUNTA(B23:AH23) -> 9 | AL23: =COUNTA(F23:O23,R23:S23) -> 4
A24: האם החלפת המפלגה בשלטון תשנה את המצב האישי שלך? | AD24: d44 | AJ24: =COUNTA(B24:AH24) -> 1 | AL24: =COUNTA(F24:O24,R24:S24) -> 0
A25: באיזו מידה אתה תומך או מתנגד לצירוף של שרים מטעם מפלגות ערביות לממשלה? | B25: v704 | L25: b13 | M25: c11 | N25: ccc20 | AJ25: =COUNTA(B25:AH25) -> 4 | AL25: =COUNTA(F25:O25,R25:S25) -> 3
A26: מה צריך להיות יותר חשוב לאזרחי המדינה, האינטרסים האישיים שלהם או האינטרסים של המדינה כולה? | M26: i55 | N26: cc44 | O26: a75 | T26: b59 | AG26: b17 | AH26: b14 | AJ26: =COUNTA(B26:AH26) -> 6 | AL26: =COUNTA(F26:O26,R26:S26) -> 3
A27: האם לפי הערכתך עלולה להתפתח מלחמת אזרחים בארץ בעקבות ההסדרים לגבי עתיד השטחים? | N27: c53 | AJ27: =COUNTA(B27:AH27) -> 1 | AL27: =COUNTA(F27:O27,R27:S27) -> 1
A28: יש החושבים שישראל יכולה להשיג את כל היעדים החשובים לה: שלום, א"י השלמה, שמירה על רוב יהודי, שמירה על משטר דמוקרטי מבלי לוותר על אף דבר. אחרים חושבים שאי אפשר להשיג את כל היעדים הללו בו זמנית, וכדי להשיג יעדים מסויימים צריך להתפשר על יעדים אחרים. מה דעתך? | N28: cc73 | O28: i31 | AJ28: =COUNTA(B28:AH28) -> 2 | AL28: =COUNTA(F28:O28,R28:S28) -> 2
A29: האם יש לך קשרים עם ערבים? | N29: ccc42 | AJ29: =COUNTA(B29:AH29) -> 1 | AL29: =COUNTA(F29:O29,R29:S29) -> 1
A30: באיזו מידה כל אחד מהמצבים הבאים מהווה איום בעיניך: מספר שווה של יהודים וערבים במדינה | O30: i17 | AJ30: =COUNTA(B30:AH30) -> 1 | AL30: =COUNTA(F30:O30,R30:S30) -> 1
A31: באיזו מידה כל אחד מהמצבים הבאים מהווה איום בעיניך: הפסקת הסיוע מארה"ב | O31: i20 | AJ31: =COUNTA(B31:AH31) -> 1 | AL31: =COUNTA(F31:O31,R31:S31) -> 1
A32: מהם הסיכויים שיתקיים כל אחד מהמצבים הבאים בעתיד הנראה לעין: מספר שווה של יהודים וערבים במדינה | O32: i26 | AJ32: =COUNTA(B32:AH32) -> 1 | AL32: =COUNTA(F32:O32,R32:S32) -> 1
A33: מהם הסיכויים שיתקיים כל אחד מהמצבים הבאים בעתיד הנראה לעין: הפסקת הסיוע של ארה"ב | O33: i29 | AJ33: =COUNTA(B33:AH33) -> 1 | AL33: =COUNTA(F33:O33,R33:S33) -> 1
A34: לפניך רשימת דעות בנושאים שונים. ציין באיזו מידה אתה מסכים או מתנגד לכל אחת מהן: מבין כל ההשקפות הקיימות בעולם כנראה שיש רק אחת בלבד שהיא נכונה | P34: v74 | AJ34: =COUNTA(B34:AH34) -> 1 | AL34: =COUNTA(F34:O34,R34:S34) -> 0
A35: אין אף מצב בו נראה כי עדיף שאנשים יקחו בעצם את החוק לידיים | P35: v75 | AJ35: =COUNTA(B35:AH35) -> 1 | AL35: =COUNTA(F35:O35,R35:S35) -> 0
A36: במצבים בהם יש ניגוד אינטרסים בין טובת הכלל וטובת הפרט במדינה יש בדר"כ להעדיף את טובת הפרט | P36: v76 | AJ36: =COUNTA(B36:AH36) -> 1 | AL36: =COUNTA(F36:O36,R36:S36) -> 0
A37: לא להחזיר שטחים מא"י הוא בחזקת יהרג ובל יעבור | P37: v77 | AJ37: =COUNTA(B37:AH37) -> 1 | AL37: =COUNTA(F37:O37,R37:S37) -> 0
A38: אלוהים ישמור עלינו אם נהיה ראויים לכך אפילו אם לא נהיה מוכנים למלחמה הבאה | P38: v78 | AJ38: =COUNTA(B38:AH38) -> 1 | AL38: =COUNTA(F38:O38,R38:S38) -> 0
A39: באיזו מידה אתה מאמין או לא מאמין בעתיד קיומנו בארץ לטווח ארוך? | P39: v79 | Q39: b27 | R39: f31 | AJ39: =COUNTA(B39:AH39) -> 3 | AL39: =COUNTA(F39:O39,R39:S39) -> 1
A40: האם נטל השירות הצבאי מתחלק באופן צודק או לא צודק? | P40: v104 | AJ40: =COUNTA(B40:AH40) -> 1 | AL40: =COUNTA(F40:O40,R40:S40) -> 0
...

Sheet עניין פוליטי
A1: שאלה | B1: 2022 | C1: 2021 | D1: 2020 | E1: 43709 | F1: 43556 | G1: 2015 | H1: 2013 | I1: 2009 | J1: 2006 | K1: 2003 | L1: 2001 | M1: 1999 | N1: 1996 | O1: 1992 | P1: 1987* | Q1: 1988* | R1: 1988 | S1: 1984 | T1: 1981 - 3 | U1: 1981 - 2 | V1: 1981 - 1 | W1: 1977 - 4 | X1: 1977 - 3 | Y1: 1977 - 2 | Z1: 1977 - 1 | AA1: 1973 - 5 | AB1: 1973 - 4 | AC1: 1973 - 3 | AD1: 1973 - 2 | AE1: 1973 - 1 | AF1: 1969 - 3 | AG1: 1969 - 2 | AH1: 1969 - 1 | AJ1: מספר חזרות | AL1: ספירה 84-19 | AN1: סה"כ מעל שתי חזרות
A2: באיזו מידה אתה וחבריך יכולים להשפיע על מדיניות הממשלה? | B2: v46 | C2: v46 | D2: v46 | F2: v46 | G2: v50 | H2: v44 | I2: v56 | J2: a54 | K2: a75 | L2: a74 | M2: i57 | N2: cc48 | O2: a61 | P2: a16 | Q2: b72 | R2: f75 | S2: v40 | T2: b30 | U2: a35 | V2: v70 | Z2: v32 | AB2: g33 | AD2: d6 | AE2: v66 | AG2: b14 | AH2: a73 | AJ2: =COUNTA(B2:AH2) -> 26 | AL2: =COUNTA(F2:O2,R2:S2) -> 12 | AN2: =COUNTIF(AL2:AL47,">=2") -> 3
A3: באיזו מידה אתה נוהג לשוחח עם חבריך ובני משפחתך על עניינים פוליטיים? | B3: v45 | C3: v45 | D3: v45 | F3: v45 | G3: v49 | H3: v43 | I3: v55 | J3: a53 | K3: a74 | L3: a73 | M3: i56 | N3: cc45 | O3: a60 | P3: a75 | Q3: b59 | R3: f62 | U3: a31 | V3: v19 | Z3: v28 | AD3: c25 | AE3: v11 | AJ3: =COUNTA(B3:AH3) -> 21 | AL3: =COUNTA(F3:O3,R3:S3) -> 11
A4: כאשר אתה נפגש עם חבריך, האם אתם דנים על עניינים פוליטיים? | P4: a113 | Q4: b71 | R4: f74 | U4: a32 | Z4: v29 | AE4: v8 | AJ4: =COUNTA(B4:AH4) -> 6 | AL4: =COUNTA(F4:O4,R4:S4) -> 1
A5: באיזו מידה אתה נוהג או לא נוהג להביע את דעתך בנושאי בטחון בדרכים שונות, כגון שיחות עם בני משפחה וחברים, כתיבת מכתבים למערכת העיתונים, חתומה על עצומות ועוד? | P5: a15 | AJ5: =COUNTA(B5:AH5) -> 1 | AL5: =COUNTA(F5:O5,R5:S5) -> 0
A6: באיזו מידה חשוב לך להביע את דעותיך בעניינים פוליטיים? | AD6: c46 | AJ6: =COUNTA(B6:AH6) -> 1 | AL6: =COUNTA(F6:O6,R6:S6) -> 0
A7: באיזו מידה השתתפות בבחירות מאפשרת לך להביע את דעותיך בעניינים פוליטיים? | AD7: d23 | AJ7: =COUNTA(B7:AH7) -> 1 | AL7: =COUNTA(F7:O7,R7:S7) -> 0
A8: באיזו מידה הדעות של בני משפחתך בנושאי השטחים ומדיניות הבטחון דומות לדעות שלך? | Q8: b58 | R8: f61 | AJ8: =COUNTA(B8:AH8) -> 2 | AL8: =COUNTA(F8:O8,R8:S8) -> 1
A9: עם מי מבני משפחתך הינך משוחח כיום על עניינים פוליטיים במידה הרבה ביותר? | P9: a76 | Q9: b60 | R9: f63 | AJ9: =COUNTA(B9:AH9) -> 3 | AL9: =COUNTA(F9:O9,R9:S9) -> 1
A10: בתקופה בה התגוררת בבית הוריך, עם מי נהגת לשוחח על עניינים פוליטיים במידה הרבה ביותר? | P10: a77 | AJ10: =COUNTA(B10:AH10) -> 1 | AL10: =COUNTA(F10:O10,R10:S10) -> 0
A11: האם נהגת לשוחח עם אביך בענייני פוליטיקה? | AE11: v20 | AJ11: =COUNTA(B11:AH11) -> 1 | AL11: =COUNTA(F11:O11,R11:S11) -> 0
